Workbook

Sheet README
A1: CE524 Applied Hydroclimatology - Lecture 16 worked examples: downscaling, the problem, the data and choosing a method
A3: Purpose
A4: Companion to the notebook lecture-16-downscaling-problem-data-and-methods.ipynb. The sheets reproduce, with live formulas, the numbers of the notebook's hands-on section.
A6: ALL DATA ARE SYNTHETIC. They were generated by the notebook (fixed random seed) to mimic a coarse GCM, a reanalysis and a catchment observation series for 2001-2010. They are NOT measurements and NOT output of a real model.
A7: To use real data: paste IMD gridded rainfall or station data (mm/day) into Data columns D:E, a reanalysis (for example ERA5 daily total precipitation in m, temperature in K) into F:G, and a CMIP6 or NEX-GDDP-CMIP6 series (pr in kg m-2 s-1, tas in K) into N:O with its year, month, day in K:M. Extend or shorten the formula ranges if the number of rows changes.
A9: Colour code
A10: Blue font = input (data or an assumption you may change).
A11: Black font = formula (do not overwrite).
A12: Yellow fill = explanation to read. Cell notes (red triangles) explain the key formulas.
A14: Sheets
A15: Data - daily series: observation + reanalysis (real calendar, 3652 days) and GCM (360-day calendar, 3600 days); unit conversions in columns H, I, P, Q.
A16: Units - kg m-2 s-1 to mm/day, m to mm, K to degC, mm/day to discharge, and the area of a grid cell compared with a catchment.
... A21: Note: the workbook was built with Python (openpyxl). Its formulas were checked against an independent Python calculation; they were not recalculated in desktop Excel while building it. Excel computes them when the file is opened.

Sheet Data
A1: Daily synthetic series for one catchment (blue = input data, black = formula)
A2: Obs/reanalysis: real calendar (leap years included). GCM: 360-day calendar (12 months of 30 days; no day 31, February has 30 days). Data rows: obs block 5 to 3656, GCM block 5 to 3604.
A3: Observation and reanalysis (real calendar) | K3: GCM (360-day calendar)
A4: date | B4: year | C4: month | D4: obs rain [mm/day] | E4: obs temp [degC] | F4: reanalysis tp [m/day] | G4: reanalysis t2m [K] | H4: reanalysis rain [mm/day] | I4: reanalysis temp [degC] | K4: year | L4: month | M4: day | N4: GCM pr [kg m-2 s-1] | O4: GCM tas [K] | P4: GCM rain [mm/day] | Q4: GCM temp [degC]
A5: 36892 | B5: =YEAR(A5) | C5: =MONTH(A5) | D5: 0 | E5: 3.7246263 | F5: 0 | G5: 279.05922 | H5: =F5*1000 | I5: =G5-273.15 | K5: 2001 | L5: 1 | M5: 1 | N5: 1.789531e-05 | O5: 277.60677 | P5: =N5*86400 | Q5: =O5-273.15
A6: 36893 | B6: =YEAR(A6) | C6: =MONTH(A6) | D6: 0 | E6: 4.2511833 | F6: 0 | G6: 278.87771 | H6: =F6*1000 | I6: =G6-273.15 | K6: 2001 | L6: 1 | M6: 2 | N6: 0 | O6: 277.07636 | P6: =N6*86400 | Q6: =O6-273.15
A7: 36894 | B7: =YEAR(A7) | C7: =MONTH(A7) | D7: 0 | E7: 1.681646 | F7: 0 | G7: 276.70397 | H7: =F7*1000 | I7: =G7-273.15 | K7: 2001 | L7: 1 | M7: 3 | N7: 5.6803288e-06 | O7: 278.2514 | P7: =N7*86400 | Q7: =O7-273.15
A8: 36895 | B8: =YEAR(A8) | C8: =MONTH(A8) | D8: 0 | E8: 2.8478852 | F8: 0 | G8: 277.38196 | H8: =F8*1000 | I8: =G8-273.15 | K8: 2001 | L8: 1 | M8: 4 | N8: 6.2471051e-05 | O8: 277.94949 | P8: =N8*86400 | Q8: =O8-273.15
A9: 36896 | B9: =YEAR(A9) | C9: =MONTH(A9) | D9: 0 | E9: 1.6135424 | F9: 0 | G9: 276.97398 | H9: =F9*1000 | I9: =G9-273.15 | K9: 2001 | L9: 1 | M9: 5 | N9: 4.2688853e-06 | O9: 278.24225 | P9: =N9*86400 | Q9: =O9-273.15
A10: 36897 | B10: =YEAR(A10) | C10: =MONTH(A10) | D10: 0 | E10: -1.2448607 | F10: 0 | G10: 273.84521 | H10: =F10*1000 | I10: =G10-273.15 | K10: 2001 | L10: 1 | M10: 6 | N10: 6.5156064e-07 | O10: 276.38349 | P10: =N10*86400 | Q10: =O10-273.15
A11: 36898 | B11: =YEAR(A11) | C11: =MONTH(A11) | D11: 0 | E11: 1.453742 | F11: 0 | G11: 276.22179 | H11: =F11*1000 | I11: =G11-273.15 | K11: 2001 | L11: 1 | M11: 7 | N11: 0 | O11: 276.74216 | P11: =N11*86400 | Q11: =O11-273.15
A12: 36899 | B12: =YEAR(A12) | C12: =MONTH(A12) | D12: 0 | E12: 1.1483297 | F12: 0 | G12: 275.65362 | H12: =F12*1000 | I12: =G12-273.15 | K12: 2001 | L12: 1 | M12: 8 | N12: 7.0994639e-07 | O12: 275.86667 | P12: =N12*86400 | Q12: =O12-273.15
A13: 36900 | B13: =YEAR(A13) | C13: =MONTH(A13) | D13: 0 | E13: 2.9728899 | F13: 0 | G13: 277.14617 | H13: =F13*1000 | I13: =G13-273.15 | K13: 2001 | L13: 1 | M13: 9 | N13: 4.4597351e-06 | O13: 274.90998 | P13: =N13*86400 | Q13: =O13-273.15
A14: 36901 | B14: =YEAR(A14) | C14: =MONTH(A14) | D14: 0 | E14: 1.4517644 | F14: 0 | G14: 277.32113 | H14: =F14*1000 | I14: =G14-273.15 | K14: 2001 | L14: 1 | M14: 10 | N14: 1.8994459e-06 | O14: 277.09202 | P14: =N14*86400 | Q14: =O14-273.15
A15: 36902 | B15: =YEAR(A15) | C15: =MONTH(A15) | D15: 0 | E15: 1.6622264 | F15: 0 | G15: 277.93992 | H15: =F15*1000 | I15: =G15-273.15 | K15: 2001 | L15: 1 | M15: 11 | N15: 0 | O15: 278.18337 | P15: =N15*86400 | Q15: =O15-273.15
A16: 36903 | B16: =YEAR(A16) | C16: =MONTH(A16) | D16: 0 | E16: 1.1392461 | F16: 0 | G16: 276.18704 | H16: =F16*1000 | I16: =G16-273.15 | K16: 2001 | L16: 1 | M16: 12 | N16: 0 | O16: 276.52546 | P16: =N16*86400 | Q16: =O16-273.15
... A3604: 40491 | B3604: =YEAR(A3604) | C3604: =MONTH(A3604) | D3604: 0 | E3604: 3.6127929 | F3604: 0.00083467242 | G3604: 279.66849 | H3604: =F3604*1000 | I3604: =G3604-273.15 | K3604: 2010 | L3604: 12 | M3604: 30 | N3604: 3.349792e-06 | O3604: 281.09468 | P3604: =N3604*86400 | Q3604: =O3604-273.15
A3605: 40492 | B3605: =YEAR(A3605) | C3605: =MONTH(A3605) | D3605: 0 | E3605: 4.5324252 | F3605: 0 | G3605: 280.66559 | H3605: =F3605*1000 | I3605: =G3605-273.15
A3606: 40493 | B3606: =YEAR(A3606) | C3606: =MONTH(A3606) | D3606: 0 | E3606: 5.266351 | F3606: 4.8542215e-06 | G3606: 280.4798 | H3606: =F3606*1000 | I3606: =G3606-273.15
A3607: 40494 | B3607: =YEAR(A3607) | C3607: =MONTH(A3607) | D3607: 0 | E3607: 6.8482156 | F3607: 0 | G3607: 281.71351 | H3607: =F3607*1000 | I3607: =G3607-273.15
A3608: 40495 | B3608: =YEAR(A3608) | C3608: =MONTH(A3608) | D3608: 0 | E3608: 4.155114 | F3608: 6.2841e-05 | G3608: 279.19561 | H3608: =F3608*1000 | I3608: =G3608-273.15
A3609: 40496 | B3609: =YEAR(A3609) | C3609: =MONTH(A3609) | D3609: 0 | E3609: 2.9168819 | F3609: 0 | G3609: 278.08752 | H3609: =F3609*1000 | I3609: =G3609-273.15
A3610: 40497 | B3610: =YEAR(A3610) | C3610: =MONTH(A3610) | D3610: 0 | E3610: 3.6394219 | F3610: 0.00074110084 | G3610: 279.1016 | H3610: =F3610*1000 | I3610: =G3610-273.15
A3611: 40498 | B3611: =YEAR(A3611) | C3611: =MONTH(A3611) | D3611: 0 | E3611: 1.9925963 | F3611: 0.0028760955 | G3611: 276.86994 | H3611: =F3611*1000 | I3611: =G3611-273.15
A3612: 40499 | B3612: =YEAR(A3612) | C3612: =MONTH(A3612) | D3612: 6.3684994 | E3612: 3.0019623 | F3612: 0.0089456664 | G3612: 277.14727 | H3612: =F3612*1000 | I3612: =G3612-273.15
A3613: 40500 | B3613: =YEAR(A3613) | C3613: =MONTH(A3613) | D3613: 0 | E3613: 5.5225392 | F3613: 0.0017395465 | G3613: 280.11967 | H3613: =F3613*1000 | I3613: =G3613-273.15
A3614: 40501 | B3614: =YEAR(A3614) | C3614: =MONTH(A3614) | D3614: 0 | E3614: 4.6737028 | F3614: 0 | G3614: 280.42233 | H3614: =F3614*1000 | I3614: =G3614-273.15
A3615: 40502 | B3615: =YEAR(A3615) | C3615: =MONTH(A3615) | D3615: 0 | E3615: 4.2073797 | F3615: 0.00027175857 | G3615: 279.84271 | H3615: =F3615*1000 | I3615: =G3615-273.15
A3616: 40503 | B3616: =YEAR(A3616) | C3616: =MONTH(A3616) | D3616: 0 | E3616: 3.9662663 | F3616: 0.00015573043 | G3616: 280.2355 | H3616: =F3616*1000 | I3616: =G3616-273.15
... A3656: 40543 | B3656: =YEAR(A3656) | C3656: =MONTH(A3656) | D3656: 0 | E3656: 2.2739041 | F3656: 0 | G3656: 279.25473 | H3656: =F3656*1000 | I3656: =G3656-273.15

Sheet Units
A1: Units and scales: converting model output and comparing scales
A3: 1. Precipitation flux (kg m-2 s-1) to mm/day
A4: Seconds per day [s] | B4: 86400
A5: Density of water [kg m-3] | B5: 1000
A6: Millimetres per metre | B6: 1000
A8: flux [kg m-2 s-1] | B8: depth per second [mm/s] = flux / density x 1000 | C8: depth per day [mm/day] = (previous) x 86400 | D8: shortcut = flux x 86400 | E8: difference (should be 0)
A9: 1e-06 | B9: =A9/$B$5*$B$6 | C9: =B9*$B$4 | D9: =A9*$B$4 | E9: =C9-D9
A10: 1e-05 | B10: =A10/$B$5*$B$6 | C10: =B10*$B$4 | D10: =A10*$B$4 | E10: =C10-D10
A11: 5e-05 | B11: =A11/$B$5*$B$6 | C11: =B11*$B$4 | D11: =A11*$B$4 | E11: =C11-D11
A12: 0.0001 | B12: =A12/$B$5*$B$6 | C12: =B12*$B$4 | D12: =A12*$B$4 | E12: =C12-D12
A13: 0.0003 | B13: =A13/$B$5*$B$6 | C13: =B13*$B$4 | D13: =A13*$B$4 | E13: =C13-D13
A14: =Data!N5 | B14: =A14/$B$5*$B$6 | C14: =B14*$B$4 | D14: =A14*$B$4 | E14: =C14-D14
A15: 1 kg of water spread over 1 m2 is 1/1000 m3 per m2 = 1 mm deep, so kg m-2 and mm are the same number (for water). The flux is per second, so multiply by 86400 to get mm per day.
A17: 2. Other conversions (first day of the Data sheet)
A18: quantity | B18: raw value | C18: unit conversion | D18: converted | E18: unit
A19: Reanalysis total precipitation | B19: =Data!F5 | C19: x 1000 | D19: =B19*$B$6 | E19: mm/day
A20: Reanalysis 2 m temperature | B20: =Data!G5 | C20: - 273.15 | D20: =B20-273.15 | E20: degC
A21: GCM near-surface temperature | B21: =Data!O5 | C21: - 273.15 | D21: =B21-273.15 | E21: degC
A23: 3. Rainfall depth to discharge: Q [m3/s] = P [mm/day] x A [km2] / 86.4
A24: Catchment area A [km2] | B24: 1000
A26: P [mm/day] | B26: volume per day [m3] = P/1000 x A x 1e6 | C26: Q [m3/s] = volume / 86400 | D26: shortcut P x A / 86.4 | E26: difference
A27: 1 | B27: =A27/1000*$B$24*1000000 | C27: =B27/$B$4 | D27: =A27*$B$24/86.4 | E27: =C27-D27
A28: 10 | B28: =A28/1000*$B$24*1000000 | C28: =B28/$B$4 | D28: =A28*$B$24/86.4 | E28: =C28-D28
A29: 50 | B29: =A29/1000*$B$24*1000000 | C29: =B29/$B$4 | D29: =A29*$B$24/86.4 | E29: =C29-D29
A30: 100 | B30: =A30/1000*$B$24*1000000 | C30: =B30/$B$4 | D30: =A30*$B$24/86.4 | E30: =C30-D30
A31: 86.4 = 86400 s per day / 1000 (mm per m), with A in km2 (1e6 m2): 1 mm/day over 1 km2 is 1000 m3/day = 0.01157 m3/s.
A33: 4. Area of a grid cell: A = R^2 x (lon width in rad) x (sin lat_north - sin lat_south)
A34: Earth radius R [km] | B34: 6371
A35: Latitude of the catchment [deg N] | B35: 31.75
A36: Catchment area for the share column [km2] | B36: 1000
A38: cell | B38: size [deg] | C38: lat south [deg] | D38: lat north [deg] | E38: lon width [deg] | F38: area [km2] | G38: catchment area as % of cell area
A39: Typical CMIP GCM | B39: 2.5 | C39: =$B$35-B39/2 | D39: =$B$35+B39/2 | E39: =B39 | F39: =$B$34^2*RADIANS(E39)*(SIN(RADIANS(D39))-SIN(RADIANS(C39))) | G39: =$B$36/F39*100
A40: Coarse reanalysis | B40: 1.25 | C40: =$B$35-B40/2 | D40: =$B$35+B40/2 | E40: =B40 | F40: =$B$34^2*RADIANS(E40)*(SIN(RADIANS(D40))-SIN(RADIANS(C40))) | G40: =$B$36/F40*100
A41: ERA5 / NEX-GDDP-CMIP6 | B41: 0.25 | C41: =$B$35-B41/2 | D41: =$B$35+B41/2 | E41: =B41 | F41: =$B$34^2*RADIANS(E41)*(SIN(RADIANS(D41))-SIN(RADIANS(C41))) | G41: =$B$36/F41*100
A42: Catchment box of the notebook | B42: 0.5 | C42: =$B$35-B42/2 | D42: =$B$35+B42/2 | E42: =B42 | F42: =$B$34^2*RADIANS(E42)*(SIN(RADIANS(D42))-SIN(RADIANS(C42))) | G42: =$B$36/F42*100
A44: A 1000 km2 catchment fills a small share of a 2.5 degree cell: it sits inside one GCM cell with no resolved structure.

Sheet Compare
A1: Observation vs reanalysis vs GCM at the catchment (synthetic data)
A2: Number of years in the record | B2: =MAX(Data!$B$5:$B$3656)-MIN(Data!$B$5:$B$3656)+1
A3: Wet-day threshold [mm/day] | B3: 1
A5: A. Monthly climatology (mean over all days of that month)
A7: month | B7: obs [mm/day] | C7: reanalysis [mm/day] | D7: GCM [mm/day] | E7: days per month, real calendar | F7: days per month, GCM (360-day) | G7: obs total [mm] | H7: reanalysis total [mm] | I7: GCM total [mm] | J7: GCM - obs [mm/day] | K7: GCM / obs | L7: reanalysis / obs
A8: 1 | B8: =AVERAGEIFS(Data!$D$5:$D$3656,Data!$C$5:$C$3656,$A8) | C8: =AVERAGEIFS(Data!$H$5:$H$3656,Data!$C$5:$C$3656,$A8) | D8: =AVERAGEIFS(Data!$P$5:$P$3604,Data!$L$5:$L$3604,$A8) | E8: =COUNTIF(Data!$C$5:$C$3656,$A8)/$B$2 | F8: =COUNTIF(Data!$L$5:$L$3604,$A8)/$B$2 | G8: =B8*E8 | H8: =C8*E8 | I8: =D8*F8 | J8: =D8-B8 | K8: =D8/B8 | L8: =C8/B8
A9: 2 | B9: =AVERAGEIFS(Data!$D$5:$D$3656,Data!$C$5:$C$3656,$A9) | C9: =AVERAGEIFS(Data!$H$5:$H$3656,Data!$C$5:$C$3656,$A9) | D9: =AVERAGEIFS(Data!$P$5:$P$3604,Data!$L$5:$L$3604,$A9) | E9: =COUNTIF(Data!$C$5:$C$3656,$A9)/$B$2 | F9: =COUNTIF(Data!$L$5:$L$3604,$A9)/$B$2 | G9: =B9*E9 | H9: =C9*E9 | I9: =D9*F9 | J9: =D9-B9 | K9: =D9/B9 | L9: =C9/B9
A10: 3 | B10: =AVERAGEIFS(Data!$D$5:$D$3656,Data!$C$5:$C$3656,$A10) | C10: =AVERAGEIFS(Data!$H$5:$H$3656,Data!$C$5:$C$3656,$A10) | D10: =AVERAGEIFS(Data!$P$5:$P$3604,Data!$L$5:$L$3604,$A10) | E10: =COUNTIF(Data!$C$5:$C$3656,$A10)/$B$2 | F10: =COUNTIF(Data!$L$5:$L$3604,$A10)/$B$2 | G10: =B10*E10 | H10: =C10*E10 | I10: =D10*F10 | J10: =D10-B10 | K10: =D10/B10 | L10: =C10/B10
A11: 4 | B11: =AVERAGEIFS(Data!$D$5:$D$3656,Data!$C$5:$C$3656,$A11) | C11: =AVERAGEIFS(Data!$H$5:$H$3656,Data!$C$5:$C$3656,$A11) | D11: =AVERAGEIFS(Data!$P$5:$P$3604,Data!$L$5:$L$3604,$A11) | E11: =COUNTIF(Data!$C$5:$C$3656,$A11)/$B$2 | F11: =COUNTIF(Data!$L$5:$L$3604,$A11)/$B$2 | G11: =B11*E11 | H11: =C11*E11 | I11: =D11*F11 | J11: =D11-B11 | K11: =D11/B11 | L11: =C11/B11
A12: 5 | B12: =AVERAGEIFS(Data!$D$5:$D$3656,Data!$C$5:$C$3656,$A12) | C12: =AVERAGEIFS(Data!$H$5:$H$3656,Data!$C$5:$C$3656,$A12) | D12: =AVERAGEIFS(Data!$P$5:$P$3604,Data!$L$5:$L$3604,$A12) | E12: =COUNTIF(Data!$C$5:$C$3656,$A12)/$B$2 | F12: =COUNTIF(Data!$L$5:$L$3604,$A12)/$B$2 | G12: =B12*E12 | H12: =C12*E12 | I12: =D12*F12 | J12: =D12-B12 | K12: =D12/B12 | L12: =C12/B12
A13: 6 | B13: =AVERAGEIFS(Data!$D$5:$D$3656,Data!$C$5:$C$3656,$A13) | C13: =AVERAGEIFS(Data!$H$5:$H$3656,Data!$C$5:$C$3656,$A13) | D13: =AVERAGEIFS(Data!$P$5:$P$3604,Data!$L$5:$L$3604,$A13) | E13: =COUNTIF(Data!$C$5:$C$3656,$A13)/$B$2 | F13: =COUNTIF(Data!$L$5:$L$3604,$A13)/$B$2 | G13: =B13*E13 | H13: =C13*E13 | I13: =D13*F13 | J13: =D13-B13 | K13: =D13/B13 | L13: =C13/B13
A14: 7 | B14: =AVERAGEIFS(Data!$D$5:$D$3656,Data!$C$5:$C$3656,$A14) | C14: =AVERAGEIFS(Data!$H$5:$H$3656,Data!$C$5:$C$3656,$A14) | D14: =AVERAGEIFS(Data!$P$5:$P$3604,Data!$L$5:$L$3604,$A14) | E14: =COUNTIF(Data!$C$5:$C$3656,$A14)/$B$2 | F14: =COUNTIF(Data!$L$5:$L$3604,$A14)/$B$2 | G14: =B14*E14 | H14: =C14*E14 | I14: =D14*F14 | J14: =D14-B14 | K14: =D14/B14 | L14: =C14/B14
A15: 8 | B15: =AVERAGEIFS(Data!$D$5:$D$3656,Data!$C$5:$C$3656,$A15) | C15: =AVERAGEIFS(Data!$H$5:$H$3656,Data!$C$5:$C$3656,$A15) | D15: =AVERAGEIFS(Data!$P$5:$P$3604,Data!$L$5:$L$3604,$A15) | E15: =COUNTIF(Data!$C$5:$C$3656,$A15)/$B$2 | F15: =COUNTIF(Data!$L$5:$L$3604,$A15)/$B$2 | G15: =B15*E15 | H15: =C15*E15 | I15: =D15*F15 | J15: =D15-B15 | K15: =D15/B15 | L15: =C15/B15
A16: 9 | B16: =AVERAGEIFS(Data!$D$5:$D$3656,Data!$C$5:$C$3656,$A16) | C16: =AVERAGEIFS(Data!$H$5:$H$3656,Data!$C$5:$C$3656,$A16) | D16: =AVERAGEIFS(Data!$P$5:$P$3604,Data!$L$5:$L$3604,$A16) | E16: =COUNTIF(Data!$C$5:$C$3656,$A16)/$B$2 | F16: =COUNTIF(Data!$L$5:$L$3604,$A16)/$B$2 | G16: =B16*E16 | H16: =C16*E16 | I16: =D16*F16 | J16: =D16-B16 | K16: =D16/B16 | L16: =C16/B16
A17: 10 | B17: =AVERAGEIFS(Data!$D$5:$D$3656,Data!$C$5:$C$3656,$A17) | C17: =AVERAGEIFS(Data!$H$5:$H$3656,Data!$C$5:$C$3656,$A17) | D17: =AVERAGEIFS(Data!$P$5:$P$3604,Data!$L$5:$L$3604,$A17) | E17: =COUNTIF(Data!$C$5:$C$3656,$A17)/$B$2 | F17: =COUNTIF(Data!$L$5:$L$3604,$A17)/$B$2 | G17: =B17*E17 | H17: =C17*E17 | I17: =D17*F17 | J17: =D17-B17 | K17: =D17/B17 | L17: =C17/B17
A18: 11 | B18: =AVERAGEIFS(Data!$D$5:$D$3656,Data!$C$5:$C$3656,$A18) | C18: =AVERAGEIFS(Data!$H$5:$H$3656,Data!$C$5:$C$3656,$A18) | D18: =AVERAGEIFS(Data!$P$5:$P$3604,Data!$L$5:$L$3604,$A18) | E18: =COUNTIF(Data!$C$5:$C$3656,$A18)/$B$2 | F18: =COUNTIF(Data!$L$5:$L$3604,$A18)/$B$2 | G18: =B18*E18 | H18: =C18*E18 | I18: =D18*F18 | J18: =D18-B18 | K18: =D18/B18 | L18: =C18/B18
A19: 12 | B19: =AVERAGEIFS(Data!$D$5:$D$3656,Data!$C$5:$C$3656,$A19) | C19: =AVERAGEIFS(Data!$H$5:$H$3656,Data!$C$5:$C$3656,$A19) | D19: =AVERAGEIFS(Data!$P$5:$P$3604,Data!$L$5:$L$3604,$A19) | E19: =COUNTIF(Data!$C$5:$C$3656,$A19)/$B$2 | F19: =COUNTIF(Data!$L$5:$L$3604,$A19)/$B$2 | G19: =B19*E19 | H19: =C19*E19 | I19: =D19*F19 | J19: =D19-B19 | K19: =D19/B19 | L19: =C19/B19
A20: Year | E20: =SUM(E8:E19) | F20: =SUM(F8:F19) | G20: =SUM(G8:G19) | H20: =SUM(H8:H19) | I20: =SUM(I8:I19) | K20: =I20/G20 | L20: =H20/G20
A22: GCM annual total, wrong way: mean daily rain x 365.25 days [mm] | D22: =AVERAGE(Data!$P$5:$P$3604)*365.25
A23: GCM annual total, right way: mean daily rain x 360 days [mm] | D23: =AVERAGE(Data!$P$5:$P$3604)*360
A24: Overstatement from ignoring the 360-day calendar [%] | D24: =(D22/D23-1)*100
A25: A rate in mm/day does not depend on the calendar, but a total does: always multiply by the number of days of the calendar the data use (the same applies to monthly flow volumes).
A27: B. Daily statistics over all days
A28: statistic | B28: obs | C28: reanalysis | D28: GCM | E28: reanalysis - obs | F28: GCM - obs | G28: reanalysis / obs | H28: GCM / obs
A29: mean rainfall [mm/day] | B29: =AVERAGE(Data!$D$5:$D$3656) | C29: =AVERAGE(Data!$H$5:$H$3656) | D29: =AVERAGE(Data!$P$5:$P$3604) | E29: =C29-B29 | F29: =D29-B29 | G29: =C29/B29 | H29: =D29/B29
A30: standard deviation of daily rainfall [mm/day] | B30: =STDEV.S(Data!$D$5:$D$3656) | C30: =STDEV.S(Data!$H$5:$H$3656) | D30: =STDEV.S(Data!$P$5:$P$3604) | E30: =C30-B30 | F30: =D30-B30 | G30: =C30/B30 | H30: =D30/B30
A31: wet-day fraction (>= threshold) | B31: =COUNTIF(Data!$D$5:$D$3656,">="&$B$3)/COUNT(Data!$D$5:$D$3656) | C31: =COUNTIF(Data!$H$5:$H$3656,">="&$B$3)/COUNT(Data!$H$5:$H$3656) | D31: =COUNTIF(Data!$P$5:$P$3604,">="&$B$3)/COUNT(Data!$P$5:$P$3604) | E31: =C31-B31 | F31: =D31-B31 | G31: =C31/B31 | H31: =D31/B31
A32: mean wet-day intensity [mm/day] | B32: =AVERAGEIF(Data!$D$5:$D$3656,">="&$B$3) | C32: =AVERAGEIF(Data!$H$5:$H$3656,">="&$B$3) | D32: =AVERAGEIF(Data!$P$5:$P$3604,">="&$B$3) | E32: =C32-B32 | F32: =D32-B32 | G32: =C32/B32 | H32: =D32/B32
A33: 95th percentile of all days [mm/day] | B33: =PERCENTILE.INC(Data!$D$5:$D$3656,0.95) | C33: =PERCENTILE.INC(Data!$H$5:$H$3656,0.95) | D33: =PERCENTILE.INC(Data!$P$5:$P$3604,0.95) | E33: =C33-B33 | F33: =D33-B33 | G33: =C33/B33 | H33: =D33/B33
A34: 99th percentile of all days [mm/day] | B34: =PERCENTILE.INC(Data!$D$5:$D$3656,0.99) | C34: =PERCENTILE.INC(Data!$H$5:$H$3656,0.99) | D34: =PERCENTILE.INC(Data!$P$5:$P$3604,0.99) | E34: =C34-B34 | F34: =D34-B34 | G34: =C34/B34 | H34: =D34/B34
A35: maximum daily rainfall [mm/day] | B35: =MAX(Data!$D$5:$D$3656) | C35: =MAX(Data!$H$5:$H$3656) | D35: =MAX(Data!$P$5:$P$3604) | E35: =C35-B35 | F35: =D35-B35 | G35: =C35/B35 | H35: =D35/B35
A36: mean temperature [degC] | B36: =AVERAGE(Data!$E$5:$E$3656) | C36: =AVERAGE(Data!$I$5:$I$3656) | D36: =AVERAGE(Data!$Q$5:$Q$3604) | E36: =C36-B36 | F36: =D36-B36 | G36: =C36/B36 | H36: =D36/B36
A37: standard deviation of daily temperature [degC] | B37: =STDEV.S(Data!$E$5:$E$3656) | C37: =STDEV.S(Data!$I$5:$I$3656) | D37: =STDEV.S(Data!$Q$5:$Q$3604) | E37: =C37-B37 | F37: =D37-B37 | G37: =C37/B37 | H37: =D37/B37
A39: C. Is the series synchronised with the real weather?
A40: Daily correlation, reanalysis rain vs observed rain | B40: =CORREL(Data!$D$5:$D$3656,Data!$H$5:$H$3656)
A41: R squared of the same pair | B41: =RSQ(Data!$H$5:$H$3656,Data!$D$5:$D$3656)
A42: Daily correlation, reanalysis temperature vs observed | B42: =CORREL(Data!$E$5:$E$3656,Data!$I$5:$I$3656)
A43: Correlation of the 12 monthly means, GCM vs obs | B43: =CORREL(B8:B19,D8:D19)
A44: Correlation of the 12 monthly means, reanalysis vs obs | B44: =CORREL(B8:B19,C8:C19)
A45: A free-running GCM has its own weather: its day-to-day correlation with observed days is about zero once the shared seasonal cycle is removed (the notebook pairs days by date to show this). Only its climatology (monthly means, distribution) can be compared. A reanalysis assimilates observations, so its days track real days.
...

Sheet Method_guide
A1: Which downscaling scheme? A checklist that mirrors the flow chart of the notebook
A2: Answer Y or N (blue cells). The first question answered Y, read left to right, decides the core method (predictor skill is tested against the threshold in B3); the last two questions add temporal and spatial downscaling. A guide, not a rule.
A3: Predictor-skill threshold (|r| between local variable and large-scale predictors) | B3: 0.5
A5: Project | B5: Q1 Only a change factor needed? | C5: Q2 Is a corrected GCM distribution enough (no day-to-day match needed)? | D5: Q3 Predictor skill r (reanalysis period) | E5: Q4 Need many equally likely series / changed variability? | F5: Q5 Rain tied to circulation classes? | G5: Need sub-daily output? | H5: Need finer grid / many sites? | I5: Core method | J5: Add-ons | K5: Where it is taught
A6: Seasonal inflow change to a reservoir, 2070-2100 vs 1981-2010 | B6: Y | C6: N | D6: 0.3 | E6: N | F6: N | G6: N | H6: N | I6: =IF(B6="Y","Delta change (change factors)",IF(C6="Y","Bias correction (scaling, quantile mapping)",IF(D6>=$B$3,"Regression downscaling (perfect prognosis)",IF(E6="Y","Weather generator",IF(F6="Y","Weather typing + stochastic model","Dynamical (RCM) output + bias correction"))))) | J6: =IF(AND(G6<>"Y",H6<>"Y"),"none",TRIM(IF(G6="Y","+ temporal downscaling ","")&IF(H6="Y","+ spatial downscaling",""))) | K6: =INDEX($B$18:$B$23,MATCH(I6,$A$18:$A$23,0))
A7: Monthly water balance with a lumped model (Lecture 7), driven by corrected GCM rain | B7: N | C7: Y | D7: 0.3 | E7: N | F7: N | G7: N | H7: N | I7: =IF(B7="Y","Delta change (change factors)",IF(C7="Y","Bias correction (scaling, quantile mapping)",IF(D7>=$B$3,"Regression downscaling (perfect prognosis)",IF(E7="Y","Weather generator",IF(F7="Y","Weather typing + stochastic model","Dynamical (RCM) output + bias correction"))))) | J7: =IF(AND(G7<>"Y",H7<>"Y"),"none",TRIM(IF(G7="Y","+ temporal downscaling ","")&IF(H7="Y","+ spatial downscaling",""))) | K7: =INDEX($B$18:$B$23,MATCH(I7,$A$18:$A$23,0))
A8: Daily temperature for a crop model, strong link to reanalysis temperature | B8: N | C8: N | D8: 0.9 | E8: N | F8: N | G8: N | H8: N | I8: =IF(B8="Y","Delta change (change factors)",IF(C8="Y","Bias correction (scaling, quantile mapping)",IF(D8>=$B$3,"Regression downscaling (perfect prognosis)",IF(E8="Y","Weather generator",IF(F8="Y","Weather typing + stochastic model","Dynamical (RCM) output + bias correction"))))) | J8: =IF(AND(G8<>"Y",H8<>"Y"),"none",TRIM(IF(G8="Y","+ temporal downscaling ","")&IF(H8="Y","+ spatial downscaling",""))) | K8: =INDEX($B$18:$B$23,MATCH(I8,$A$18:$A$23,0))
A9: Drought risk: thousands of 30-year rainfall series | B9: N | C9: N | D9: 0.3 | E9: Y | F9: N | G9: N | H9: N | I9: =IF(B9="Y","Delta change (change factors)",IF(C9="Y","Bias correction (scaling, quantile mapping)",IF(D9>=$B$3,"Regression downscaling (perfect prognosis)",IF(E9="Y","Weather generator",IF(F9="Y","Weather typing + stochastic model","Dynamical (RCM) output + bias correction"))))) | J9: =IF(AND(G9<>"Y",H9<>"Y"),"none",TRIM(IF(G9="Y","+ temporal downscaling ","")&IF(H9="Y","+ spatial downscaling",""))) | K9: =INDEX($B$18:$B$23,MATCH(I9,$A$18:$A$23,0))
A10: Monsoon-depression rainfall linked to circulation types | B10: N | C10: N | D10: 0.3 | E10: N | F10: Y | G10: N | H10: N | I10: =IF(B10="Y","Delta change (change factors)",IF(C10="Y","Bias correction (scaling, quantile mapping)",IF(D10>=$B$3,"Regression downscaling (perfect prognosis)",IF(E10="Y","Weather generator",IF(F10="Y","Weather typing + stochastic model","Dynamical (RCM) output + bias correction"))))) | J10: =IF(AND(G10<>"Y",H10<>"Y"),"none",TRIM(IF(G10="Y","+ temporal downscaling ","")&IF(H10="Y","+ spatial downscaling",""))) | K10: =INDEX($B$18:$B$23,MATCH(I10,$A$18:$A$23,0))
A11: Urban drainage design: hourly rain for a 20 km2 catchment | B11: N | C11: N | D11: 0.3 | E11: Y | F11: N | G11: Y | H11: N | I11: =IF(B11="Y","Delta change (change factors)",IF(C11="Y","Bias correction (scaling, quantile mapping)",IF(D11>=$B$3,"Regression downscaling (perfect prognosis)",IF(E11="Y","Weather generator",IF(F11="Y","Weather typing + stochastic model","Dynamical (RCM) output + bias correction"))))) | J11: =IF(AND(G11<>"Y",H11<>"Y"),"none",TRIM(IF(G11="Y","+ temporal downscaling ","")&IF(H11="Y","+ spatial downscaling",""))) | K11: =INDEX($B$18:$B$23,MATCH(I11,$A$18:$A$23,0))
A12: Distributed hydrological model on a 1 km grid | B12: N | C12: Y | D12: 0.3 | E12: N | F12: N | G12: N | H12: Y | I12: =IF(B12="Y","Delta change (change factors)",IF(C12="Y","Bias correction (scaling, quantile mapping)",IF(D12>=$B$3,"Regression downscaling (perfect prognosis)",IF(E12="Y","Weather generator",IF(F12="Y","Weather typing + stochastic model","Dynamical (RCM) output + bias correction"))))) | J12: =IF(AND(G12<>"Y",H12<>"Y"),"none",TRIM(IF(G12="Y","+ temporal downscaling ","")&IF(H12="Y","+ spatial downscaling",""))) | K12: =INDEX($B$18:$B$23,MATCH(I12,$A$18:$A$23,0))
A13: Your case (change the blue cells) | B13: N | C13: N | D13: 0.3 | E13: N | F13: N | G13: N | H13: N | I13: =IF(B13="Y","Delta change (change factors)",IF(C13="Y","Bias correction (scaling, quantile mapping)",IF(D13>=$B$3,"Regression downscaling (perfect prognosis)",IF(E13="Y","Weather generator",IF(F13="Y","Weather typing + stochastic model","Dynamical (RCM) output + bias correction"))))) | J13: =IF(AND(G13<>"Y",H13<>"Y"),"none",TRIM(IF(G13="Y","+ temporal downscaling ","")&IF(H13="Y","+ spatial downscaling",""))) | K13: =INDEX($B$18:$B$23,MATCH(I13,$A$18:$A$23,0))
A16: Lookup table
A17: Core method | B17: Lecture(s) | C17: What it gives you
A18: Delta change (change factors) | B18: 18 | C18: observed record scaled by a projected change; no change in wet-day frequency or sequence
A19: Bias correction (scaling, quantile mapping) | B19: 18 | C19: model series with the observed distribution; model weather kept
A20: Regression downscaling (perfect prognosis) | B20: 19, 20 | C20: local series from large-scale predictors; needs skill and stationarity
A21: Weather generator | B21: 21 | C21: unlimited synthetic series with perturbed statistics; no unique day
A22: Weather typing + stochastic model | B22: 22 | C22: rain conditional on circulation classes
A23: Dynamical (RCM) output + bias correction | B23: 14 (Section 4) | C23: physically consistent fine-scale fields, expensive; still needs bias correction
