Workbook

Sheet README
A1: Lecture 23: Spatial downscaling. Companion workbook (CE524 Applied Hydroclimatology, IIT Mandi)
A3: Purpose: hand-checkable worked examples of the lecture, with live formulas: (1) bilinear interpolation, (2) BCSD from a 2x2 coarse to a 4x4 fine grid, (3) constructed analogues with a ridge term.
A4: ALL NUMBERS ARE SYNTHETIC. They were invented for teaching; none is an observation or a model output. To use real data, replace the blue cells on the sheet Data (e.g. IMD gridded rainfall for the fine fields, a CMIP6 or NEX-GDDP-CMIP6 field averaged to the coarse cells).
A6: Colour code: BLUE font = input (type over it). BLACK font = formula (do not overwrite). Yellow bars = step headings. Blue shading = column headings. Hover over a heading with a red corner to read a note about the formula.
A8: Sheets
A9: Data: every input of the three examples in one place.
A10: Bilinear: 4x4 coarse grid, six target points; weights from the formulas, two-step versus four-weight value, nearest neighbour.
A11: BCSD_2x2: factor = coarse GCM / coarse climatology, interpolated factor, rescaling by the fine climatology (rainfall, multiplicative); anomaly version for temperature (additive).
A12: BCCA: 8 library days, RMSE ranking, the N=3 best analogues, weights by LINEST, by the normal equations and by ridge (MMULT/MINVERSE), downscaled 4x4 field.
A14: How to use: change a blue input (for example the ridge lambda on Data) and watch the formulas follow. Set lambda = 0 on Data: the ridge weights become the plain least-squares weights.
A15: Only widely supported functions are used (AVERAGE, SUMPRODUCT, INDEX, MATCH, RANK, IF, MIN, MAX, INT, MMULT, MINVERSE, TRANSPOSE, LINEST, SQRT, SUMXMY2). The matrix formulas are legacy array formulas (they work in Excel and Google Sheets).
A16: The file was written by a script (openpyxl) and carries no stored results; Excel computes them when the file is opened (press F9 if cells look empty). The same numbers are reproduced in lecture-23-spatial-downscaling.ipynb.
A17: Units: precipitation mm/day, temperature degC. Grid indices: row 0 is the first row listed, column 0 the first column listed.
A18: Example of an input (blue): | B18: 1
A19: Example of a formula (black): | B19: =B18*2

Sheet Data
A1: Data: synthetic inputs for the three worked examples (blue = input)
A2: Same numbers as the CSV files in data/downscaling/lec23/ (bilinear_*, bcsd_*, ca_*).
A4: A. Coarse grid z (mm/day) at nodes x = 0..3 (columns), y = 0..3 (rows) | G4: A. Target points (x, y in coarse-cell units)
A5: y \ x | B5: 0 | C5: 1 | D5: 2 | E5: 3 | G5: id | H5: x | I5: y
A6: 0 | B6: 12 | C6: 18 | D6: 10 | E6: 6 | G6: 1 | H6: 0.5 | I6: 0.5
A7: 1 | B7: 20 | C7: 30 | D7: 16 | E7: 9 | G7: 2 | H7: 1.25 | I7: 1.75
A8: 2 | B8: 14 | C8: 22 | D8: 13 | E8: 7 | G8: 3 | H8: 1 | I8: 1
A9: 3 | B9: 8 | C9: 11 | D9: 9 | E9: 5 | G9: 4 | H9: 2.4 | I9: 0.6
G10: 5 | H10: 0.2 | I10: 2.8
G11: 6 | H11: 2.9 | I11: 2.9
A12: B. BCSD inputs: precipitation (mm/day), 2x2 coarse and 4x4 fine; temperature (degC)
A13: B1 Coarse climatology of observations | G13: B4 Coarse clim. T (degC)
B14: 2 | C14: 4 | H14: 24 | I14: 22
B15: 6 | C15: 8 | H15: 20 | I15: 18
A17: B2 Bias-corrected coarse GCM, today | G17: B5 BC-GCM T today (degC)
B18: 3 | C18: 4 | H18: 26 | I18: 23
B19: 3 | C19: 12 | H19: 21 | I19: 17
A21: B3 Fine climatology of observations | G21: B6 Fine clim. T (degC)
B22: 1 | C22: 3 | D22: 3 | E22: 5 | H22: 25.5 | I22: 22.5 | J22: 22.5 | K22: 21.5
B23: 1.5 | C23: 2.5 | D23: 3.5 | E23: 4.5 | H23: 25 | I23: 23 | J23: 22.5 | K23: 21.5
B24: 4 | C24: 8 | D24: 6 | E24: 10 | H24: 21 | I24: 20 | J24: 18.5 | K24: 17.5
B25: 5 | C25: 7 | D25: 7 | E25: 9 | H25: 20 | I25: 19 | J25: 18.5 | K25: 17.5
A28: C. Constructed analogues: library of 8 days, fine 4x4 field per day (mm/day); fine cell id = 4*row + col + 1
A29: day | B29: 1 | C29: 2 | D29: 3 | E29: 4 | F29: 5 | G29: 6 | H29: 7 | I29: 8 | J29: 9 | K29: 10 | L29: 11 | M29: 12 | N29: 13 | O29: 14 | P29: 15 | Q29: 16
A30: 1 | B30: 1.1 | C30: 4.4 | D30: 5.3 | E30: 11 | F30: 2.4 | G30: 3.3 | H30: 4.3 | I30: 8.8 | J30: 10.2 | K30: 13.6 | L30: 6.5 | M30: 11.7 | N30: 12.7 | O30: 11.6 | P30: 6.5 | Q30: 13.7
A31: 2 | B31: 1 | C31: 3.1 | D31: 2.9 | E31: 7 | F31: 1.8 | G31: 2.5 | H31: 4.7 | I31: 6.9 | J31: 2.9 | K31: 8.8 | L31: 5.3 | M31: 11.3 | N31: 4 | O31: 8.4 | P31: 8.2 | Q31: 9.8
A32: 3 | B32: 0.7 | C32: 1.8 | D32: 1.7 | E32: 4.5 | F32: 0.9 | G32: 3 | H32: 3.7 | I32: 2.1 | J32: 3.7 | K32: 4.9 | L32: 5.1 | M32: 8.6 | N32: 2.3 | O32: 5.5 | P32: 5.5 | Q32: 10.1
A33: 4 | B33: 2 | C33: 3.5 | D33: 4.4 | E33: 6.3 | F33: 3.7 | G33: 4.8 | H33: 11.7 | I33: 8.8 | J33: 8.3 | K33: 16.6 | L33: 8.1 | M33: 15.8 | N33: 12.1 | O33: 10 | P33: 12 | Q33: 14.4
A34: 5 | B34: 1.4 | C34: 4.5 | D34: 5 | E34: 8 | F34: 1.8 | G34: 5.1 | H34: 3.7 | I34: 4.9 | J34: 4.2 | K34: 16.7 | L34: 8.4 | M34: 11.6 | N34: 5.5 | O34: 12.4 | P34: 7.9 | Q34: 9.6
A35: 6 | B35: 1.2 | C35: 4.8 | D35: 5.2 | E35: 7.7 | F35: 2.6 | G35: 6.5 | H35: 5.2 | I35: 5.4 | J35: 4 | K35: 13.2 | L35: 9.4 | M35: 19 | N35: 7.6 | O35: 10.6 | P35: 9.9 | Q35: 13.5
A36: 7 | B36: 0.7 | C36: 2.4 | D36: 4.1 | E36: 4.4 | F36: 0.7 | G36: 3.2 | H36: 3 | I36: 2.6 | J36: 4 | K36: 6.2 | L36: 3.8 | M36: 6.3 | N36: 2.8 | O36: 5.5 | P36: 7.4 | Q36: 6.3
A37: 8 | B37: 2.5 | C37: 2.9 | D37: 4.5 | E37: 6.4 | F37: 1.5 | G37: 2.6 | H37: 4.9 | I37: 7.2 | J37: 4.8 | K37: 11.4 | L37: 10.4 | M37: 15.3 | N37: 9.1 | O37: 11.3 | P37: 11.3 | Q37: 21.8
A39: Target coarse field, cells (1,1) (1,2) (2,1) (2,2) | B39: 3.3 | C39: 6.3 | D39: 8.2 | E39: 13.6
A40: Truth fine field (only to check) | B40: 1.7 | C40: 4.4 | D40: 5.2 | E40: 5.3 | F40: 1.9 | G40: 4.4 | H40: 5.9 | I40: 10 | J40: 5.6 | K40: 7.2 | L40: 15.1 | M40: 19.4 | N40: 5.1 | O40: 14.8 | P40: 9.9 | Q40: 7.3
A42: Ridge lambda (mm2/day2) | B42: 5

Sheet Bilinear
A1: Bilinear interpolation: linear in x, then linear in y; equal to the area-weighted mean of the 4 corners
A2: x runs along columns, y along rows. (i0, j0) is the lower-left node of the cell that holds the point; tx, ty in [0,1] are the fractions of the way across it.
A4: id | B4: x | C4: y | D4: i0 | E4: j0 | F4: tx | G4: ty | H4: w00 | I4: w10 | J4: w01 | K4: w11 | L4: sum w | M4: z00 | N4: z10 | O4: z01 | P4: z11 | Q4: z bottom (x first) | R4: z top (x first) | S4: z two-step | T4: z four-weight | U4: two-step minus four-weight | V4: nearest neighbour | W4: nearest minus bilinear
A5: =Data!G6 | B5: =Data!H6 | C5: =Data!I6 | D5: =MIN(INT(B5),COLUMNS(Data!$B$6:$E$9)-2) | E5: =MIN(INT(C5),ROWS(Data!$B$6:$E$9)-2) | F5: =B5-D5 | G5: =C5-E5 | H5: =(1-F5)*(1-G5) | I5: =F5*(1-G5) | J5: =(1-F5)*G5 | K5: =F5*G5 | L5: =SUM(H5:K5) | M5: =INDEX(Data!$B$6:$E$9,E5+1,D5+1) | N5: =INDEX(Data!$B$6:$E$9,E5+1,D5+2) | O5: =INDEX(Data!$B$6:$E$9,E5+2,D5+1) | P5: =INDEX(Data!$B$6:$E$9,E5+2,D5+2) | Q5: =(1-F5)*M5+F5*N5 | R5: =(1-F5)*O5+F5*P5 | S5: =(1-G5)*Q5+G5*R5 | T5: =SUMPRODUCT(H5:K5,M5:P5) | U5: =S5-T5 | V5: =INDEX(Data!$B$6:$E$9,INT(C5+0.5)+1,INT(B5+0.5)+1) | W5: =V5-T5
A6: =Data!G7 | B6: =Data!H7 | C6: =Data!I7 | D6: =MIN(INT(B6),COLUMNS(Data!$B$6:$E$9)-2) | E6: =MIN(INT(C6),ROWS(Data!$B$6:$E$9)-2) | F6: =B6-D6 | G6: =C6-E6 | H6: =(1-F6)*(1-G6) | I6: =F6*(1-G6) | J6: =(1-F6)*G6 | K6: =F6*G6 | L6: =SUM(H6:K6) | M6: =INDEX(Data!$B$6:$E$9,E6+1,D6+1) | N6: =INDEX(Data!$B$6:$E$9,E6+1,D6+2) | O6: =INDEX(Data!$B$6:$E$9,E6+2,D6+1) | P6: =INDEX(Data!$B$6:$E$9,E6+2,D6+2) | Q6: =(1-F6)*M6+F6*N6 | R6: =(1-F6)*O6+F6*P6 | S6: =(1-G6)*Q6+G6*R6 | T6: =SUMPRODUCT(H6:K6,M6:P6) | U6: =S6-T6 | V6: =INDEX(Data!$B$6:$E$9,INT(C6+0.5)+1,INT(B6+0.5)+1) | W6: =V6-T6
A7: =Data!G8 | B7: =Data!H8 | C7: =Data!I8 | D7: =MIN(INT(B7),COLUMNS(Data!$B$6:$E$9)-2) | E7: =MIN(INT(C7),ROWS(Data!$B$6:$E$9)-2) | F7: =B7-D7 | G7: =C7-E7 | H7: =(1-F7)*(1-G7) | I7: =F7*(1-G7) | J7: =(1-F7)*G7 | K7: =F7*G7 | L7: =SUM(H7:K7) | M7: =INDEX(Data!$B$6:$E$9,E7+1,D7+1) | N7: =INDEX(Data!$B$6:$E$9,E7+1,D7+2) | O7: =INDEX(Data!$B$6:$E$9,E7+2,D7+1) | P7: =INDEX(Data!$B$6:$E$9,E7+2,D7+2) | Q7: =(1-F7)*M7+F7*N7 | R7: =(1-F7)*O7+F7*P7 | S7: =(1-G7)*Q7+G7*R7 | T7: =SUMPRODUCT(H7:K7,M7:P7) | U7: =S7-T7 | V7: =INDEX(Data!$B$6:$E$9,INT(C7+0.5)+1,INT(B7+0.5)+1) | W7: =V7-T7
A8: =Data!G9 | B8: =Data!H9 | C8: =Data!I9 | D8: =MIN(INT(B8),COLUMNS(Data!$B$6:$E$9)-2) | E8: =MIN(INT(C8),ROWS(Data!$B$6:$E$9)-2) | F8: =B8-D8 | G8: =C8-E8 | H8: =(1-F8)*(1-G8) | I8: =F8*(1-G8) | J8: =(1-F8)*G8 | K8: =F8*G8 | L8: =SUM(H8:K8) | M8: =INDEX(Data!$B$6:$E$9,E8+1,D8+1) | N8: =INDEX(Data!$B$6:$E$9,E8+1,D8+2) | O8: =INDEX(Data!$B$6:$E$9,E8+2,D8+1) | P8: =INDEX(Data!$B$6:$E$9,E8+2,D8+2) | Q8: =(1-F8)*M8+F8*N8 | R8: =(1-F8)*O8+F8*P8 | S8: =(1-G8)*Q8+G8*R8 | T8: =SUMPRODUCT(H8:K8,M8:P8) | U8: =S8-T8 | V8: =INDEX(Data!$B$6:$E$9,INT(C8+0.5)+1,INT(B8+0.5)+1) | W8: =V8-T8
A9: =Data!G10 | B9: =Data!H10 | C9: =Data!I10 | D9: =MIN(INT(B9),COLUMNS(Data!$B$6:$E$9)-2) | E9: =MIN(INT(C9),ROWS(Data!$B$6:$E$9)-2) | F9: =B9-D9 | G9: =C9-E9 | H9: =(1-F9)*(1-G9) | I9: =F9*(1-G9) | J9: =(1-F9)*G9 | K9: =F9*G9 | L9: =SUM(H9:K9) | M9: =INDEX(Data!$B$6:$E$9,E9+1,D9+1) | N9: =INDEX(Data!$B$6:$E$9,E9+1,D9+2) | O9: =INDEX(Data!$B$6:$E$9,E9+2,D9+1) | P9: =INDEX(Data!$B$6:$E$9,E9+2,D9+2) | Q9: =(1-F9)*M9+F9*N9 | R9: =(1-F9)*O9+F9*P9 | S9: =(1-G9)*Q9+G9*R9 | T9: =SUMPRODUCT(H9:K9,M9:P9) | U9: =S9-T9 | V9: =INDEX(Data!$B$6:$E$9,INT(C9+0.5)+1,INT(B9+0.5)+1) | W9: =V9-T9
A10: =Data!G11 | B10: =Data!H11 | C10: =Data!I11 | D10: =MIN(INT(B10),COLUMNS(Data!$B$6:$E$9)-2) | E10: =MIN(INT(C10),ROWS(Data!$B$6:$E$9)-2) | F10: =B10-D10 | G10: =C10-E10 | H10: =(1-F10)*(1-G10) | I10: =F10*(1-G10) | J10: =(1-F10)*G10 | K10: =F10*G10 | L10: =SUM(H10:K10) | M10: =INDEX(Data!$B$6:$E$9,E10+1,D10+1) | N10: =INDEX(Data!$B$6:$E$9,E10+1,D10+2) | O10: =INDEX(Data!$B$6:$E$9,E10+2,D10+1) | P10: =INDEX(Data!$B$6:$E$9,E10+2,D10+2) | Q10: =(1-F10)*M10+F10*N10 | R10: =(1-F10)*O10+F10*P10 | S10: =(1-G10)*Q10+G10*R10 | T10: =SUMPRODUCT(H10:K10,M10:P10) | U10: =S10-T10 | V10: =INDEX(Data!$B$6:$E$9,INT(C10+0.5)+1,INT(B10+0.5)+1) | W10: =V10-T10
A12: Interpolation adds no information: the results stay inside the range of the coarse values (smoothness, no new extremes)
A13: Smallest coarse value | E13: =MIN(Data!$B$6:$E$9)
A14: Largest coarse value | E14: =MAX(Data!$B$6:$E$9)
A15: Smallest interpolated value | E15: =MIN(T5:T10)
A16: Largest interpolated value | E16: =MAX(T5:T10)

Sheet BCSD_2x2
A1: BCSD, tiny example: 2x2 coarse to 4x4 fine (quantile mapping assumed done: the coarse GCM field is already bias corrected)
A2: Rainfall: MULTIPLICATIVE scaling (factor = today / climatology). Temperature (lower part): ADDITIVE scaling (anomaly = today - climatology).
A4: Step 0. Inputs (links to Data)
A5: Coarse clim. Ybar (mm/day) | E5: BC-GCM coarse today y (mm/day) | I5: Fine clim. xbar (mm/day)
B6: =Data!B14 | C6: =Data!C14 | F6: =Data!B18 | G6: =Data!C18 | J6: =Data!B22 | K6: =Data!C22 | L6: =Data!D22 | M6: =Data!E22
B7: =Data!B15 | C7: =Data!C15 | F7: =Data!B19 | G7: =Data!C19 | J7: =Data!B23 | K7: =Data!C23 | L7: =Data!D23 | M7: =Data!E23
J8: =Data!B24 | K8: =Data!C24 | L8: =Data!D24 | M8: =Data!E24
A9: Check: block means of xbar (= Ybar?) | J9: =Data!B25 | K9: =Data!C25 | L9: =Data!D25 | M9: =Data!E25
B10: =AVERAGE(J6:K7) | C10: =AVERAGE(L6:M7)
B11: =AVERAGE(J8:K9) | C11: =AVERAGE(L8:M9)
A13: Step 1. Factor R = y / Ybar (>1: wetter than usual)
B14: =F6/B6 | C14: =G6/C6
B15: =F7/B7 | C15: =G7/C7
A17: Step 2. Interpolation weights along one axis (fine cell centres vs coarse cell centres)
A18: Refinement factor f (fine cells per coarse cell) | C18: 2
A19: First coarse centre c0 = (f-1)/2 (fine-cell units) | C19: =(C18-1)/2
A20: Second coarse centre c1 = c0 + f | C20: =C19+C18
A21: Fine cell centre index xi | B21: 0 | C21: 1 | D21: 2 | E21: 3
A22: Weight t = clip((xi - c0)/(c1 - c0), 0, 1) | B22: =MIN(1,MAX(0,(B21-$C$19)/($C$20-$C$19))) | C22: =MIN(1,MAX(0,(C21-$C$19)/($C$20-$C$19))) | D22: =MIN(1,MAX(0,(D21-$C$19)/($C$20-$C$19))) | E22: =MIN(1,MAX(0,(E21-$C$19)/($C$20-$C$19)))
A24: Step 3. Interpolated factor R_f (along x with t, then along y with t_y) | F24: t_y (row)
A25: 0 | B25: =(1-$F25)*((1-B$22)*$B$14+B$22*$C$14)+$F25*((1-B$22)*$B$15+B$22*$C$15) | C25: =(1-$F25)*((1-C$22)*$B$14+C$22*$C$14)+$F25*((1-C$22)*$B$15+C$22*$C$15) | D25: =(1-$F25)*((1-D$22)*$B$14+D$22*$C$14)+$F25*((1-D$22)*$B$15+D$22*$C$15) | E25: =(1-$F25)*((1-E$22)*$B$14+E$22*$C$14)+$F25*((1-E$22)*$B$15+E$22*$C$15) | F25: =INDEX($B$22:$E$22,A25+1)
A26: 1 | B26: =(1-$F26)*((1-B$22)*$B$14+B$22*$C$14)+$F26*((1-B$22)*$B$15+B$22*$C$15) | C26: =(1-$F26)*((1-C$22)*$B$14+C$22*$C$14)+$F26*((1-C$22)*$B$15+C$22*$C$15) | D26: =(1-$F26)*((1-D$22)*$B$14+D$22*$C$14)+$F26*((1-D$22)*$B$15+D$22*$C$15) | E26: =(1-$F26)*((1-E$22)*$B$14+E$22*$C$14)+$F26*((1-E$22)*$B$15+E$22*$C$15) | F26: =INDEX($B$22:$E$22,A26+1)
A27: 2 | B27: =(1-$F27)*((1-B$22)*$B$14+B$22*$C$14)+$F27*((1-B$22)*$B$15+B$22*$C$15) | C27: =(1-$F27)*((1-C$22)*$B$14+C$22*$C$14)+$F27*((1-C$22)*$B$15+C$22*$C$15) | D27: =(1-$F27)*((1-D$22)*$B$14+D$22*$C$14)+$F27*((1-D$22)*$B$15+D$22*$C$15) | E27: =(1-$F27)*((1-E$22)*$B$14+E$22*$C$14)+$F27*((1-E$22)*$B$15+E$22*$C$15) | F27: =INDEX($B$22:$E$22,A27+1)
A28: 3 | B28: =(1-$F28)*((1-B$22)*$B$14+B$22*$C$14)+$F28*((1-B$22)*$B$15+B$22*$C$15) | C28: =(1-$F28)*((1-C$22)*$B$14+C$22*$C$14)+$F28*((1-C$22)*$B$15+C$22*$C$15) | D28: =(1-$F28)*((1-D$22)*$B$14+D$22*$C$14)+$F28*((1-D$22)*$B$15+D$22*$C$15) | E28: =(1-$F28)*((1-E$22)*$B$14+E$22*$C$14)+$F28*((1-E$22)*$B$15+E$22*$C$15) | F28: =INDEX($B$22:$E$22,A28+1)
A30: Step 4. Downscaled rainfall P = R_f x xbar (mm/day) | G30: For comparison: plain bilinear interpolation of y (no climatology)
B31: =B25*J6 | C31: =C25*K6 | D31: =D25*L6 | E31: =E25*M6 | H31: =(1-$F25)*((1-B$22)*$F$6+B$22*$G$6)+$F25*((1-B$22)*$F$7+B$22*$G$7) | I31: =(1-$F25)*((1-C$22)*$F$6+C$22*$G$6)+$F25*((1-C$22)*$F$7+C$22*$G$7) | J31: =(1-$F25)*((1-D$22)*$F$6+D$22*$G$6)+$F25*((1-D$22)*$F$7+D$22*$G$7) | K31: =(1-$F25)*((1-E$22)*$F$6+E$22*$G$6)+$F25*((1-E$22)*$F$7+E$22*$G$7)
B32: =B26*J7 | C32: =C26*K7 | D32: =D26*L7 | E32: =E26*M7 | H32: =(1-$F26)*((1-B$22)*$F$6+B$22*$G$6)+$F26*((1-B$22)*$F$7+B$22*$G$7) | I32: =(1-$F26)*((1-C$22)*$F$6+C$22*$G$6)+$F26*((1-C$22)*$F$7+C$22*$G$7) | J32: =(1-$F26)*((1-D$22)*$F$6+D$22*$G$6)+$F26*((1-D$22)*$F$7+D$22*$G$7) | K32: =(1-$F26)*((1-E$22)*$F$6+E$22*$G$6)+$F26*((1-E$22)*$F$7+E$22*$G$7)
B33: =B27*J8 | C33: =C27*K8 | D33: =D27*L8 | E33: =E27*M8 | H33: =(1-$F27)*((1-B$22)*$F$6+B$22*$G$6)+$F27*((1-B$22)*$F$7+B$22*$G$7) | I33: =(1-$F27)*((1-C$22)*$F$6+C$22*$G$6)+$F27*((1-C$22)*$F$7+C$22*$G$7) | J33: =(1-$F27)*((1-D$22)*$F$6+D$22*$G$6)+$F27*((1-D$22)*$F$7+D$22*$G$7) | K33: =(1-$F27)*((1-E$22)*$F$6+E$22*$G$6)+$F27*((1-E$22)*$F$7+E$22*$G$7)
B34: =B28*J9 | C34: =C28*K9 | D34: =D28*L9 | E34: =E28*M9 | H34: =(1-$F28)*((1-B$22)*$F$6+B$22*$G$6)+$F28*((1-B$22)*$F$7+B$22*$G$7) | I34: =(1-$F28)*((1-C$22)*$F$6+C$22*$G$6)+$F28*((1-C$22)*$F$7+C$22*$G$7) | J34: =(1-$F28)*((1-D$22)*$F$6+D$22*$G$6)+$F28*((1-D$22)*$F$7+D$22*$G$7) | K34: =(1-$F28)*((1-E$22)*$F$6+E$22*$G$6)+$F28*((1-E$22)*$F$7+E$22*$G$7)
A36: Step 5. Check: block means of P, and minus y | E36: difference:
B37: =AVERAGE(B31:C32) | C37: =AVERAGE(D31:E32) | F37: =B37-F6 | G37: =C37-G6
B38: =AVERAGE(B33:C34) | C38: =AVERAGE(D33:E34) | F38: =B38-F7 | G38: =C38-G7
A40: Temperature, additive version
A41: Coarse clim. Tbar (degC) | E41: BC-GCM T today (degC) | I41: Fine clim. T (degC)
B42: =Data!H14 | C42: =Data!I14 | F42: =Data!H18 | G42: =Data!I18 | J42: =Data!H22 | K42: =Data!I22 | L42: =Data!J22 | M42: =Data!K22
B43: =Data!H15 | C43: =Data!I15 | F43: =Data!H19 | G43: =Data!I19 | J43: =Data!H23 | K43: =Data!I23 | L43: =Data!J23 | M43: =Data!K23
J44: =Data!H24 | K44: =Data!I24 | L44: =Data!J24 | M44: =Data!K24
J45: =Data!H25 | K45: =Data!I25 | L45: =Data!J25 | M45: =Data!K25
A47: Anomaly A = y - Tbar (K)
B48: =F42-B42 | C48: =G42-C42
...

Sheet BCCA
A1: Constructed analogues: today's coarse field as a combination of the coarse fields of N=3 similar days; reuse the weights on their fine fields
A2: q = 4 coarse cells, p = 16 fine cells, library of H = 8 days. No intercept: weights by plain least squares (LINEST) or ridge (MMULT/MINVERSE).
A4: Step 1. Coarse fields of the library days (mean of each 2x2 block of the fine field) and RMSE to today's target
A5: day | B5: cell 1 | C5: cell 2 | D5: cell 3 | E5: cell 4 | F5: RMSE to target | G5: rank (1 = most similar)
A6: =Data!A30 | B6: =AVERAGE(Data!B30,Data!C30,Data!F30,Data!G30) | C6: =AVERAGE(Data!D30,Data!E30,Data!H30,Data!I30) | D6: =AVERAGE(Data!J30,Data!K30,Data!N30,Data!O30) | E6: =AVERAGE(Data!L30,Data!M30,Data!P30,Data!Q30) | F6: =SQRT(SUMPRODUCT((B6:E6-Data!$B$39:$E$39)^2)/COLUMNS(B6:E6)) | G6: =RANK(F6,$F$6:$F$13,1)
A7: =Data!A31 | B7: =AVERAGE(Data!B31,Data!C31,Data!F31,Data!G31) | C7: =AVERAGE(Data!D31,Data!E31,Data!H31,Data!I31) | D7: =AVERAGE(Data!J31,Data!K31,Data!N31,Data!O31) | E7: =AVERAGE(Data!L31,Data!M31,Data!P31,Data!Q31) | F7: =SQRT(SUMPRODUCT((B7:E7-Data!$B$39:$E$39)^2)/COLUMNS(B7:E7)) | G7: =RANK(F7,$F$6:$F$13,1)
A8: =Data!A32 | B8: =AVERAGE(Data!B32,Data!C32,Data!F32,Data!G32) | C8: =AVERAGE(Data!D32,Data!E32,Data!H32,Data!I32) | D8: =AVERAGE(Data!J32,Data!K32,Data!N32,Data!O32) | E8: =AVERAGE(Data!L32,Data!M32,Data!P32,Data!Q32) | F8: =SQRT(SUMPRODUCT((B8:E8-Data!$B$39:$E$39)^2)/COLUMNS(B8:E8)) | G8: =RANK(F8,$F$6:$F$13,1)
A9: =Data!A33 | B9: =AVERAGE(Data!B33,Data!C33,Data!F33,Data!G33) | C9: =AVERAGE(Data!D33,Data!E33,Data!H33,Data!I33) | D9: =AVERAGE(Data!J33,Data!K33,Data!N33,Data!O33) | E9: =AVERAGE(Data!L33,Data!M33,Data!P33,Data!Q33) | F9: =SQRT(SUMPRODUCT((B9:E9-Data!$B$39:$E$39)^2)/COLUMNS(B9:E9)) | G9: =RANK(F9,$F$6:$F$13,1)
A10: =Data!A34 | B10: =AVERAGE(Data!B34,Data!C34,Data!F34,Data!G34) | C10: =AVERAGE(Data!D34,Data!E34,Data!H34,Data!I34) | D10: =AVERAGE(Data!J34,Data!K34,Data!N34,Data!O34) | E10: =AVERAGE(Data!L34,Data!M34,Data!P34,Data!Q34) | F10: =SQRT(SUMPRODUCT((B10:E10-Data!$B$39:$E$39)^2)/COLUMNS(B10:E10)) | G10: =RANK(F10,$F$6:$F$13,1)
A11: =Data!A35 | B11: =AVERAGE(Data!B35,Data!C35,Data!F35,Data!G35) | C11: =AVERAGE(Data!D35,Data!E35,Data!H35,Data!I35) | D11: =AVERAGE(Data!J35,Data!K35,Data!N35,Data!O35) | E11: =AVERAGE(Data!L35,Data!M35,Data!P35,Data!Q35) | F11: =SQRT(SUMPRODUCT((B11:E11-Data!$B$39:$E$39)^2)/COLUMNS(B11:E11)) | G11: =RANK(F11,$F$6:$F$13,1)
A12: =Data!A36 | B12: =AVERAGE(Data!B36,Data!C36,Data!F36,Data!G36) | C12: =AVERAGE(Data!D36,Data!E36,Data!H36,Data!I36) | D12: =AVERAGE(Data!J36,Data!K36,Data!N36,Data!O36) | E12: =AVERAGE(Data!L36,Data!M36,Data!P36,Data!Q36) | F12: =SQRT(SUMPRODUCT((B12:E12-Data!$B$39:$E$39)^2)/COLUMNS(B12:E12)) | G12: =RANK(F12,$F$6:$F$13,1)
A13: =Data!A37 | B13: =AVERAGE(Data!B37,Data!C37,Data!F37,Data!G37) | C13: =AVERAGE(Data!D37,Data!E37,Data!H37,Data!I37) | D13: =AVERAGE(Data!J37,Data!K37,Data!N37,Data!O37) | E13: =AVERAGE(Data!L37,Data!M37,Data!P37,Data!Q37) | F13: =SQRT(SUMPRODUCT((B13:E13-Data!$B$39:$E$39)^2)/COLUMNS(B13:E13)) | G13: =RANK(F13,$F$6:$F$13,1)
A15: Target y (BC-GCM) | B15: =Data!B39 | C15: =Data!C39 | D15: =Data!D39 | E15: =Data!E39
A17: Step 2. The N = 3 best analogue days
A18: k | B18: 1 | C18: 2 | D18: 3
A19: day index | B19: =MATCH(B18,$G$6:$G$13,0) | C19: =MATCH(C18,$G$6:$G$13,0) | D19: =MATCH(D18,$G$6:$G$13,0)
A20: RMSE | B20: =INDEX($F$6:$F$13,B19) | C20: =INDEX($F$6:$F$13,C19) | D20: =INDEX($F$6:$F$13,D19)
A22: Step 3. Y (q x N): coarse fields of the chosen days as columns; y: target
A23: cell | B23: day k=1 | C23: day k=2 | D23: day k=3 | E23: y (target)
A24: 1 | B24: =INDEX($B$6:$E$13,B$19,$A24) | C24: =INDEX($B$6:$E$13,C$19,$A24) | D24: =INDEX($B$6:$E$13,D$19,$A24) | E24: =INDEX($B$15:$E$15,A24)
A25: 2 | B25: =INDEX($B$6:$E$13,B$19,$A25) | C25: =INDEX($B$6:$E$13,C$19,$A25) | D25: =INDEX($B$6:$E$13,D$19,$A25) | E25: =INDEX($B$15:$E$15,A25)
A26: 3 | B26: =INDEX($B$6:$E$13,B$19,$A26) | C26: =INDEX($B$6:$E$13,C$19,$A26) | D26: =INDEX($B$6:$E$13,D$19,$A26) | E26: =INDEX($B$15:$E$15,A26)
A27: 4 | B27: =INDEX($B$6:$E$13,B$19,$A27) | C27: =INDEX($B$6:$E$13,C$19,$A27) | D27: =INDEX($B$6:$E$13,D$19,$A27) | E27: =INDEX($B$15:$E$15,A27)
A29: Y'Y (N x N) | F29: Y'y (N x 1)
B30: {=MMULT(TRANSPOSE(B24:D27),B24:D27)} | F30: {=MMULT(TRANSPOSE(B24:D27),E24:E27)}
A34: Ridge: G = Y'Y + lambda I (lambda from Data)
A35: lambda | B35: =Data!B42 | F35: G inverse
B36: =B30+$B$35 | C36: =C30 | D36: =D30 | F36: {=MINVERSE(B36:D38)}
B37: =B31 | C37: =C31+$B$35 | D37: =D31
B38: =B32 | C38: =C32 | D38: =D32+$B$35
A40: Step 4. Weights
A41: k | B41: plain LS (LINEST) | C41: plain LS (normal equations) | D41: ridge (MMULT, MINVERSE)
A42: 1 | B42: =INDEX(LINEST($E$24:$E$27,$B$24:$D$27,FALSE,FALSE),1,COLUMNS($B$24:$D$24)+1-A42) | C42: {=MMULT(MINVERSE(B30:D32),F30:F32)} | D42: {=MMULT(F36:H38,F30:F32)}
A43: 2 | B43: =INDEX(LINEST($E$24:$E$27,$B$24:$D$27,FALSE,FALSE),1,COLUMNS($B$24:$D$24)+1-A43)
A44: 3 | B44: =INDEX(LINEST($E$24:$E$27,$B$24:$D$27,FALSE,FALSE),1,COLUMNS($B$24:$D$24)+1-A44)
A45: sum of weights | B45: =SUM(B42:B44) | C45: =SUM(C42:C44) | D45: =SUM(D42:D44)
A47: Step 5. Same weights on the FINE fields of the chosen days
A48: fine cell | B48: row | C48: col | D48: fine, day k=1 | E48: fine, day k=2 | F48: fine, day k=3 | G48: plain LS | H48: ridge | I48: truth | J48: error ridge | K48: error plain
A49: 1 | B49: =INT((A49-1)/4) | C49: =MOD(A49-1,4) | D49: =INDEX(Data!$B$30:$Q$37,B$19,$A49) | E49: =INDEX(Data!$B$30:$Q$37,C$19,$A49) | F49: =INDEX(Data!$B$30:$Q$37,D$19,$A49) | G49: =D49*$B$42+E49*$B$43+F49*$B$44 | H49: =D49*$D$42+E49*$D$43+F49*$D$44 | I49: =INDEX(Data!$B$40:$Q$40,A49) | J49: =H49-I49 | K49: =G49-I49
A50: 2 | B50: =INT((A50-1)/4) | C50: =MOD(A50-1,4) | D50: =INDEX(Data!$B$30:$Q$37,B$19,$A50) | E50: =INDEX(Data!$B$30:$Q$37,C$19,$A50) | F50: =INDEX(Data!$B$30:$Q$37,D$19,$A50) | G50: =D50*$B$42+E50*$B$43+F50*$B$44 | H50: =D50*$D$42+E50*$D$43+F50*$D$44 | I50: =INDEX(Data!$B$40:$Q$40,A50) | J50: =H50-I50 | K50: =G50-I50
...
