Workbook

Sheet README
A1: Lecture 19: regression downscaling, worked examples (CE524 Applied Hydroclimatology, IIT Mandi)
A3: Purpose
A4: Companion to the notebook lecture-19-regression-downscaling.ipynb. Every number is a live formula, so you can see each step of simple and multiple regression, validation, collinearity and variance inflation.
A6: Colour code
A7: Blue font = input (data or a choice you may change). Black font = formula. Yellow fill = key result.
A9: All data are SYNTHETIC
A10: The numbers were generated by a small random-number program (see the notebook) to mimic monsoon-season (June-September) monthly values at a station: a large-scale 'reanalysis' predictor set (sea-level pressure, specific humidity, 850 hPa temperature, 2 m temperature) and a local predictand (Tmax anomaly, monthly rainfall). They are not observations. To use real data replace the blue columns, for example station or IMD gridded rainfall and temperature for the predictand and ERA5 or NCEP/NCAR for the predictors; keep the same layout and row counts, or edit the ranges.
A12: Sheets
A13: Data: the monthly synthetic series (70 years x 4 months = 280 rows). Rows 2-161 (1951-1990) are the calibration period, rows 162-281 (1991-2020) the validation period. The ranges in the other sheets are fixed to these rows; the 'cal'/'val' label in column J only follows cell M1.
A14: SimpleReg: simple regression by hand (n = 15): slope = Sxy/Sxx, intercept, R2, standard errors, t-test, F-test, confidence and prediction intervals, with SLOPE, INTERCEPT, RSQ as checks.
A15: MultiReg: multiple regression on the calibration months. beta = (X'X)^-1 X'y with MMULT and MINVERSE, compared with LINEST; R2, adjusted R2, F, t-tests.
A16: Collinearity: variance inflation factors from the inverse correlation matrix, and coefficient instability when two predictors are almost the same variable.
... A24: Only widely supported functions are used (AVERAGE, STDEV.S, SLOPE, INTERCEPT, RSQ, CORREL, LINEST, MMULT, MINVERSE, TRANSPOSE, SUMPRODUCT, T.INV.2T, T.DIST.2T, F.DIST.RT, PERCENTILE.INC, PERCENTRANK.INC, AVERAGEIFS, COUNTIF, LN, EXP). Matrix blocks are legacy array formulas (shown in braces in Excel) and work in Excel and Google Sheets. Values appear once the file is opened and calculated in Excel or Sheets.

Sheet Data
A1: year | B1: month (JJAS) | C1: slp_hPa | D1: q_gkg | E1: t850_C | F1: t2m_C | G1: tmax_C | H1: rain_mm | I1: z_noise | J1: period | L1: Calibration ends (year) | M1: 1990
A2: 1951 | B2: 6 | C2: 0.416 | D2: -0.445 | E2: -0.559 | F2: -0.342 | G2: -1.22 | H2: 74.4 | I2: -0.803 | J2: =IF(A2<=$M$1,"cal","val") | L2: n calibration rows | M2: =COUNTIF(J2:J281,"cal")
A3: 1951 | B3: 7 | C3: -0.752 | D3: 0.805 | E3: -0.131 | F3: -0.486 | G3: 0.89 | H3: 46.7 | I3: 0.243 | J3: =IF(A3<=$M$1,"cal","val") | L3: n validation rows | M3: =COUNTIF(J2:J281,"val")
A4: 1951 | B4: 8 | C4: 1.047 | D4: -0.84 | E4: -1.851 | F4: -2.031 | G4: -2.953 | H4: 70.5 | I4: -1.656 | J4: =IF(A4<=$M$1,"cal","val") | L4: Other sheets use rows 2-161 (cal) and 162-281 (val); M2 should read 160.
A5: 1951 | B5: 9 | C5: -0.815 | D5: -0.404 | E5: -0.707 | F5: -0.954 | G5: 0.517 | H5: 39 | I5: 0.656 | J5: =IF(A5<=$M$1,"cal","val")
A6: 1952 | B6: 6 | C6: 2.222 | D6: 0.496 | E6: 0.272 | F6: 0.623 | G6: -0.376 | H6: 45.6 | I6: 1.143 | J6: =IF(A6<=$M$1,"cal","val")
A7: 1952 | B7: 7 | C7: 1.671 | D7: 0.404 | E7: 2.493 | F7: 2.123 | G7: 1.677 | H7: 25.6 | I7: -0.453 | J7: =IF(A7<=$M$1,"cal","val")
A8: 1952 | B8: 8 | C8: 0.409 | D8: 0.642 | E8: 1.022 | F8: 0.976 | G8: 0.769 | H8: 55.3 | I8: 0.43 | J8: =IF(A8<=$M$1,"cal","val")
A9: 1952 | B9: 9 | C9: 0.061 | D9: 0.687 | E9: -0.328 | F9: -0.332 | G9: -0.179 | H9: 50 | I9: 0.251 | J9: =IF(A9<=$M$1,"cal","val")
A10: 1953 | B10: 6 | C10: -0.89 | D10: 0.539 | E10: 0.812 | F10: 0.787 | G10: -0.573 | H10: 103.5 | I10: -0.394 | J10: =IF(A10<=$M$1,"cal","val")
A11: 1953 | B11: 7 | C11: 0.139 | D11: 0.719 | E11: 0.454 | F11: 0.291 | G11: 0.791 | H11: 43.5 | I11: -0.862 | J11: =IF(A11<=$M$1,"cal","val")
A12: 1953 | B12: 8 | C12: 2.294 | D12: -0.544 | E12: -0.569 | F12: -0.472 | G12: -0.117 | H12: 22.2 | I12: -2.033 | J12: =IF(A12<=$M$1,"cal","val")
A13: 1953 | B13: 9 | C13: 0.449 | D13: 0.043 | E13: -0.331 | F13: -0.399 | G13: -0.049 | H13: 51.1 | I13: 1.41 | J13: =IF(A13<=$M$1,"cal","val")
A14: 1954 | B14: 6 | C14: 0.354 | D14: 0.019 | E14: -0.87 | F14: -0.884 | G14: 0.075 | H14: 63.6 | I14: -0.048 | J14: =IF(A14<=$M$1,"cal","val")
A15: 1954 | B15: 7 | C15: 0.69 | D15: 0.166 | E15: 2.313 | F15: 2.152 | G15: 1.284 | H15: 49.7 | I15: 2.522 | J15: =IF(A15<=$M$1,"cal","val")
A16: 1954 | B16: 8 | C16: -0.415 | D16: -0.228 | E16: -0.705 | F16: -0.352 | G16: -1.988 | H16: 175.3 | I16: 0.826 | J16: =IF(A16<=$M$1,"cal","val")
... A281: 2020 | B281: 9 | C281: -0.191 | D281: -0.455 | E281: 1.232 | F281: 1.267 | G281: -1.611 | H281: 31.2 | I281: -0.332 | J281: =IF(A281<=$M$1,"cal","val")

Sheet SimpleReg
A1: Simple linear regression by hand: Tmax anomaly (y) on humidity anomaly (x), n = 15 annual values (synthetic)
L2: Step-by-step results (labels in L, values in M, notes in N)
A3: year | B3: x: q [g/kg] | C3: y: Tmax [C] | D3: x - xbar | E3: y - ybar | F3: (x-xbar)(y-ybar) | G3: (x-xbar)^2 | H3: fitted y | I3: residual e = y - fitted | J3: e^2 | L3: alpha (two-sided) | M3: 0.05 | N3: Significance level; blue = you may change
A4: 2006 | B4: 0 | C4: 0.52 | D4: =B4-$M$6 | E4: =C4-$M$7 | F4: =D4*E4 | G4: =D4^2 | H4: =$M$11+$M$10*B4 | I4: =C4-H4 | J4: =I4^2 | L4: x0: new predictor value | M4: 0.5 | N4: A GCM humidity anomaly to downscale [g/kg]
A5: 2007 | B5: 0.18 | C5: -0.44 | D5: =B5-$M$6 | E5: =C5-$M$7 | F5: =D5*E5 | G5: =D5^2 | H5: =$M$11+$M$10*B5 | I5: =C5-H5 | J5: =I5^2 | L5: n | M5: =COUNT($B$4:$B$18)
A6: 2008 | B6: -0.16 | C6: -0.41 | D6: =B6-$M$6 | E6: =C6-$M$7 | F6: =D6*E6 | G6: =D6^2 | H6: =$M$11+$M$10*B6 | I6: =C6-H6 | J6: =I6^2 | L6: mean of x | M6: =AVERAGE($B$4:$B$18)
A7: 2009 | B7: -0.53 | C7: -1.84 | D7: =B7-$M$6 | E7: =C7-$M$7 | F7: =D7*E7 | G7: =D7^2 | H7: =$M$11+$M$10*B7 | I7: =C7-H7 | J7: =I7^2 | L7: mean of y | M7: =AVERAGE($C$4:$C$18)
A8: 2010 | B8: -0.27 | C8: -1.08 | D8: =B8-$M$6 | E8: =C8-$M$7 | F8: =D8*E8 | G8: =D8^2 | H8: =$M$11+$M$10*B8 | I8: =C8-H8 | J8: =I8^2 | L8: Sxy = sum (x-xbar)(y-ybar) | M8: =SUM(F4:F18) | N8: numerator of the slope
A9: 2011 | B9: -0.59 | C9: -1.89 | D9: =B9-$M$6 | E9: =C9-$M$7 | F9: =D9*E9 | G9: =D9^2 | H9: =$M$11+$M$10*B9 | I9: =C9-H9 | J9: =I9^2 | L9: Sxx = sum (x-xbar)^2 | M9: =SUM(G4:G18) | N9: denominator of the slope
A10: 2012 | B10: 0.04 | C10: 0.02 | D10: =B10-$M$6 | E10: =C10-$M$7 | F10: =D10*E10 | G10: =D10^2 | H10: =$M$11+$M$10*B10 | I10: =C10-H10 | J10: =I10^2 | L10: slope b1 = Sxy/Sxx | M10: =$M$8/$M$9 | N10: normal equation 2 solved: cov(x,y)/var(x)
A11: 2013 | B11: 0.8 | C11: 0.54 | D11: =B11-$M$6 | E11: =C11-$M$7 | F11: =D11*E11 | G11: =D11^2 | H11: =$M$11+$M$10*B11 | I11: =C11-H11 | J11: =I11^2 | L11: intercept b0 = ybar - b1 xbar | M11: =$M$7-$M$10*$M$6 | N11: normal equation 1: the line passes through (xbar, ybar)
A12: 2014 | B12: -0.3 | C12: -0.19 | D12: =B12-$M$6 | E12: =C12-$M$7 | F12: =D12*E12 | G12: =D12^2 | H12: =$M$11+$M$10*B12 | I12: =C12-H12 | J12: =I12^2 | L12: check: SLOPE() | M12: =SLOPE($C$4:$C$18,$B$4:$B$18) | N12: built-in function, must equal b1
A13: 2015 | B13: -0.37 | C13: -0.36 | D13: =B13-$M$6 | E13: =C13-$M$7 | F13: =D13*E13 | G13: =D13^2 | H13: =$M$11+$M$10*B13 | I13: =C13-H13 | J13: =I13^2 | L13: check: INTERCEPT() | M13: =INTERCEPT($C$4:$C$18,$B$4:$B$18) | N13: must equal b0
A14: 2016 | B14: 0.29 | C14: 0.42 | D14: =B14-$M$6 | E14: =C14-$M$7 | F14: =D14*E14 | G14: =D14^2 | H14: =$M$11+$M$10*B14 | I14: =C14-H14 | J14: =I14^2 | L14: SSE = sum e^2 | M14: =SUM(J4:J18) | N14: unexplained sum of squares
A15: 2017 | B15: 0.21 | C15: -1.1 | D15: =B15-$M$6 | E15: =C15-$M$7 | F15: =D15*E15 | G15: =D15^2 | H15: =$M$11+$M$10*B15 | I15: =C15-H15 | J15: =I15^2 | L15: SST = sum (y-ybar)^2 | M15: =SUMPRODUCT(E4:E18,E4:E18) | N15: total sum of squares
A16: 2018 | B16: 0.06 | C16: -0.13 | D16: =B16-$M$6 | E16: =C16-$M$7 | F16: =D16*E16 | G16: =D16^2 | H16: =$M$11+$M$10*B16 | I16: =C16-H16 | J16: =I16^2 | L16: SSR = SST - SSE | M16: =$M$15-$M$14 | N16: explained sum of squares
A17: 2019 | B17: -0.56 | C17: -0.77 | D17: =B17-$M$6 | E17: =C17-$M$7 | F17: =D17*E17 | G17: =D17^2 | H17: =$M$11+$M$10*B17 | I17: =C17-H17 | J17: =I17^2 | L17: R2 = SSR/SST | M17: =$M$16/$M$15 | N17: fraction of the variance of y explained by x
A18: 2020 | B18: -0.02 | C18: 0.14 | D18: =B18-$M$6 | E18: =C18-$M$7 | F18: =D18*E18 | G18: =D18^2 | H18: =$M$11+$M$10*B18 | I18: =C18-H18 | J18: =I18^2 | L18: check: RSQ() | M18: =RSQ($C$4:$C$18,$B$4:$B$18) | N18: must equal R2
A19: sum | D19: =SUM(D4:D18) | E19: =SUM(E4:E18) | F19: =SUM(F4:F18) | G19: =SUM(G4:G18) | I19: =SUM(I4:I18) | J19: =SUM(J4:J18) | L19: correlation r = CORREL | M19: =CORREL($B$4:$B$18,$C$4:$C$18) | N19: r^2 = R2 for one predictor
A20: The residuals sum to 0 and are orthogonal to x: these are the two normal equations. | L20: degrees of freedom n-2 | M20: =$M$5-2 | N20: two parameters were estimated
L21: s_e^2 = SSE/(n-2) | M21: =$M$14/$M$20 | N21: residual variance estimate [C^2]
L22: s_e = sqrt(s_e^2) | M22: =SQRT($M$21) | N22: residual standard error [C]
L23: SE(b1) = s_e/sqrt(Sxx) | M23: =SQRT($M$21/$M$9) | N23: standard error of the slope
L24: SE(b0) | M24: =SQRT($M$21*(1/$M$5+$M$6^2/$M$9)) | N24: standard error of the intercept
L25: t = b1/SE(b1) | M25: =$M$10/$M$23 | N25: test of H0: slope = 0
L26: t critical, T.INV.2T(alpha, n-2) | M26: =T.INV.2T($M$3,$M$20) | N26: small sample: a t quantile, not 1.96
L27: p-value, T.DIST.2T(|t|, n-2) | M27: =T.DIST.2T(ABS($M$25),$M$20) | N27: reject H0 if p < alpha, i.e. |t| > t critical
L28: F = SSR / (SSE/(n-2)) | M28: =$M$16/($M$14/$M$20) | N28: ANOVA F-test with 1 and n-2 degrees of freedom
L29: p-value of F, F.DIST.RT(F,1,n-2) | M29: =F.DIST.RT($M$28,1,$M$20) | N29: equals the t-test p-value
L30: check: t^2 | M30: =$M$25^2 | N30: for one predictor F = t^2
L31: CI of slope: lower | M31: =$M$10-$M$26*$M$23 | N31: b1 -/+ t_crit SE(b1)
L32: CI of slope: upper | M32: =$M$10+$M$26*$M$23
L33: predicted y at x0 | M33: =$M$11+$M$10*$M$4 | N33: the downscaled value
L34: SE of the mean response at x0 | M34: =SQRT($M$21*(1/$M$5+($M$4-$M$6)^2/$M$9)) | N34: uncertainty of the line
L35: SE of a new observation at x0 | M35: =SQRT($M$21*(1+1/$M$5+($M$4-$M$6)^2/$M$9)) | N35: adds the residual noise (the '1')
L36: confidence interval at x0: lower | M36: =$M$33-$M$26*$M$34 | N36: where the true mean Tmax lies
L37: confidence interval at x0: upper | M37: =$M$33+$M$26*$M$34
L38: prediction interval at x0: lower | M38: =$M$33-$M$26*$M$35 | N38: where an individual year will fall
L39: prediction interval at x0: upper | M39: =$M$33+$M$26*$M$35

Sheet MultiReg
A1: Multiple regression on the calibration months (1951-1990, 160 rows): Tmax ~ slp + q + t850
A2: Left: design matrix X (first column = 1 for the intercept) and the fit. Right: matrix algebra step by step, then LINEST as a check.
K4: Normal equations in matrix form
A5: 1 (intercept) | B5: slp [hPa] | C5: q [g/kg] | D5: t850 [C] | E5: y: Tmax [C] | F5: fitted y | G5: e = y - fitted | H5: e^2 | K5: X'X (4 x 4)
A6: 1 | B6: =Data!C2 | C6: =Data!D2 | D6: =Data!E2 | E6: =Data!G2 | F6: =SUMPRODUCT(A6:D6,$K$29:$N$29) | G6: =E6-F6 | H6: =G6^2 | K6: {=MMULT(TRANSPOSE($A$6:$D$165),$A$6:$D$165)}
A7: 1 | B7: =Data!C3 | C7: =Data!D3 | D7: =Data!E3 | E7: =Data!G3 | F7: =SUMPRODUCT(A7:D7,$K$29:$N$29) | G7: =E7-F7 | H7: =G7^2
A8: 1 | B8: =Data!C4 | C8: =Data!D4 | D8: =Data!E4 | E8: =Data!G4 | F8: =SUMPRODUCT(A8:D8,$K$29:$N$29) | G8: =E8-F8 | H8: =G8^2
A9: 1 | B9: =Data!C5 | C9: =Data!D5 | D9: =Data!E5 | E9: =Data!G5 | F9: =SUMPRODUCT(A9:D9,$K$29:$N$29) | G9: =E9-F9 | H9: =G9^2
A10: 1 | B10: =Data!C6 | C10: =Data!D6 | D10: =Data!E6 | E10: =Data!G6 | F10: =SUMPRODUCT(A10:D10,$K$29:$N$29) | G10: =E10-F10 | H10: =G10^2
A11: 1 | B11: =Data!C7 | C11: =Data!D7 | D11: =Data!E7 | E11: =Data!G7 | F11: =SUMPRODUCT(A11:D11,$K$29:$N$29) | G11: =E11-F11 | H11: =G11^2 | K11: X'y (4 x 1)
A12: 1 | B12: =Data!C8 | C12: =Data!D8 | D12: =Data!E8 | E12: =Data!G8 | F12: =SUMPRODUCT(A12:D12,$K$29:$N$29) | G12: =E12-F12 | H12: =G12^2 | K12: {=MMULT(TRANSPOSE($A$6:$D$165),$E$6:$E$165)}
A13: 1 | B13: =Data!C9 | C13: =Data!D9 | D13: =Data!E9 | E13: =Data!G9 | F13: =SUMPRODUCT(A13:D13,$K$29:$N$29) | G13: =E13-F13 | H13: =G13^2
A14: 1 | B14: =Data!C10 | C14: =Data!D10 | D14: =Data!E10 | E14: =Data!G10 | F14: =SUMPRODUCT(A14:D14,$K$29:$N$29) | G14: =E14-F14 | H14: =G14^2
A15: 1 | B15: =Data!C11 | C15: =Data!D11 | D15: =Data!E11 | E15: =Data!G11 | F15: =SUMPRODUCT(A15:D15,$K$29:$N$29) | G15: =E15-F15 | H15: =G15^2
A16: 1 | B16: =Data!C12 | C16: =Data!D12 | D16: =Data!E12 | E16: =Data!G12 | F16: =SUMPRODUCT(A16:D16,$K$29:$N$29) | G16: =E16-F16 | H16: =G16^2
A17: 1 | B17: =Data!C13 | C17: =Data!D13 | D17: =Data!E13 | E17: =Data!G13 | F17: =SUMPRODUCT(A17:D17,$K$29:$N$29) | G17: =E17-F17 | H17: =G17^2 | K17: (X'X)^-1 via MINVERSE
A18: 1 | B18: =Data!C14 | C18: =Data!D14 | D18: =Data!E14 | E18: =Data!G14 | F18: =SUMPRODUCT(A18:D18,$K$29:$N$29) | G18: =E18-F18 | H18: =G18^2 | K18: {=MINVERSE(K6:N9)}
A19: 1 | B19: =Data!C15 | C19: =Data!D15 | D19: =Data!E15 | E19: =Data!G15 | F19: =SUMPRODUCT(A19:D19,$K$29:$N$29) | G19: =E19-F19 | H19: =G19^2
A20: 1 | B20: =Data!C16 | C20: =Data!D16 | D20: =Data!E16 | E20: =Data!G16 | F20: =SUMPRODUCT(A20:D20,$K$29:$N$29) | G20: =E20-F20 | H20: =G20^2
A21: 1 | B21: =Data!C17 | C21: =Data!D17 | D21: =Data!E17 | E21: =Data!G17 | F21: =SUMPRODUCT(A21:D21,$K$29:$N$29) | G21: =E21-F21 | H21: =G21^2
A22: 1 | B22: =Data!C18 | C22: =Data!D18 | D22: =Data!E18 | E22: =Data!G18 | F22: =SUMPRODUCT(A22:D22,$K$29:$N$29) | G22: =E22-F22 | H22: =G22^2
A23: 1 | B23: =Data!C19 | C23: =Data!D19 | D23: =Data!E19 | E23: =Data!G19 | F23: =SUMPRODUCT(A23:D23,$K$29:$N$29) | G23: =E23-F23 | H23: =G23^2 | K23: beta = (X'X)^-1 X'y | L23: LINEST beta | M23: difference | N23: SE (matrix) | O23: SE (LINEST) | P23: t | Q23: p-value
A24: 1 | B24: =Data!C20 | C24: =Data!D20 | D24: =Data!E20 | E24: =Data!G20 | F24: =SUMPRODUCT(A24:D24,$K$29:$N$29) | G24: =E24-F24 | H24: =G24^2 | J24: intercept | K24: {=MMULT(K18:N21,K12:K15)} | L24: =INDEX(LINEST($E$6:$E$165,$B$6:$D$165,TRUE,TRUE),1,4) | M24: =K24-L24 | N24: =SQRT($N$40*INDEX($K$18:$N$21,1,1)) | O24: =INDEX(LINEST($E$6:$E$165,$B$6:$D$165,TRUE,TRUE),2,4) | P24: =K24/N24 | Q24: =T.DIST.2T(ABS(P24),$N$34)
A25: 1 | B25: =Data!C21 | C25: =Data!D21 | D25: =Data!E21 | E25: =Data!G21 | F25: =SUMPRODUCT(A25:D25,$K$29:$N$29) | G25: =E25-F25 | H25: =G25^2 | J25: slp | L25: =INDEX(LINEST($E$6:$E$165,$B$6:$D$165,TRUE,TRUE),1,3) | M25: =K25-L25 | N25: =SQRT($N$40*INDEX($K$18:$N$21,2,2)) | O25: =INDEX(LINEST($E$6:$E$165,$B$6:$D$165,TRUE,TRUE),2,3) | P25: =K25/N25 | Q25: =T.DIST.2T(ABS(P25),$N$34)
A26: 1 | B26: =Data!C22 | C26: =Data!D22 | D26: =Data!E22 | E26: =Data!G22 | F26: =SUMPRODUCT(A26:D26,$K$29:$N$29) | G26: =E26-F26 | H26: =G26^2 | J26: q | L26: =INDEX(LINEST($E$6:$E$165,$B$6:$D$165,TRUE,TRUE),1,2) | M26: =K26-L26 | N26: =SQRT($N$40*INDEX($K$18:$N$21,3,3)) | O26: =INDEX(LINEST($E$6:$E$165,$B$6:$D$165,TRUE,TRUE),2,2) | P26: =K26/N26 | Q26: =T.DIST.2T(ABS(P26),$N$34)
A27: 1 | B27: =Data!C23 | C27: =Data!D23 | D27: =Data!E23 | E27: =Data!G23 | F27: =SUMPRODUCT(A27:D27,$K$29:$N$29) | G27: =E27-F27 | H27: =G27^2 | J27: t850 | L27: =INDEX(LINEST($E$6:$E$165,$B$6:$D$165,TRUE,TRUE),1,1) | M27: =K27-L27 | N27: =SQRT($N$40*INDEX($K$18:$N$21,4,4)) | O27: =INDEX(LINEST($E$6:$E$165,$B$6:$D$165,TRUE,TRUE),2,1) | P27: =K27/N27 | Q27: =T.DIST.2T(ABS(P27),$N$34)
A28: 1 | B28: =Data!C24 | C28: =Data!D24 | D28: =Data!E24 | E28: =Data!G24 | F28: =SUMPRODUCT(A28:D28,$K$29:$N$29) | G28: =E28-F28 | H28: =G28^2 | K28: beta as a row (used by column F)
A29: 1 | B29: =Data!C25 | C29: =Data!D25 | D29: =Data!E25 | E29: =Data!G25 | F29: =SUMPRODUCT(A29:D29,$K$29:$N$29) | G29: =E29-F29 | H29: =G29^2 | K29: {=TRANSPOSE(K24:K27)}
A30: 1 | B30: =Data!C26 | C30: =Data!D26 | D30: =Data!E26 | E30: =Data!G26 | F30: =SUMPRODUCT(A30:D30,$K$29:$N$29) | G30: =E30-F30 | H30: =G30^2
A31: 1 | B31: =Data!C27 | C31: =Data!D27 | D31: =Data!E27 | E31: =Data!G27 | F31: =SUMPRODUCT(A31:D31,$K$29:$N$29) | G31: =E31-F31 | H31: =G31^2 | K31: Fit statistics
A32: 1 | B32: =Data!C28 | C32: =Data!D28 | D32: =Data!E28 | E32: =Data!G28 | F32: =SUMPRODUCT(A32:D32,$K$29:$N$29) | G32: =E32-F32 | H32: =G32^2 | K32: n | N32: =COUNT($E$6:$E$165)
A33: 1 | B33: =Data!C29 | C33: =Data!D29 | D33: =Data!E29 | E33: =Data!G29 | F33: =SUMPRODUCT(A33:D33,$K$29:$N$29) | G33: =E33-F33 | H33: =G33^2 | K33: predictors p | N33: =COLUMNS($B$6:$D$165) | O33: columns of X without the intercept
A34: 1 | B34: =Data!C30 | C34: =Data!D30 | D34: =Data!E30 | E34: =Data!G30 | F34: =SUMPRODUCT(A34:D34,$K$29:$N$29) | G34: =E34-F34 | H34: =G34^2 | K34: degrees of freedom n-p-1 | N34: =$N$32-$N$33-1
A35: 1 | B35: =Data!C31 | C35: =Data!D31 | D35: =Data!E31 | E35: =Data!G31 | F35: =SUMPRODUCT(A35:D35,$K$29:$N$29) | G35: =E35-F35 | H35: =G35^2 | K35: SSE | N35: =SUM(H6:H165) | O35: sum of e^2
A36: 1 | B36: =Data!C32 | C36: =Data!D32 | D36: =Data!E32 | E36: =Data!G32 | F36: =SUMPRODUCT(A36:D36,$K$29:$N$29) | G36: =E36-F36 | H36: =G36^2 | K36: SST | N36: =SUMPRODUCT(($E$6:$E$165-AVERAGE($E$6:$E$165))^2)
A37: 1 | B37: =Data!C33 | C37: =Data!D33 | D37: =Data!E33 | E37: =Data!G33 | F37: =SUMPRODUCT(A37:D37,$K$29:$N$29) | G37: =E37-F37 | H37: =G37^2 | K37: R2 = 1 - SSE/SST | N37: =1-$N$35/$N$36
A38: 1 | B38: =Data!C34 | C38: =Data!D34 | D38: =Data!E34 | E38: =Data!G34 | F38: =SUMPRODUCT(A38:D38,$K$29:$N$29) | G38: =E38-F38 | H38: =G38^2 | K38: adjusted R2 = 1-(1-R2)(n-1)/(n-p-1) | N38: =1-(1-$N$37)*($N$32-1)/$N$34 | O38: penalises useless predictors
A39: 1 | B39: =Data!C35 | C39: =Data!D35 | D39: =Data!E35 | E39: =Data!G35 | F39: =SUMPRODUCT(A39:D39,$K$29:$N$29) | G39: =E39-F39 | H39: =G39^2 | K39: check: LINEST R2 | N39: =INDEX(LINEST($E$6:$E$165,$B$6:$D$165,TRUE,TRUE),3,1)
A40: 1 | B40: =Data!C36 | C40: =Data!D36 | D40: =Data!E36 | E40: =Data!G36 | F40: =SUMPRODUCT(A40:D40,$K$29:$N$29) | G40: =E40-F40 | H40: =G40^2 | K40: s_e^2 = SSE/(n-p-1) | N40: =$N$35/$N$34 | O40: residual variance [C^2]
A41: 1 | B41: =Data!C37 | C41: =Data!D37 | D41: =Data!E37 | E41: =Data!G37 | F41: =SUMPRODUCT(A41:D41,$K$29:$N$29) | G41: =E41-F41 | H41: =G41^2 | K41: F = (SSR/p)/(SSE/(n-p-1)) | N41: =(($N$36-$N$35)/$N$33)/($N$35/$N$34) | O41: overall test: is any predictor useful?
...

Sheet Collinearity
A1: Multicollinearity: t850 and t2m are almost the same variable (calibration months 1951-1990)
A3: Correlation matrix R of (q, t850, t2m)
B4: q | C4: t850 | D4: t2m
A5: q | B5: =CORREL(Data!$D$2:$D$161,Data!$D$2:$D$161) | C5: =CORREL(Data!$D$2:$D$161,Data!$E$2:$E$161) | D5: =CORREL(Data!$D$2:$D$161,Data!$F$2:$F$161)
A6: t850 | B6: =CORREL(Data!$E$2:$E$161,Data!$D$2:$D$161) | C6: =CORREL(Data!$E$2:$E$161,Data!$E$2:$E$161) | D6: =CORREL(Data!$E$2:$E$161,Data!$F$2:$F$161)
A7: t2m | B7: =CORREL(Data!$F$2:$F$161,Data!$D$2:$D$161) | C7: =CORREL(Data!$F$2:$F$161,Data!$E$2:$E$161) | D7: =CORREL(Data!$F$2:$F$161,Data!$F$2:$F$161)
A9: Inverse of R (MINVERSE)
B10: q | C10: t850 | D10: t2m
A11: q | B11: {=MINVERSE(B5:D7)}
A12: t850
A13: t2m
A15: VIF_j = diagonal of R^-1 (equals 1/(1-R_j^2), R_j^2 = R2 of x_j on the other predictors)
A16: predictor | B16: VIF with (q, t850, t2m) | C16: R_j^2 = 1 - 1/VIF | D16: sqrt(VIF) = SE inflation
A17: q | B17: =INDEX($B$11:$D$13,1,1) | C17: =1-1/B17 | D17: =SQRT(B17)
A18: t850 | B18: =INDEX($B$11:$D$13,2,2) | C18: =1-1/B18 | D18: =SQRT(B18)
A19: t2m | B19: =INDEX($B$11:$D$13,3,3) | C19: =1-1/B19 | D19: =SQRT(B19)
A21: Rule of thumb: a VIF above about 5 to 10 signals trouble.
A23: Coefficients of Tmax on the predictors, fitted on different samples (LINEST)
A24: fit | B24: sample | C24: b_q | D24: b_t850 | E24: b_t2m | F24: b_t850 + b_t2m | G24: SE(b_t850)
A25: A: q, t850, t2m | B25: full cal | C25: =INDEX(LINEST(Data!$G$2:$G$161,Data!$D$2:$F$161,TRUE,TRUE),1,3) | D25: =INDEX(LINEST(Data!$G$2:$G$161,Data!$D$2:$F$161,TRUE,TRUE),1,2) | E25: =INDEX(LINEST(Data!$G$2:$G$161,Data!$D$2:$F$161,TRUE,TRUE),1,1) | F25: =D25+E25 | G25: =INDEX(LINEST(Data!$G$2:$G$161,Data!$D$2:$F$161,TRUE,TRUE),2,2)
A26: A: q, t850, t2m | B26: first 20 yr | C26: =INDEX(LINEST(Data!$G$2:$G$81,Data!$D$2:$F$81,TRUE,TRUE),1,3) | D26: =INDEX(LINEST(Data!$G$2:$G$81,Data!$D$2:$F$81,TRUE,TRUE),1,2) | E26: =INDEX(LINEST(Data!$G$2:$G$81,Data!$D$2:$F$81,TRUE,TRUE),1,1) | F26: =D26+E26 | G26: =INDEX(LINEST(Data!$G$2:$G$81,Data!$D$2:$F$81,TRUE,TRUE),2,2)
A27: A: q, t850, t2m | B27: last 20 yr | C27: =INDEX(LINEST(Data!$G$82:$G$161,Data!$D$82:$F$161,TRUE,TRUE),1,3) | D27: =INDEX(LINEST(Data!$G$82:$G$161,Data!$D$82:$F$161,TRUE,TRUE),1,2) | E27: =INDEX(LINEST(Data!$G$82:$G$161,Data!$D$82:$F$161,TRUE,TRUE),1,1) | F27: =D27+E27 | G27: =INDEX(LINEST(Data!$G$82:$G$161,Data!$D$82:$F$161,TRUE,TRUE),2,2)
A28: B: q, t850 | B28: full cal | C28: =INDEX(LINEST(Data!$G$2:$G$161,Data!$D$2:$E$161,TRUE,TRUE),1,2) | D28: =INDEX(LINEST(Data!$G$2:$G$161,Data!$D$2:$E$161,TRUE,TRUE),1,1) | E28: n/a | F28: =D28 | G28: =INDEX(LINEST(Data!$G$2:$G$161,Data!$D$2:$E$161,TRUE,TRUE),2,1)
A29: B: q, t850 | B29: first 20 yr | C29: =INDEX(LINEST(Data!$G$2:$G$81,Data!$D$2:$E$81,TRUE,TRUE),1,2) | D29: =INDEX(LINEST(Data!$G$2:$G$81,Data!$D$2:$E$81,TRUE,TRUE),1,1) | E29: n/a | F29: =D29 | G29: =INDEX(LINEST(Data!$G$2:$G$81,Data!$D$2:$E$81,TRUE,TRUE),2,1)
A30: B: q, t850 | B30: last 20 yr | C30: =INDEX(LINEST(Data!$G$82:$G$161,Data!$D$82:$E$161,TRUE,TRUE),1,2) | D30: =INDEX(LINEST(Data!$G$82:$G$161,Data!$D$82:$E$161,TRUE,TRUE),1,1) | E30: n/a | F30: =D30 | G30: =INDEX(LINEST(Data!$G$82:$G$161,Data!$D$82:$E$161,TRUE,TRUE),2,1)
A32: SE(b_t850), model A / model B (full calibration sample) | G32: =G25/G28
A33: sqrt(VIF of t850) from the table above; the SE ratio is roughly this: | G33: =D18
A35: Reading: with t2m included, b_t850 and b_t2m swing from sample to sample and have large standard errors, but their SUM stays stable. Prediction is fine; interpreting single coefficients is not.

Sheet CalVal
A1: Calibration (1951-1990) and validation (1991-2020) of the Tmax regression
A2: Coefficients come from MultiReg (fitted on calibration months only) and are applied unchanged to the validation months.
A4: year | B4: period | C4: observed Tmax | D4: downscaled Tmax | E4: error = pred - obs | F4: error^2 | H4: Metric | I4: calibration | J4: validation | K4: meaning
A5: =Data!A2 | B5: =Data!J2 | C5: =Data!G2 | D5: =MultiReg!$K$29+MultiReg!$L$29*Data!C2+MultiReg!$M$29*Data!D2+MultiReg!$N$29*Data!E2 | E5: =D5-C5 | F5: =E5^2 | H5: Bias (mean error) [C] | I5: =AVERAGEIFS(E5:E284,B5:B284,"cal") | J5: =AVERAGEIFS(E5:E284,B5:B284,"val") | K5: mean of (pred - obs)
A6: =Data!A3 | B6: =Data!J3 | C6: =Data!G3 | D6: =MultiReg!$K$29+MultiReg!$L$29*Data!C3+MultiReg!$M$29*Data!D3+MultiReg!$N$29*Data!E3 | E6: =D6-C6 | F6: =E6^2 | H6: RMSE [C] | I6: =SQRT(AVERAGEIFS(F5:F284,B5:B284,"cal")) | J6: =SQRT(AVERAGEIFS(F5:F284,B5:B284,"val")) | K6: root mean square error
A7: =Data!A4 | B7: =Data!J4 | C7: =Data!G4 | D7: =MultiReg!$K$29+MultiReg!$L$29*Data!C4+MultiReg!$M$29*Data!D4+MultiReg!$N$29*Data!E4 | E7: =D7-C7 | F7: =E7^2 | H7: Correlation r | I7: =CORREL(C5:C164,D5:D164) | J7: =CORREL(C165:C284,D165:D284) | K7: pred vs obs
A8: =Data!A5 | B8: =Data!J5 | C8: =Data!G5 | D8: =MultiReg!$K$29+MultiReg!$L$29*Data!C5+MultiReg!$M$29*Data!D5+MultiReg!$N$29*Data!E5 | E8: =D8-C8 | F8: =E8^2 | H8: R2 = r^2 | I8: =I7^2 | J8: =J7^2
A9: =Data!A6 | B9: =Data!J6 | C9: =Data!G6 | D9: =MultiReg!$K$29+MultiReg!$L$29*Data!C6+MultiReg!$M$29*Data!D6+MultiReg!$N$29*Data!E6 | E9: =D9-C9 | F9: =E9^2 | H9: Skill 1 - SSE/SST | I9: =1-SUM(F5:F164)/SUMPRODUCT((C5:C164-AVERAGE(C5:C164))^2) | J9: =1-SUM(F165:F284)/SUMPRODUCT((C165:C284-AVERAGE(C165:C284))^2) | K9: Nash-Sutcliffe style skill relative to the period mean
A10: =Data!A7 | B10: =Data!J7 | C10: =Data!G7 | D10: =MultiReg!$K$29+MultiReg!$L$29*Data!C7+MultiReg!$M$29*Data!D7+MultiReg!$N$29*Data!E7 | E10: =D10-C10 | F10: =E10^2 | H10: SD observed [C] | I10: =STDEV.S(C5:C164) | J10: =STDEV.S(C165:C284)
A11: =Data!A8 | B11: =Data!J8 | C11: =Data!G8 | D11: =MultiReg!$K$29+MultiReg!$L$29*Data!C8+MultiReg!$M$29*Data!D8+MultiReg!$N$29*Data!E8 | E11: =D11-C11 | F11: =E11^2 | H11: SD downscaled [C] | I11: =STDEV.S(D5:D164) | J11: =STDEV.S(D165:D284) | K11: too small: regression explains only part of the variance
A12: =Data!A9 | B12: =Data!J9 | C12: =Data!G9 | D12: =MultiReg!$K$29+MultiReg!$L$29*Data!C9+MultiReg!$M$29*Data!D9+MultiReg!$N$29*Data!E9 | E12: =D12-C12 | F12: =E12^2 | H12: SD ratio (downscaled / observed) | I12: =I11/I10 | J12: =J11/J10 | K12: calibration value is about sqrt(R2)
A13: =Data!A10 | B13: =Data!J10 | C13: =Data!G10 | D13: =MultiReg!$K$29+MultiReg!$L$29*Data!C10+MultiReg!$M$29*Data!D10+MultiReg!$N$29*Data!E10 | E13: =D13-C13 | F13: =E13^2 | H13: sqrt(R2) from MultiReg | I13: =SQRT(MultiReg!$N$37) | K13: compare with the calibration SD ratio
A14: =Data!A11 | B14: =Data!J11 | C14: =Data!G11 | D14: =MultiReg!$K$29+MultiReg!$L$29*Data!C11+MultiReg!$M$29*Data!D11+MultiReg!$N$29*Data!E11 | E14: =D14-C14 | F14: =E14^2
A15: =Data!A12 | B15: =Data!J12 | C15: =Data!G12 | D15: =MultiReg!$K$29+MultiReg!$L$29*Data!C12+MultiReg!$M$29*Data!D12+MultiReg!$N$29*Data!E12 | E15: =D15-C15 | F15: =E15^2
A16: =Data!A13 | B16: =Data!J13 | C16: =Data!G13 | D16: =MultiReg!$K$29+MultiReg!$L$29*Data!C13+MultiReg!$M$29*Data!D13+MultiReg!$N$29*Data!E13 | E16: =D16-C16 | F16: =E16^2 | H16: Standardised coefficients (importance of each predictor)
A17: =Data!A14 | B17: =Data!J14 | C17: =Data!G14 | D17: =MultiReg!$K$29+MultiReg!$L$29*Data!C14+MultiReg!$M$29*Data!D14+MultiReg!$N$29*Data!E14 | E17: =D17-C17 | F17: =E17^2 | H17: predictor | I17: beta [C per unit] | J17: SD of x (cal) | K17: beta_std = beta SD(x)/SD(y)
A18: =Data!A15 | B18: =Data!J15 | C18: =Data!G15 | D18: =MultiReg!$K$29+MultiReg!$L$29*Data!C15+MultiReg!$M$29*Data!D15+MultiReg!$N$29*Data!E15 | E18: =D18-C18 | F18: =E18^2 | H18: slp | I18: =MultiReg!L29 | J18: =STDEV.S(Data!C2:C161) | K18: =I18*J18/I10
A19: =Data!A16 | B19: =Data!J16 | C19: =Data!G16 | D19: =MultiReg!$K$29+MultiReg!$L$29*Data!C16+MultiReg!$M$29*Data!D16+MultiReg!$N$29*Data!E16 | E19: =D19-C19 | F19: =E19^2 | H19: q | I19: =MultiReg!M29 | J19: =STDEV.S(Data!D2:D161) | K19: =I19*J19/I10
A20: =Data!A17 | B20: =Data!J17 | C20: =Data!G17 | D20: =MultiReg!$K$29+MultiReg!$L$29*Data!C17+MultiReg!$M$29*Data!D17+MultiReg!$N$29*Data!E17 | E20: =D20-C20 | F20: =E20^2 | H20: t850 | I20: =MultiReg!N29 | J20: =STDEV.S(Data!E2:E161) | K20: =I20*J20/I10
A21: =Data!A18 | B21: =Data!J18 | C21: =Data!G18 | D21: =MultiReg!$K$29+MultiReg!$L$29*Data!C18+MultiReg!$M$29*Data!D18+MultiReg!$N$29*Data!E18 | E21: =D21-C21 | F21: =E21^2
A22: =Data!A19 | B22: =Data!J19 | C22: =Data!G19 | D22: =MultiReg!$K$29+MultiReg!$L$29*Data!C19+MultiReg!$M$29*Data!D19+MultiReg!$N$29*Data!E19 | E22: =D22-C22 | F22: =E22^2 | H22: beta_std = change of y in SDs of y per SD of x: it makes predictors in different units comparable.
A23: =Data!A20 | B23: =Data!J20 | C23: =Data!G20 | D23: =MultiReg!$K$29+MultiReg!$L$29*Data!C20+MultiReg!$M$29*Data!D20+MultiReg!$N$29*Data!E20 | E23: =D23-C23 | F23: =E23^2
A24: =Data!A21 | B24: =Data!J21 | C24: =Data!G21 | D24: =MultiReg!$K$29+MultiReg!$L$29*Data!C21+MultiReg!$M$29*Data!D21+MultiReg!$N$29*Data!E21 | E24: =D24-C24 | F24: =E24^2
A25: =Data!A22 | B25: =Data!J22 | C25: =Data!G22 | D25: =MultiReg!$K$29+MultiReg!$L$29*Data!C22+MultiReg!$M$29*Data!D22+MultiReg!$N$29*Data!E22 | E25: =D25-C25 | F25: =E25^2
A26: =Data!A23 | B26: =Data!J23 | C26: =Data!G23 | D26: =MultiReg!$K$29+MultiReg!$L$29*Data!C23+MultiReg!$M$29*Data!D23+MultiReg!$N$29*Data!E23 | E26: =D26-C26 | F26: =E26^2
A27: =Data!A24 | B27: =Data!J24 | C27: =Data!G24 | D27: =MultiReg!$K$29+MultiReg!$L$29*Data!C24+MultiReg!$M$29*Data!D24+MultiReg!$N$29*Data!E24 | E27: =D27-C27 | F27: =E27^2
A28: =Data!A25 | B28: =Data!J25 | C28: =Data!G25 | D28: =MultiReg!$K$29+MultiReg!$L$29*Data!C25+MultiReg!$M$29*Data!D25+MultiReg!$N$29*Data!E25 | E28: =D28-C28 | F28: =E28^2
A29: =Data!A26 | B29: =Data!J26 | C29: =Data!G26 | D29: =MultiReg!$K$29+MultiReg!$L$29*Data!C26+MultiReg!$M$29*Data!D26+MultiReg!$N$29*Data!E26 | E29: =D29-C29 | F29: =E29^2
A30: =Data!A27 | B30: =Data!J27 | C30: =Data!G27 | D30: =MultiReg!$K$29+MultiReg!$L$29*Data!C27+MultiReg!$M$29*Data!D27+MultiReg!$N$29*Data!E27 | E30: =D30-C30 | F30: =E30^2
A31: =Data!A28 | B31: =Data!J28 | C31: =Data!G28 | D31: =MultiReg!$K$29+MultiReg!$L$29*Data!C28+MultiReg!$M$29*Data!D28+MultiReg!$N$29*Data!E28 | E31: =D31-C31 | F31: =E31^2
A32: =Data!A29 | B32: =Data!J29 | C32: =Data!G29 | D32: =MultiReg!$K$29+MultiReg!$L$29*Data!C29+MultiReg!$M$29*Data!D29+MultiReg!$N$29*Data!E29 | E32: =D32-C32 | F32: =E32^2
A33: =Data!A30 | B33: =Data!J30 | C33: =Data!G30 | D33: =MultiReg!$K$29+MultiReg!$L$29*Data!C30+MultiReg!$M$29*Data!D30+MultiReg!$N$29*Data!E30 | E33: =D33-C33 | F33: =E33^2
A34: =Data!A31 | B34: =Data!J31 | C34: =Data!G31 | D34: =MultiReg!$K$29+MultiReg!$L$29*Data!C31+MultiReg!$M$29*Data!D31+MultiReg!$N$29*Data!E31 | E34: =D34-C34 | F34: =E34^2
... A284: =Data!A281 | B284: =Data!J281 | C284: =Data!G281 | D284: =MultiReg!$K$29+MultiReg!$L$29*Data!C281+MultiReg!$M$29*Data!D281+MultiReg!$N$29*Data!E281 | E284: =D284-C284 | F284: =E284^2

Sheet VarInfl
A1: Variance deflation: ln(rain) regressed on slp, q, t850 (calibration), applied to validation months
A2: Regression is done on ln(rain) so that rainfall stays positive; fitted + noise on the log scale gives lognormal rainfall.
A4: year | B4: period | C4: ln(rain) obs | D4: fitted ln rain | E4: residual | F4: rain: deterministic | G4: rain: fitted + noise | H4: rain: variance inflated | I4: rain observed | L4: intercept | M4: =INDEX(LINEST($C$5:$C$164,Data!$C$2:$E$161,TRUE,TRUE),1,4) | N4: LINEST order is reversed
A5: =Data!A2 | B5: =Data!J2 | C5: =LN(Data!H2) | D5: =$M$4+$M$5*Data!C2+$M$6*Data!D2+$M$7*Data!E2 | E5: =C5-D5 | F5: =EXP(D5) | G5: =EXP(D5+$M$9*Data!I2) | H5: =EXP($M$10+(D5-$M$10)/SQRT($M$8)) | I5: =Data!H2 | L5: b_slp | M5: =INDEX(LINEST($C$5:$C$164,Data!$C$2:$E$161,TRUE,TRUE),1,3)
A6: =Data!A3 | B6: =Data!J3 | C6: =LN(Data!H3) | D6: =$M$4+$M$5*Data!C3+$M$6*Data!D3+$M$7*Data!E3 | E6: =C6-D6 | F6: =EXP(D6) | G6: =EXP(D6+$M$9*Data!I3) | H6: =EXP($M$10+(D6-$M$10)/SQRT($M$8)) | I6: =Data!H3 | L6: b_q | M6: =INDEX(LINEST($C$5:$C$164,Data!$C$2:$E$161,TRUE,TRUE),1,2)
A7: =Data!A4 | B7: =Data!J4 | C7: =LN(Data!H4) | D7: =$M$4+$M$5*Data!C4+$M$6*Data!D4+$M$7*Data!E4 | E7: =C7-D7 | F7: =EXP(D7) | G7: =EXP(D7+$M$9*Data!I4) | H7: =EXP($M$10+(D7-$M$10)/SQRT($M$8)) | I7: =Data!H4 | L7: b_t850 | M7: =INDEX(LINEST($C$5:$C$164,Data!$C$2:$E$161,TRUE,TRUE),1,1)
A8: =Data!A5 | B8: =Data!J5 | C8: =LN(Data!H5) | D8: =$M$4+$M$5*Data!C5+$M$6*Data!D5+$M$7*Data!E5 | E8: =C8-D8 | F8: =EXP(D8) | G8: =EXP(D8+$M$9*Data!I5) | H8: =EXP($M$10+(D8-$M$10)/SQRT($M$8)) | I8: =Data!H5 | L8: R2 (calibration) | M8: =INDEX(LINEST($C$5:$C$164,Data!$C$2:$E$161,TRUE,TRUE),3,1)
A9: =Data!A6 | B9: =Data!J6 | C9: =LN(Data!H6) | D9: =$M$4+$M$5*Data!C6+$M$6*Data!D6+$M$7*Data!E6 | E9: =C9-D9 | F9: =EXP(D9) | G9: =EXP(D9+$M$9*Data!I6) | H9: =EXP($M$10+(D9-$M$10)/SQRT($M$8)) | I9: =Data!H6 | L9: residual SD s_e | M9: =INDEX(LINEST($C$5:$C$164,Data!$C$2:$E$161,TRUE,TRUE),3,2) | N9: standard error of y estimate, sqrt(SSE/(n-p-1))
A10: =Data!A7 | B10: =Data!J7 | C10: =LN(Data!H7) | D10: =$M$4+$M$5*Data!C7+$M$6*Data!D7+$M$7*Data!E7 | E10: =C10-D10 | F10: =EXP(D10) | G10: =EXP(D10+$M$9*Data!I7) | H10: =EXP($M$10+(D10-$M$10)/SQRT($M$8)) | I10: =Data!H7 | L10: mean ln rain (cal) | M10: =AVERAGE($C$5:$C$164)
A11: =Data!A8 | B11: =Data!J8 | C11: =LN(Data!H8) | D11: =$M$4+$M$5*Data!C8+$M$6*Data!D8+$M$7*Data!E8 | E11: =C11-D11 | F11: =EXP(D11) | G11: =EXP(D11+$M$9*Data!I8) | H11: =EXP($M$10+(D11-$M$10)/SQRT($M$8)) | I11: =Data!H8 | L11: Var(ln rain) (cal) | M11: =STDEV.S($C$5:$C$164)^2 | N11: total variance
A12: =Data!A9 | B12: =Data!J9 | C12: =LN(Data!H9) | D12: =$M$4+$M$5*Data!C9+$M$6*Data!D9+$M$7*Data!E9 | E12: =C12-D12 | F12: =EXP(D12) | G12: =EXP(D12+$M$9*Data!I9) | H12: =EXP($M$10+(D12-$M$10)/SQRT($M$8)) | I12: =Data!H9 | L12: Var(fitted) (cal) | M12: =STDEV.S($D$5:$D$164)^2 | N12: explained variance
A13: =Data!A10 | B13: =Data!J10 | C13: =LN(Data!H10) | D13: =$M$4+$M$5*Data!C10+$M$6*Data!D10+$M$7*Data!E10 | E13: =C13-D13 | F13: =EXP(D13) | G13: =EXP(D13+$M$9*Data!I10) | H13: =EXP($M$10+(D13-$M$10)/SQRT($M$8)) | I13: =Data!H10 | L13: Var(residual) (cal) | M13: =STDEV.S($E$5:$E$164)^2 | N13: unexplained variance
A14: =Data!A11 | B14: =Data!J11 | C14: =LN(Data!H11) | D14: =$M$4+$M$5*Data!C11+$M$6*Data!D11+$M$7*Data!E11 | E14: =C14-D14 | F14: =EXP(D14) | G14: =EXP(D14+$M$9*Data!I11) | H14: =EXP($M$10+(D14-$M$10)/SQRT($M$8)) | I14: =Data!H11 | L14: Var(fitted) + Var(residual) | M14: =$M$12+$M$13 | N14: must equal Var(ln rain)
A15: =Data!A12 | B15: =Data!J12 | C15: =LN(Data!H12) | D15: =$M$4+$M$5*Data!C12+$M$6*Data!D12+$M$7*Data!E12 | E15: =C15-D15 | F15: =EXP(D15) | G15: =EXP(D15+$M$9*Data!I12) | H15: =EXP($M$10+(D15-$M$10)/SQRT($M$8)) | I15: =Data!H12 | L15: Var(fitted)/Var(ln rain) | M15: =$M$12/$M$11 | N15: equals R2: the variance the downscaled series keeps
A16: =Data!A13 | B16: =Data!J13 | C16: =LN(Data!H13) | D16: =$M$4+$M$5*Data!C13+$M$6*Data!D13+$M$7*Data!E13 | E16: =C16-D16 | F16: =EXP(D16) | G16: =EXP(D16+$M$9*Data!I13) | H16: =EXP($M$10+(D16-$M$10)/SQRT($M$8)) | I16: =Data!H13
A17: =Data!A14 | B17: =Data!J14 | C17: =LN(Data!H14) | D17: =$M$4+$M$5*Data!C14+$M$6*Data!D14+$M$7*Data!E14 | E17: =C17-D17 | F17: =EXP(D17) | G17: =EXP(D17+$M$9*Data!I14) | H17: =EXP($M$10+(D17-$M$10)/SQRT($M$8)) | I17: =Data!H14
A18: =Data!A15 | B18: =Data!J15 | C18: =LN(Data!H15) | D18: =$M$4+$M$5*Data!C15+$M$6*Data!D15+$M$7*Data!E15 | E18: =C18-D18 | F18: =EXP(D18) | G18: =EXP(D18+$M$9*Data!I15) | H18: =EXP($M$10+(D18-$M$10)/SQRT($M$8)) | I18: =Data!H15
A19: =Data!A16 | B19: =Data!J16 | C19: =LN(Data!H16) | D19: =$M$4+$M$5*Data!C16+$M$6*Data!D16+$M$7*Data!E16 | E19: =C19-D19 | F19: =EXP(D19) | G19: =EXP(D19+$M$9*Data!I16) | H19: =EXP($M$10+(D19-$M$10)/SQRT($M$8)) | I19: =Data!H16 | L19: Validation months 1991-2020: rainfall statistics [mm]
A20: =Data!A17 | B20: =Data!J17 | C20: =LN(Data!H17) | D20: =$M$4+$M$5*Data!C17+$M$6*Data!D17+$M$7*Data!E17 | E20: =C20-D20 | F20: =EXP(D20) | G20: =EXP(D20+$M$9*Data!I17) | H20: =EXP($M$10+(D20-$M$10)/SQRT($M$8)) | I20: =Data!H17 | L20: statistic | M20: observed | N20: deterministic fit | O20: fit + noise | P20: variance inflated
A21: =Data!A18 | B21: =Data!J18 | C21: =LN(Data!H18) | D21: =$M$4+$M$5*Data!C18+$M$6*Data!D18+$M$7*Data!E18 | E21: =C21-D21 | F21: =EXP(D21) | G21: =EXP(D21+$M$9*Data!I18) | H21: =EXP($M$10+(D21-$M$10)/SQRT($M$8)) | I21: =Data!H18 | L21: mean | M21: =AVERAGE(I165:I284) | N21: =AVERAGE(F165:F284) | O21: =AVERAGE(G165:G284) | P21: =AVERAGE(H165:H284)
A22: =Data!A19 | B22: =Data!J19 | C22: =LN(Data!H19) | D22: =$M$4+$M$5*Data!C19+$M$6*Data!D19+$M$7*Data!E19 | E22: =C22-D22 | F22: =EXP(D22) | G22: =EXP(D22+$M$9*Data!I19) | H22: =EXP($M$10+(D22-$M$10)/SQRT($M$8)) | I22: =Data!H19 | L22: SD | M22: =STDEV.S(I165:I284) | N22: =STDEV.S(F165:F284) | O22: =STDEV.S(G165:G284) | P22: =STDEV.S(H165:H284)
A23: =Data!A20 | B23: =Data!J20 | C23: =LN(Data!H20) | D23: =$M$4+$M$5*Data!C20+$M$6*Data!D20+$M$7*Data!E20 | E23: =C23-D23 | F23: =EXP(D23) | G23: =EXP(D23+$M$9*Data!I20) | H23: =EXP($M$10+(D23-$M$10)/SQRT($M$8)) | I23: =Data!H20 | L23: median (P50) | M23: =PERCENTILE.INC(I165:I284,0.5) | N23: =PERCENTILE.INC(F165:F284,0.5) | O23: =PERCENTILE.INC(G165:G284,0.5) | P23: =PERCENTILE.INC(H165:H284,0.5)
A24: =Data!A21 | B24: =Data!J21 | C24: =LN(Data!H21) | D24: =$M$4+$M$5*Data!C21+$M$6*Data!D21+$M$7*Data!E21 | E24: =C24-D24 | F24: =EXP(D24) | G24: =EXP(D24+$M$9*Data!I21) | H24: =EXP($M$10+(D24-$M$10)/SQRT($M$8)) | I24: =Data!H21 | L24: P90 | M24: =PERCENTILE.INC(I165:I284,0.9) | N24: =PERCENTILE.INC(F165:F284,0.9) | O24: =PERCENTILE.INC(G165:G284,0.9) | P24: =PERCENTILE.INC(H165:H284,0.9)
A25: =Data!A22 | B25: =Data!J22 | C25: =LN(Data!H22) | D25: =$M$4+$M$5*Data!C22+$M$6*Data!D22+$M$7*Data!E22 | E25: =C25-D25 | F25: =EXP(D25) | G25: =EXP(D25+$M$9*Data!I22) | H25: =EXP($M$10+(D25-$M$10)/SQRT($M$8)) | I25: =Data!H22 | L25: P99 | M25: =PERCENTILE.INC(I165:I284,0.99) | N25: =PERCENTILE.INC(F165:F284,0.99) | O25: =PERCENTILE.INC(G165:G284,0.99) | P25: =PERCENTILE.INC(H165:H284,0.99)
A26: =Data!A23 | B26: =Data!J23 | C26: =LN(Data!H23) | D26: =$M$4+$M$5*Data!C23+$M$6*Data!D23+$M$7*Data!E23 | E26: =C26-D26 | F26: =EXP(D26) | G26: =EXP(D26+$M$9*Data!I23) | H26: =EXP($M$10+(D26-$M$10)/SQRT($M$8)) | I26: =Data!H23 | L26: maximum | M26: =MAX(I165:I284) | N26: =MAX(F165:F284) | O26: =MAX(G165:G284) | P26: =MAX(H165:H284)
A27: =Data!A24 | B27: =Data!J24 | C27: =LN(Data!H24) | D27: =$M$4+$M$5*Data!C24+$M$6*Data!D24+$M$7*Data!E24 | E27: =C27-D27 | F27: =EXP(D27) | G27: =EXP(D27+$M$9*Data!I24) | H27: =EXP($M$10+(D27-$M$10)/SQRT($M$8)) | I27: =Data!H24 | L27: Share of months above the observed P90 [%] | M27: =100*COUNTIF(I165:I284,">"&$M$24)/COUNT(I165:I284) | N27: =100*COUNTIF(F165:F284,">"&$M$24)/COUNT(F165:F284) | O27: =100*COUNTIF(G165:G284,">"&$M$24)/COUNT(G165:G284) | P27: =100*COUNTIF(H165:H284,">"&$M$24)/COUNT(H165:H284)
A28: =Data!A25 | B28: =Data!J25 | C28: =LN(Data!H25) | D28: =$M$4+$M$5*Data!C25+$M$6*Data!D25+$M$7*Data!E25 | E28: =C28-D28 | F28: =EXP(D28) | G28: =EXP(D28+$M$9*Data!I25) | H28: =EXP($M$10+(D28-$M$10)/SQRT($M$8)) | I28: =Data!H25 | L28: Share of months above the observed P99 [%] | M28: =100*COUNTIF(I165:I284,">"&$M$25)/COUNT(I165:I284) | N28: =100*COUNTIF(F165:F284,">"&$M$25)/COUNT(F165:F284) | O28: =100*COUNTIF(G165:G284,">"&$M$25)/COUNT(G165:G284) | P28: =100*COUNTIF(H165:H284,">"&$M$25)/COUNT(H165:H284)
A29: =Data!A26 | B29: =Data!J26 | C29: =LN(Data!H26) | D29: =$M$4+$M$5*Data!C26+$M$6*Data!D26+$M$7*Data!E26 | E29: =C29-D29 | F29: =EXP(D29) | G29: =EXP(D29+$M$9*Data!I26) | H29: =EXP($M$10+(D29-$M$10)/SQRT($M$8)) | I29: =Data!H26 | L29: Percentile rank of the observed P99 in each series | M29: =IF($M$25>=MAX(I165:I284),1,PERCENTRANK.INC(I165:I284,$M$25)) | N29: =IF($M$25>=MAX(F165:F284),1,PERCENTRANK.INC(F165:F284,$M$25)) | O29: =IF($M$25>=MAX(G165:G284),1,PERCENTRANK.INC(G165:G284,$M$25)) | P29: =IF($M$25>=MAX(H165:H284),1,PERCENTRANK.INC(H165:H284,$M$25))
A30: =Data!A27 | B30: =Data!J27 | C30: =LN(Data!H27) | D30: =$M$4+$M$5*Data!C27+$M$6*Data!D27+$M$7*Data!E27 | E30: =C30-D30 | F30: =EXP(D30) | G30: =EXP(D30+$M$9*Data!I27) | H30: =EXP($M$10+(D30-$M$10)/SQRT($M$8)) | I30: =Data!H27
A31: =Data!A28 | B31: =Data!J28 | C31: =LN(Data!H28) | D31: =$M$4+$M$5*Data!C28+$M$6*Data!D28+$M$7*Data!E28 | E31: =C31-D31 | F31: =EXP(D31) | G31: =EXP(D31+$M$9*Data!I28) | H31: =EXP($M$10+(D31-$M$10)/SQRT($M$8)) | I31: =Data!H28 | L31: Reading: the deterministic fit (column N) has too small a spread and almost no months above the observed P99. Adding noise or inflating the variance restores the spread.
A32: =Data!A29 | B32: =Data!J29 | C32: =LN(Data!H29) | D32: =$M$4+$M$5*Data!C29+$M$6*Data!D29+$M$7*Data!E29 | E32: =C32-D32 | F32: =EXP(D32) | G32: =EXP(D32+$M$9*Data!I29) | H32: =EXP($M$10+(D32-$M$10)/SQRT($M$8)) | I32: =Data!H29 | L32: Note: exp(fitted ln rain) estimates the median of the lognormal, so the noise version has a larger mean, by about exp(s_e^2/2).
A33: =Data!A30 | B33: =Data!J30 | C33: =LN(Data!H30) | D33: =$M$4+$M$5*Data!C30+$M$6*Data!D30+$M$7*Data!E30 | E33: =C33-D33 | F33: =EXP(D33) | G33: =EXP(D33+$M$9*Data!I30) | H33: =EXP($M$10+(D33-$M$10)/SQRT($M$8)) | I33: =Data!H30
A34: =Data!A31 | B34: =Data!J31 | C34: =LN(Data!H31) | D34: =$M$4+$M$5*Data!C31+$M$6*Data!D31+$M$7*Data!E31 | E34: =C34-D34 | F34: =EXP(D34) | G34: =EXP(D34+$M$9*Data!I31) | H34: =EXP($M$10+(D34-$M$10)/SQRT($M$8)) | I34: =Data!H31
A35: =Data!A32 | B35: =Data!J32 | C35: =LN(Data!H32) | D35: =$M$4+$M$5*Data!C32+$M$6*Data!D32+$M$7*Data!E32 | E35: =C35-D35 | F35: =EXP(D35) | G35: =EXP(D35+$M$9*Data!I32) | H35: =EXP($M$10+(D35-$M$10)/SQRT($M$8)) | I35: =Data!H32
A36: =Data!A33 | B36: =Data!J33 | C36: =LN(Data!H33) | D36: =$M$4+$M$5*Data!C33+$M$6*Data!D33+$M$7*Data!E33 | E36: =C36-D36 | F36: =EXP(D36) | G36: =EXP(D36+$M$9*Data!I33) | H36: =EXP($M$10+(D36-$M$10)/SQRT($M$8)) | I36: =Data!H33
A37: =Data!A34 | B37: =Data!J34 | C37: =LN(Data!H34) | D37: =$M$4+$M$5*Data!C34+$M$6*Data!D34+$M$7*Data!E34 | E37: =C37-D37 | F37: =EXP(D37) | G37: =EXP(D37+$M$9*Data!I34) | H37: =EXP($M$10+(D37-$M$10)/SQRT($M$8)) | I37: =Data!H34
A38: =Data!A35 | B38: =Data!J35 | C38: =LN(Data!H35) | D38: =$M$4+$M$5*Data!C35+$M$6*Data!D35+$M$7*Data!E35 | E38: =C38-D38 | F38: =EXP(D38) | G38: =EXP(D38+$M$9*Data!I35) | H38: =EXP($M$10+(D38-$M$10)/SQRT($M$8)) | I38: =Data!H35
A39: =Data!A36 | B39: =Data!J36 | C39: =LN(Data!H36) | D39: =$M$4+$M$5*Data!C36+$M$6*Data!D36+$M$7*Data!E36 | E39: =C39-D39 | F39: =EXP(D39) | G39: =EXP(D39+$M$9*Data!I36) | H39: =EXP($M$10+(D39-$M$10)/SQRT($M$8)) | I39: =Data!H36
A40: =Data!A37 | B40: =Data!J37 | C40: =LN(Data!H37) | D40: =$M$4+$M$5*Data!C37+$M$6*Data!D37+$M$7*Data!E37 | E40: =C40-D40 | F40: =EXP(D40) | G40: =EXP(D40+$M$9*Data!I37) | H40: =EXP($M$10+(D40-$M$10)/SQRT($M$8)) | I40: =Data!H37
A41: =Data!A38 | B41: =Data!J38 | C41: =LN(Data!H38) | D41: =$M$4+$M$5*Data!C38+$M$6*Data!D38+$M$7*Data!E38 | E41: =C41-D41 | F41: =EXP(D41) | G41: =EXP(D41+$M$9*Data!I38) | H41: =EXP($M$10+(D41-$M$10)/SQRT($M$8)) | I41: =Data!H38
...
