Workbook

Sheet README
A1: Lecture 18 - Bias correction: worked examples (CE524 Applied Hydroclimatology)
A3: Purpose | B3: Companion to Lecture 18. Every correction method of the lecture is computed here with live formulas on the same synthetic data that the notebook uses, so each step can be inspected cell by cell.
A4: Data are synthetic | B4: All series were generated for teaching. 'Observed' and 'model' are made-up monsoon-season (JJAS, 122 days per year) daily rainfall (mm/day) and temperature (degC). The model is given a KNOWN bias and a KNOWN climate-change signal, and a synthetic 'truth' future is available, so you can see which method recovers it. Nothing here is IMD or CMIP data. To use real data, paste an observed gridded or station series (e.g. IMD) into the 'obs' columns and a model series (e.g. NEX-GDDP-CMIP6) into the 'mod' columns of the Data sheet in place of the generated values (and delete or ignore the u columns).
A5: Colour code | B5: Blue font = input typed in (parameters, fixed uniform random numbers, tiny-example values). Black = formula. Green = link to another sheet. Yellow fill = a key result.
A6: How to use | B6: Start with Params and Data, then follow the sheets in order: Occurrence, Delta, QM_tiny (12 values you can check by hand), QM_gamma, QM_empirical, QDM, Evaluation (and Eval_calc, its support tables). Change a blue value in Params (for example the model temperature bias) and everything recalculates. Calibration = 20 seasons used to fit each correction; Validation = 20 other seasons of the same climate (held out); Future = 20 seasons of changed climate, compared with the synthetic truth.
A7: Periods | B7: cal: calibration (obs and model historical). val: held-out validation (obs and model, same climate as cal). fut: future; 'mod_fut' is the model future, 'tru_fut' is the synthetic truth that the correction should reproduce.
A8: Random numbers | B8: The Data sheet holds FIXED uniform random numbers u (columns C to N, with day-to-day persistence). The synthetic series are computed from them by inverse CDFs (GAMMA.INV, NORM.INV) with the parameters on the Params sheet, so the workbook gives the same numbers every time.
A9: Functions used | B9: AVERAGE, STDEV.S, PERCENTILE.INC, COUNTIF(S), AVERAGEIFS, SUMPRODUCT, INDEX/MATCH, SMALL, GAMMA.DIST, GAMMA.INV, NORM.DIST, NORM.INV, IF, MAX, ROUND. No LET, LAMBDA or dynamic arrays.
A10: Wet-day percentile trick | B10: To get a percentile of the WET days only, from a column that also holds zeros, the sheets use PERCENTILE.INC on the whole column at probability (zeros + p*(wet - 1)) / (N - 1). This equals the percentile of the wet-day values alone, because the zeros occupy the lowest ranks.
A11: Checks | B11: Results were checked against an independent Python implementation (see the notebook). Excel itself was not used to recalculate the file when it was built; if a cell shows an error after you change inputs, check that denominators are not zero.
A12: Sheets | B12: Params | Data | Occurrence | Delta | QM_tiny | QM_gamma | QM_empirical | QDM | Evaluation | Eval_calc
A14: Source of the methods | B14: Lee, T. and Singh, V. P. (2019) Statistical Downscaling for Hydrological and Environmental Applications, CRC Press, Chapter 4. Spreadsheets and numbers here are our own.

Sheet Params
A1: Parameters of the synthetic world (inputs, blue)
A2: Change a value and the Data sheet (and every sheet after it) recalculates.
A3: Parameter | B3: Value | C3: Unit | D3: Meaning
A4: Observed rain: wet-day fraction | B4: 0.55 | C4: - | D4: Share of days with rain >= 0.1 mm
A5: Observed rain: gamma shape k | B5: 0.55 | C5: - | D5: Wet-day intensity ~ gamma(k, theta)
A6: Observed rain: gamma scale theta | B6: 20 | C6: mm | D6: Mean wet-day rain = k*theta
A7: Model rain: wet-day fraction | B7: 0.93 | C7: - | D7: Too many wet days: the drizzle problem
A8: Model rain: gamma shape k | B8: 0.6 | C8: -
A9: Model rain: gamma scale theta | B9: 6 | C9: mm | D9: Lighter intensities than observed
A10: Climate-change factor c(tau) = a + b*tau^p: a | B10: 1.05 | C10: - | D10: Relative change of the daily-rain quantile at probability tau (tau = all-days non-exceedance probability)
A11: Climate-change factor: b | B11: 0.4 | C11: - | D11: Upper quantiles intensify more than the median
A12: Climate-change factor: p | B12: 6 | C12: -
A13: Observed temperature mean | B13: 30 | C13: degC
A14: Observed temperature standard deviation | B14: 2.2 | C14: degC
A15: Model temperature mean | B15: 27 | C15: degC | D15: Cold bias
A16: Model temperature standard deviation | B16: 3 | C16: degC | D16: Too variable
A17: Warming d(tau) = a + b*tau: a | B17: 2.4 | C17: degC | D17: Warming at probability tau
A18: Warming: b | B18: 1.6 | C18: degC | D18: Hot days warm more than cool days
A20: Derived (for reference)
A21: Observed mean wet-day rain k*theta (mm) | B21: =B5*B6
A22: Model mean wet-day rain k*theta, before threshold (mm) | B22: =B8*B9
A23: Temperature bias, model minus obs (degC) | B23: =B15-B13
A25: Series are built as quantile functions: a day with uniform number u is dry if u <= 1 - f, otherwise wet with intensity = gamma quantile at (u-(1-f))/f. The future multiplies (rain) or shifts (temperature) the quantile at probability u by c(u) or d(u): the 'known climate-change signal'.

Sheet Data
A1: day | B1: season | C1: u_rain_obs_cal | D1: u_rain_mod_cal | E1: u_rain_obs_val | F1: u_rain_mod_val | G1: u_rain_mod_fut | H1: u_rain_tru_fut | I1: u_temp_obs_cal | J1: u_temp_mod_cal | K1: u_temp_obs_val | L1: u_temp_mod_val | M1: u_temp_mod_fut | N1: u_temp_tru_fut | O1: rain_obs_cal | P1: rain_mod_cal | Q1: rain_obs_val | R1: rain_mod_val | S1: rain_mod_fut | T1: rain_tru_fut | U1: temp_obs_cal | V1: temp_mod_cal | W1: temp_obs_val | X1: temp_mod_val | Y1: temp_mod_fut | Z1: temp_tru_fut
A2: 1 | B2: =INT((A2-1)/122)+1 | C2: 0.332747 | D2: 0.806201 | E2: 0.215514 | F2: 0.370591 | G2: 0.927704 | H2: 0.647036 | I2: 0.76865 | J2: 0.544602 | K2: 0.722636 | L2: 0.017036 | M2: 0.674204 | N2: 0.519173 | O2: =IF(C2<=1-Params!$B$4,0,MAX(0.1,ROUND(_xlfn.GAMMA.INV((C2-(1-Params!$B$4))/Params!$B$4,Params!$B$5,Params!$B$6),1))) | P2: =IF(D2<=1-Params!$B$7,0,ROUND(_xlfn.GAMMA.INV((D2-(1-Params!$B$7))/Params!$B$7,Params!$B$8,Params!$B$9),3)) | Q2: =IF(E2<=1-Params!$B$4,0,MAX(0.1,ROUND(_xlfn.GAMMA.INV((E2-(1-Params!$B$4))/Params!$B$4,Params!$B$5,Params!$B$6),1))) | R2: =IF(F2<=1-Params!$B$7,0,ROUND(_xlfn.GAMMA.INV((F2-(1-Params!$B$7))/Params!$B$7,Params!$B$8,Params!$B$9),3)) | S2: =IF(G2<=1-Params!$B$7,0,ROUND((Params!$B$10+Params!$B$11*G2^Params!$B$12)*_xlfn.GAMMA.INV((G2-(1-Params!$B$7))/Params!$B$7,Params!$B$8,Params!$B$9),3)) | T2: =IF(H2<=1-Params!$B$4,0,MAX(0.1,ROUND((Params!$B$10+Params!$B$11*H2^Params!$B$12)*_xlfn.GAMMA.INV((H2-(1-Params!$B$4))/Params!$B$4,Params!$B$5,Params!$B$6),1))) | U2: =ROUND(_xlfn.NORM.INV(I2,Params!$B$13,Params!$B$14),1) | V2: =ROUND(_xlfn.NORM.INV(J2,Params!$B$15,Params!$B$16),2) | W2: =ROUND(_xlfn.NORM.INV(K2,Params!$B$13,Params!$B$14),1) | X2: =ROUND(_xlfn.NORM.INV(L2,Params!$B$15,Params!$B$16),2) | Y2: =ROUND(_xlfn.NORM.INV(M2,Params!$B$15,Params!$B$16)+Params!$B$17+Params!$B$18*M2,2) | Z2: =ROUND(_xlfn.NORM.INV(N2,Params!$B$13,Params!$B$14)+Params!$B$17+Params!$B$18*N2,1)
A3: 2 | B3: =INT((A3-1)/122)+1 | C3: 0.684352 | D3: 0.232259 | E3: 0.968326 | F3: 0.294894 | G3: 0.917329 | H3: 0.609147 | I3: 0.80972 | J3: 0.499869 | K3: 0.94903 | L3: 0.012143 | M3: 0.568948 | N3: 0.429176 | O3: =IF(C3<=1-Params!$B$4,0,MAX(0.1,ROUND(_xlfn.GAMMA.INV((C3-(1-Params!$B$4))/Params!$B$4,Params!$B$5,Params!$B$6),1))) | P3: =IF(D3<=1-Params!$B$7,0,ROUND(_xlfn.GAMMA.INV((D3-(1-Params!$B$7))/Params!$B$7,Params!$B$8,Params!$B$9),3)) | Q3: =IF(E3<=1-Params!$B$4,0,MAX(0.1,ROUND(_xlfn.GAMMA.INV((E3-(1-Params!$B$4))/Params!$B$4,Params!$B$5,Params!$B$6),1))) | R3: =IF(F3<=1-Params!$B$7,0,ROUND(_xlfn.GAMMA.INV((F3-(1-Params!$B$7))/Params!$B$7,Params!$B$8,Params!$B$9),3)) | S3: =IF(G3<=1-Params!$B$7,0,ROUND((Params!$B$10+Params!$B$11*G3^Params!$B$12)*_xlfn.GAMMA.INV((G3-(1-Params!$B$7))/Params!$B$7,Params!$B$8,Params!$B$9),3)) | T3: =IF(H3<=1-Params!$B$4,0,MAX(0.1,ROUND((Params!$B$10+Params!$B$11*H3^Params!$B$12)*_xlfn.GAMMA.INV((H3-(1-Params!$B$4))/Params!$B$4,Params!$B$5,Params!$B$6),1))) | U3: =ROUND(_xlfn.NORM.INV(I3,Params!$B$13,Params!$B$14),1) | V3: =ROUND(_xlfn.NORM.INV(J3,Params!$B$15,Params!$B$16),2) | W3: =ROUND(_xlfn.NORM.INV(K3,Params!$B$13,Params!$B$14),1) | X3: =ROUND(_xlfn.NORM.INV(L3,Params!$B$15,Params!$B$16),2) | Y3: =ROUND(_xlfn.NORM.INV(M3,Params!$B$15,Params!$B$16)+Params!$B$17+Params!$B$18*M3,2) | Z3: =ROUND(_xlfn.NORM.INV(N3,Params!$B$13,Params!$B$14)+Params!$B$17+Params!$B$18*N3,1)
A4: 3 | B4: =INT((A4-1)/122)+1 | C4: 0.192211 | D4: 0.249626 | E4: 0.747132 | F4: 0.58603 | G4: 0.974214 | H4: 0.382656 | I4: 0.474677 | J4: 0.524774 | K4: 0.446471 | L4: 0.190615 | M4: 0.740563 | N4: 0.501548 | O4: =IF(C4<=1-Params!$B$4,0,MAX(0.1,ROUND(_xlfn.GAMMA.INV((C4-(1-Params!$B$4))/Params!$B$4,Params!$B$5,Params!$B$6),1))) | P4: =IF(D4<=1-Params!$B$7,0,ROUND(_xlfn.GAMMA.INV((D4-(1-Params!$B$7))/Params!$B$7,Params!$B$8,Params!$B$9),3)) | Q4: =IF(E4<=1-Params!$B$4,0,MAX(0.1,ROUND(_xlfn.GAMMA.INV((E4-(1-Params!$B$4))/Params!$B$4,Params!$B$5,Params!$B$6),1))) | R4: =IF(F4<=1-Params!$B$7,0,ROUND(_xlfn.GAMMA.INV((F4-(1-Params!$B$7))/Params!$B$7,Params!$B$8,Params!$B$9),3)) | S4: =IF(G4<=1-Params!$B$7,0,ROUND((Params!$B$10+Params!$B$11*G4^Params!$B$12)*_xlfn.GAMMA.INV((G4-(1-Params!$B$7))/Params!$B$7,Params!$B$8,Params!$B$9),3)) | T4: =IF(H4<=1-Params!$B$4,0,MAX(0.1,ROUND((Params!$B$10+Params!$B$11*H4^Params!$B$12)*_xlfn.GAMMA.INV((H4-(1-Params!$B$4))/Params!$B$4,Params!$B$5,Params!$B$6),1))) | U4: =ROUND(_xlfn.NORM.INV(I4,Params!$B$13,Params!$B$14),1) | V4: =ROUND(_xlfn.NORM.INV(J4,Params!$B$15,Params!$B$16),2) | W4: =ROUND(_xlfn.NORM.INV(K4,Params!$B$13,Params!$B$14),1) | X4: =ROUND(_xlfn.NORM.INV(L4,Params!$B$15,Params!$B$16),2) | Y4: =ROUND(_xlfn.NORM.INV(M4,Params!$B$15,Params!$B$16)+Params!$B$17+Params!$B$18*M4,2) | Z4: =ROUND(_xlfn.NORM.INV(N4,Params!$B$13,Params!$B$14)+Params!$B$17+Params!$B$18*N4,1)
A5: 4 | B5: =INT((A5-1)/122)+1 | C5: 0.943188 | D5: 0.054721 | E5: 0.705251 | F5: 0.189104 | G5: 0.681147 | H5: 0.14048 | I5: 0.665131 | J5: 0.299257 | K5: 0.170186 | L5: 0.298246 | M5: 0.493898 | N5: 0.111534 | O5: =IF(C5<=1-Params!$B$4,0,MAX(0.1,ROUND(_xlfn.GAMMA.INV((C5-(1-Params!$B$4))/Params!$B$4,Params!$B$5,Params!$B$6),1))) | P5: =IF(D5<=1-Params!$B$7,0,ROUND(_xlfn.GAMMA.INV((D5-(1-Params!$B$7))/Params!$B$7,Params!$B$8,Params!$B$9),3)) | Q5: =IF(E5<=1-Params!$B$4,0,MAX(0.1,ROUND(_xlfn.GAMMA.INV((E5-(1-Params!$B$4))/Params!$B$4,Params!$B$5,Params!$B$6),1))) | R5: =IF(F5<=1-Params!$B$7,0,ROUND(_xlfn.GAMMA.INV((F5-(1-Params!$B$7))/Params!$B$7,Params!$B$8,Params!$B$9),3)) | S5: =IF(G5<=1-Params!$B$7,0,ROUND((Params!$B$10+Params!$B$11*G5^Params!$B$12)*_xlfn.GAMMA.INV((G5-(1-Params!$B$7))/Params!$B$7,Params!$B$8,Params!$B$9),3)) | T5: =IF(H5<=1-Params!$B$4,0,MAX(0.1,ROUND((Params!$B$10+Params!$B$11*H5^Params!$B$12)*_xlfn.GAMMA.INV((H5-(1-Params!$B$4))/Params!$B$4,Params!$B$5,Params!$B$6),1))) | U5: =ROUND(_xlfn.NORM.INV(I5,Params!$B$13,Params!$B$14),1) | V5: =ROUND(_xlfn.NORM.INV(J5,Params!$B$15,Params!$B$16),2) | W5: =ROUND(_xlfn.NORM.INV(K5,Params!$B$13,Params!$B$14),1) | X5: =ROUND(_xlfn.NORM.INV(L5,Params!$B$15,Params!$B$16),2) | Y5: =ROUND(_xlfn.NORM.INV(M5,Params!$B$15,Params!$B$16)+Params!$B$17+Params!$B$18*M5,2) | Z5: =ROUND(_xlfn.NORM.INV(N5,Params!$B$13,Params!$B$14)+Params!$B$17+Params!$B$18*N5,1)
A6: 5 | B6: =INT((A6-1)/122)+1 | C6: 0.922109 | D6: 0.015077 | E6: 0.539291 | F6: 0.843712 | G6: 0.438799 | H6: 0.589438 | I6: 0.123205 | J6: 0.571702 | K6: 0.27485 | L6: 0.349719 | M6: 0.591482 | N6: 0.209312 | O6: =IF(C6<=1-Params!$B$4,0,MAX(0.1,ROUND(_xlfn.GAMMA.INV((C6-(1-Params!$B$4))/Params!$B$4,Params!$B$5,Params!$B$6),1))) | P6: =IF(D6<=1-Params!$B$7,0,ROUND(_xlfn.GAMMA.INV((D6-(1-Params!$B$7))/Params!$B$7,Params!$B$8,Params!$B$9),3)) | Q6: =IF(E6<=1-Params!$B$4,0,MAX(0.1,ROUND(_xlfn.GAMMA.INV((E6-(1-Params!$B$4))/Params!$B$4,Params!$B$5,Params!$B$6),1))) | R6: =IF(F6<=1-Params!$B$7,0,ROUND(_xlfn.GAMMA.INV((F6-(1-Params!$B$7))/Params!$B$7,Params!$B$8,Params!$B$9),3)) | S6: =IF(G6<=1-Params!$B$7,0,ROUND((Params!$B$10+Params!$B$11*G6^Params!$B$12)*_xlfn.GAMMA.INV((G6-(1-Params!$B$7))/Params!$B$7,Params!$B$8,Params!$B$9),3)) | T6: =IF(H6<=1-Params!$B$4,0,MAX(0.1,ROUND((Params!$B$10+Params!$B$11*H6^Params!$B$12)*_xlfn.GAMMA.INV((H6-(1-Params!$B$4))/Params!$B$4,Params!$B$5,Params!$B$6),1))) | U6: =ROUND(_xlfn.NORM.INV(I6,Params!$B$13,Params!$B$14),1) | V6: =ROUND(_xlfn.NORM.INV(J6,Params!$B$15,Params!$B$16),2) | W6: =ROUND(_xlfn.NORM.INV(K6,Params!$B$13,Params!$B$14),1) | X6: =ROUND(_xlfn.NORM.INV(L6,Params!$B$15,Params!$B$16),2) | Y6: =ROUND(_xlfn.NORM.INV(M6,Params!$B$15,Params!$B$16)+Params!$B$17+Params!$B$18*M6,2) | Z6: =ROUND(_xlfn.NORM.INV(N6,Params!$B$13,Params!$B$14)+Params!$B$17+Params!$B$18*N6,1)
A7: 6 | B7: =INT((A7-1)/122)+1 | C7: 0.563658 | D7: 0.133954 | E7: 0.442071 | F7: 0.906276 | G7: 0.930934 | H7: 0.764668 | I7: 0.133172 | J7: 0.92103 | K7: 0.535918 | L7: 0.798236 | M7: 0.616624 | N7: 0.248707 | O7: =IF(C7<=1-Params!$B$4,0,MAX(0.1,ROUND(_xlfn.GAMMA.INV((C7-(1-Params!$B$4))/Params!$B$4,Params!$B$5,Params!$B$6),1))) | P7: =IF(D7<=1-Params!$B$7,0,ROUND(_xlfn.GAMMA.INV((D7-(1-Params!$B$7))/Params!$B$7,Params!$B$8,Params!$B$9),3)) | Q7: =IF(E7<=1-Params!$B$4,0,MAX(0.1,ROUND(_xlfn.GAMMA.INV((E7-(1-Params!$B$4))/Params!$B$4,Params!$B$5,Params!$B$6),1))) | R7: =IF(F7<=1-Params!$B$7,0,ROUND(_xlfn.GAMMA.INV((F7-(1-Params!$B$7))/Params!$B$7,Params!$B$8,Params!$B$9),3)) | S7: =IF(G7<=1-Params!$B$7,0,ROUND((Params!$B$10+Params!$B$11*G7^Params!$B$12)*_xlfn.GAMMA.INV((G7-(1-Params!$B$7))/Params!$B$7,Params!$B$8,Params!$B$9),3)) | T7: =IF(H7<=1-Params!$B$4,0,MAX(0.1,ROUND((Params!$B$10+Params!$B$11*H7^Params!$B$12)*_xlfn.GAMMA.INV((H7-(1-Params!$B$4))/Params!$B$4,Params!$B$5,Params!$B$6),1))) | U7: =ROUND(_xlfn.NORM.INV(I7,Params!$B$13,Params!$B$14),1) | V7: =ROUND(_xlfn.NORM.INV(J7,Params!$B$15,Params!$B$16),2) | W7: =ROUND(_xlfn.NORM.INV(K7,Params!$B$13,Params!$B$14),1) | X7: =ROUND(_xlfn.NORM.INV(L7,Params!$B$15,Params!$B$16),2) | Y7: =ROUND(_xlfn.NORM.INV(M7,Params!$B$15,Params!$B$16)+Params!$B$17+Params!$B$18*M7,2) | Z7: =ROUND(_xlfn.NORM.INV(N7,Params!$B$13,Params!$B$14)+Params!$B$17+Params!$B$18*N7,1)
A8: 7 | B8: =INT((A8-1)/122)+1 | C8: 0.722578 | D8: 0.727102 | E8: 0.271734 | F8: 0.84546 | G8: 0.853359 | H8: 0.122659 | I8: 0.227008 | J8: 0.93784 | K8: 0.627071 | L8: 0.6405 | M8: 0.654141 | N8: 0.0958 | O8: =IF(C8<=1-Params!$B$4,0,MAX(0.1,ROUND(_xlfn.GAMMA.INV((C8-(1-Params!$B$4))/Params!$B$4,Params!$B$5,Params!$B$6),1))) | P8: =IF(D8<=1-Params!$B$7,0,ROUND(_xlfn.GAMMA.INV((D8-(1-Params!$B$7))/Params!$B$7,Params!$B$8,Params!$B$9),3)) | Q8: =IF(E8<=1-Params!$B$4,0,MAX(0.1,ROUND(_xlfn.GAMMA.INV((E8-(1-Params!$B$4))/Params!$B$4,Params!$B$5,Params!$B$6),1))) | R8: =IF(F8<=1-Params!$B$7,0,ROUND(_xlfn.GAMMA.INV((F8-(1-Params!$B$7))/Params!$B$7,Params!$B$8,Params!$B$9),3)) | S8: =IF(G8<=1-Params!$B$7,0,ROUND((Params!$B$10+Params!$B$11*G8^Params!$B$12)*_xlfn.GAMMA.INV((G8-(1-Params!$B$7))/Params!$B$7,Params!$B$8,Params!$B$9),3)) | T8: =IF(H8<=1-Params!$B$4,0,MAX(0.1,ROUND((Params!$B$10+Params!$B$11*H8^Params!$B$12)*_xlfn.GAMMA.INV((H8-(1-Params!$B$4))/Params!$B$4,Params!$B$5,Params!$B$6),1))) | U8: =ROUND(_xlfn.NORM.INV(I8,Params!$B$13,Params!$B$14),1) | V8: =ROUND(_xlfn.NORM.INV(J8,Params!$B$15,Params!$B$16),2) | W8: =ROUND(_xlfn.NORM.INV(K8,Params!$B$13,Params!$B$14),1) | X8: =ROUND(_xlfn.NORM.INV(L8,Params!$B$15,Params!$B$16),2) | Y8: =ROUND(_xlfn.NORM.INV(M8,Params!$B$15,Params!$B$16)+Params!$B$17+Params!$B$18*M8,2) | Z8: =ROUND(_xlfn.NORM.INV(N8,Params!$B$13,Params!$B$14)+Params!$B$17+Params!$B$18*N8,1)
A9: 8 | B9: =INT((A9-1)/122)+1 | C9: 0.95695 | D9: 0.869601 | E9: 0.546139 | F9: 0.10918 | G9: 0.325263 | H9: 0.058049 | I9: 0.375186 | J9: 0.455822 | K9: 0.797763 | L9: 0.140729 | M9: 0.785541 | N9: 0.122948 | O9: =IF(C9<=1-Params!$B$4,0,MAX(0.1,ROUND(_xlfn.GAMMA.INV((C9-(1-Params!$B$4))/Params!$B$4,Params!$B$5,Params!$B$6),1))) | P9: =IF(D9<=1-Params!$B$7,0,ROUND(_xlfn.GAMMA.INV((D9-(1-Params!$B$7))/Params!$B$7,Params!$B$8,Params!$B$9),3)) | Q9: =IF(E9<=1-Params!$B$4,0,MAX(0.1,ROUND(_xlfn.GAMMA.INV((E9-(1-Params!$B$4))/Params!$B$4,Params!$B$5,Params!$B$6),1))) | R9: =IF(F9<=1-Params!$B$7,0,ROUND(_xlfn.GAMMA.INV((F9-(1-Params!$B$7))/Params!$B$7,Params!$B$8,Params!$B$9),3)) | S9: =IF(G9<=1-Params!$B$7,0,ROUND((Params!$B$10+Params!$B$11*G9^Params!$B$12)*_xlfn.GAMMA.INV((G9-(1-Params!$B$7))/Params!$B$7,Params!$B$8,Params!$B$9),3)) | T9: =IF(H9<=1-Params!$B$4,0,MAX(0.1,ROUND((Params!$B$10+Params!$B$11*H9^Params!$B$12)*_xlfn.GAMMA.INV((H9-(1-Params!$B$4))/Params!$B$4,Params!$B$5,Params!$B$6),1))) | U9: =ROUND(_xlfn.NORM.INV(I9,Params!$B$13,Params!$B$14),1) | V9: =ROUND(_xlfn.NORM.INV(J9,Params!$B$15,Params!$B$16),2) | W9: =ROUND(_xlfn.NORM.INV(K9,Params!$B$13,Params!$B$14),1) | X9: =ROUND(_xlfn.NORM.INV(L9,Params!$B$15,Params!$B$16),2) | Y9: =ROUND(_xlfn.NORM.INV(M9,Params!$B$15,Params!$B$16)+Params!$B$17+Params!$B$18*M9,2) | Z9: =ROUND(_xlfn.NORM.INV(N9,Params!$B$13,Params!$B$14)+Params!$B$17+Params!$B$18*N9,1)
A10: 9 | B10: =INT((A10-1)/122)+1 | C10: 0.999434 | D10: 0.621561 | E10: 0.434385 | F10: 0.929831 | G10: 0.086048 | H10: 0.060428 | I10: 0.735413 | J10: 0.593182 | K10: 0.548973 | L10: 0.05845 | M10: 0.864875 | N10: 0.116399 | O10: =IF(C10<=1-Params!$B$4,0,MAX(0.1,ROUND(_xlfn.GAMMA.INV((C10-(1-Params!$B$4))/Params!$B$4,Params!$B$5,Params!$B$6),1))) | P10: =IF(D10<=1-Params!$B$7,0,ROUND(_xlfn.GAMMA.INV((D10-(1-Params!$B$7))/Params!$B$7,Params!$B$8,Params!$B$9),3)) | Q10: =IF(E10<=1-Params!$B$4,0,MAX(0.1,ROUND(_xlfn.GAMMA.INV((E10-(1-Params!$B$4))/Params!$B$4,Params!$B$5,Params!$B$6),1))) | R10: =IF(F10<=1-Params!$B$7,0,ROUND(_xlfn.GAMMA.INV((F10-(1-Params!$B$7))/Params!$B$7,Params!$B$8,Params!$B$9),3)) | S10: =IF(G10<=1-Params!$B$7,0,ROUND((Params!$B$10+Params!$B$11*G10^Params!$B$12)*_xlfn.GAMMA.INV((G10-(1-Params!$B$7))/Params!$B$7,Params!$B$8,Params!$B$9),3)) | T10: =IF(H10<=1-Params!$B$4,0,MAX(0.1,ROUND((Params!$B$10+Params!$B$11*H10^Params!$B$12)*_xlfn.GAMMA.INV((H10-(1-Params!$B$4))/Params!$B$4,Params!$B$5,Params!$B$6),1))) | U10: =ROUND(_xlfn.NORM.INV(I10,Params!$B$13,Params!$B$14),1) | V10: =ROUND(_xlfn.NORM.INV(J10,Params!$B$15,Params!$B$16),2) | W10: =ROUND(_xlfn.NORM.INV(K10,Params!$B$13,Params!$B$14),1) | X10: =ROUND(_xlfn.NORM.INV(L10,Params!$B$15,Params!$B$16),2) | Y10: =ROUND(_xlfn.NORM.INV(M10,Params!$B$15,Params!$B$16)+Params!$B$17+Params!$B$18*M10,2) | Z10: =ROUND(_xlfn.NORM.INV(N10,Params!$B$13,Params!$B$14)+Params!$B$17+Params!$B$18*N10,1)
A11: 10 | B11: =INT((A11-1)/122)+1 | C11: 0.608163 | D11: 0.858835 | E11: 0.908147 | F11: 0.999491 | G11: 0.472054 | H11: 0.380971 | I11: 0.234828 | J11: 0.549658 | K11: 0.843891 | L11: 0.228727 | M11: 0.502943 | N11: 0.230589 | O11: =IF(C11<=1-Params!$B$4,0,MAX(0.1,ROUND(_xlfn.GAMMA.INV((C11-(1-Params!$B$4))/Params!$B$4,Params!$B$5,Params!$B$6),1))) | P11: =IF(D11<=1-Params!$B$7,0,ROUND(_xlfn.GAMMA.INV((D11-(1-Params!$B$7))/Params!$B$7,Params!$B$8,Params!$B$9),3)) | Q11: =IF(E11<=1-Params!$B$4,0,MAX(0.1,ROUND(_xlfn.GAMMA.INV((E11-(1-Params!$B$4))/Params!$B$4,Params!$B$5,Params!$B$6),1))) | R11: =IF(F11<=1-Params!$B$7,0,ROUND(_xlfn.GAMMA.INV((F11-(1-Params!$B$7))/Params!$B$7,Params!$B$8,Params!$B$9),3)) | S11: =IF(G11<=1-Params!$B$7,0,ROUND((Params!$B$10+Params!$B$11*G11^Params!$B$12)*_xlfn.GAMMA.INV((G11-(1-Params!$B$7))/Params!$B$7,Params!$B$8,Params!$B$9),3)) | T11: =IF(H11<=1-Params!$B$4,0,MAX(0.1,ROUND((Params!$B$10+Params!$B$11*H11^Params!$B$12)*_xlfn.GAMMA.INV((H11-(1-Params!$B$4))/Params!$B$4,Params!$B$5,Params!$B$6),1))) | U11: =ROUND(_xlfn.NORM.INV(I11,Params!$B$13,Params!$B$14),1) | V11: =ROUND(_xlfn.NORM.INV(J11,Params!$B$15,Params!$B$16),2) | W11: =ROUND(_xlfn.NORM.INV(K11,Params!$B$13,Params!$B$14),1) | X11: =ROUND(_xlfn.NORM.INV(L11,Params!$B$15,Params!$B$16),2) | Y11: =ROUND(_xlfn.NORM.INV(M11,Params!$B$15,Params!$B$16)+Params!$B$17+Params!$B$18*M11,2) | Z11: =ROUND(_xlfn.NORM.INV(N11,Params!$B$13,Params!$B$14)+Params!$B$17+Params!$B$18*N11,1)
A12: 11 | B12: =INT((A12-1)/122)+1 | C12: 0.862978 | D12: 0.705869 | E12: 0.495907 | F12: 0.509594 | G12: 0.070649 | H12: 0.563828 | I12: 0.259877 | J12: 0.285753 | K12: 0.706001 | L12: 0.213928 | M12: 0.29096 | N12: 0.78141 | O12: =IF(C12<=1-Params!$B$4,0,MAX(0.1,ROUND(_xlfn.GAMMA.INV((C12-(1-Params!$B$4))/Params!$B$4,Params!$B$5,Params!$B$6),1))) | P12: =IF(D12<=1-Params!$B$7,0,ROUND(_xlfn.GAMMA.INV((D12-(1-Params!$B$7))/Params!$B$7,Params!$B$8,Params!$B$9),3)) | Q12: =IF(E12<=1-Params!$B$4,0,MAX(0.1,ROUND(_xlfn.GAMMA.INV((E12-(1-Params!$B$4))/Params!$B$4,Params!$B$5,Params!$B$6),1))) | R12: =IF(F12<=1-Params!$B$7,0,ROUND(_xlfn.GAMMA.INV((F12-(1-Params!$B$7))/Params!$B$7,Params!$B$8,Params!$B$9),3)) | S12: =IF(G12<=1-Params!$B$7,0,ROUND((Params!$B$10+Params!$B$11*G12^Params!$B$12)*_xlfn.GAMMA.INV((G12-(1-Params!$B$7))/Params!$B$7,Params!$B$8,Params!$B$9),3)) | T12: =IF(H12<=1-Params!$B$4,0,MAX(0.1,ROUND((Params!$B$10+Params!$B$11*H12^Params!$B$12)*_xlfn.GAMMA.INV((H12-(1-Params!$B$4))/Params!$B$4,Params!$B$5,Params!$B$6),1))) | U12: =ROUND(_xlfn.NORM.INV(I12,Params!$B$13,Params!$B$14),1) | V12: =ROUND(_xlfn.NORM.INV(J12,Params!$B$15,Params!$B$16),2) | W12: =ROUND(_xlfn.NORM.INV(K12,Params!$B$13,Params!$B$14),1) | X12: =ROUND(_xlfn.NORM.INV(L12,Params!$B$15,Params!$B$16),2) | Y12: =ROUND(_xlfn.NORM.INV(M12,Params!$B$15,Params!$B$16)+Params!$B$17+Params!$B$18*M12,2) | Z12: =ROUND(_xlfn.NORM.INV(N12,Params!$B$13,Params!$B$14)+Params!$B$17+Params!$B$18*N12,1)
A13: 12 | B13: =INT((A13-1)/122)+1 | C13: 0.807254 | D13: 0.994337 | E13: 0.953738 | F13: 0.090085 | G13: 0.615791 | H13: 0.543274 | I13: 0.222157 | J13: 0.36809 | K13: 0.435653 | L13: 0.157599 | M13: 0.460366 | N13: 0.640632 | O13: =IF(C13<=1-Params!$B$4,0,MAX(0.1,ROUND(_xlfn.GAMMA.INV((C13-(1-Params!$B$4))/Params!$B$4,Params!$B$5,Params!$B$6),1))) | P13: =IF(D13<=1-Params!$B$7,0,ROUND(_xlfn.GAMMA.INV((D13-(1-Params!$B$7))/Params!$B$7,Params!$B$8,Params!$B$9),3)) | Q13: =IF(E13<=1-Params!$B$4,0,MAX(0.1,ROUND(_xlfn.GAMMA.INV((E13-(1-Params!$B$4))/Params!$B$4,Params!$B$5,Params!$B$6),1))) | R13: =IF(F13<=1-Params!$B$7,0,ROUND(_xlfn.GAMMA.INV((F13-(1-Params!$B$7))/Params!$B$7,Params!$B$8,Params!$B$9),3)) | S13: =IF(G13<=1-Params!$B$7,0,ROUND((Params!$B$10+Params!$B$11*G13^Params!$B$12)*_xlfn.GAMMA.INV((G13-(1-Params!$B$7))/Params!$B$7,Params!$B$8,Params!$B$9),3)) | T13: =IF(H13<=1-Params!$B$4,0,MAX(0.1,ROUND((Params!$B$10+Params!$B$11*H13^Params!$B$12)*_xlfn.GAMMA.INV((H13-(1-Params!$B$4))/Params!$B$4,Params!$B$5,Params!$B$6),1))) | U13: =ROUND(_xlfn.NORM.INV(I13,Params!$B$13,Params!$B$14),1) | V13: =ROUND(_xlfn.NORM.INV(J13,Params!$B$15,Params!$B$16),2) | W13: =ROUND(_xlfn.NORM.INV(K13,Params!$B$13,Params!$B$14),1) | X13: =ROUND(_xlfn.NORM.INV(L13,Params!$B$15,Params!$B$16),2) | Y13: =ROUND(_xlfn.NORM.INV(M13,Params!$B$15,Params!$B$16)+Params!$B$17+Params!$B$18*M13,2) | Z13: =ROUND(_xlfn.NORM.INV(N13,Params!$B$13,Params!$B$14)+Params!$B$17+Params!$B$18*N13,1)
... A2441: 2440 | B2441: =INT((A2441-1)/122)+1 | C2441: 0.175422 | D2441: 0.604253 | E2441: 0.981725 | F2441: 0.271145 | G2441: 0.900256 | H2441: 0.880261 | I2441: 0.555406 | J2441: 0.214973 | K2441: 0.731488 | L2441: 0.309777 | M2441: 0.802824 | N2441: 0.871195 | O2441: =IF(C2441<=1-Params!$B$4,0,MAX(0.1,ROUND(_xlfn.GAMMA.INV((C2441-(1-Params!$B$4))/Params!$B$4,Params!$B$5,Params!$B$6),1))) | P2441: =IF(D2441<=1-Params!$B$7,0,ROUND(_xlfn.GAMMA.INV((D2441-(1-Params!$B$7))/Params!$B$7,Params!$B$8,Params!$B$9),3)) | Q2441: =IF(E2441<=1-Params!$B$4,0,MAX(0.1,ROUND(_xlfn.GAMMA.INV((E2441-(1-Params!$B$4))/Params!$B$4,Params!$B$5,Params!$B$6),1))) | R2441: =IF(F2441<=1-Params!$B$7,0,ROUND(_xlfn.GAMMA.INV((F2441-(1-Params!$B$7))/Params!$B$7,Params!$B$8,Params!$B$9),3)) | S2441: =IF(G2441<=1-Params!$B$7,0,ROUND((Params!$B$10+Params!$B$11*G2441^Params!$B$12)*_xlfn.GAMMA.INV((G2441-(1-Params!$B$7))/Params!$B$7,Params!$B$8,Params!$B$9),3)) | T2441: =IF(H2441<=1-Params!$B$4,0,MAX(0.1,ROUND((Params!$B$10+Params!$B$11*H2441^Params!$B$12)*_xlfn.GAMMA.INV((H2441-(1-Params!$B$4))/Params!$B$4,Params!$B$5,Params!$B$6),1))) | U2441: =ROUND(_xlfn.NORM.INV(I2441,Params!$B$13,Params!$B$14),1) | V2441: =ROUND(_xlfn.NORM.INV(J2441,Params!$B$15,Params!$B$16),2) | W2441: =ROUND(_xlfn.NORM.INV(K2441,Params!$B$13,Params!$B$14),1) | X2441: =ROUND(_xlfn.NORM.INV(L2441,Params!$B$15,Params!$B$16),2) | Y2441: =ROUND(_xlfn.NORM.INV(M2441,Params!$B$15,Params!$B$16)+Params!$B$17+Params!$B$18*M2441,2) | Z2441: =ROUND(_xlfn.NORM.INV(N2441,Params!$B$13,Params!$B$14)+Params!$B$17+Params!$B$18*N2441,1)

Sheet Occurrence
A1: Occurrence adjustment of model rainfall (wet-day threshold) | H1: day | I1: mod_cal adjusted | J1: mod_val adjusted | K1: mod_fut adjusted
A2: Idea: choose the model threshold so that the model has as many wet days as the observations. Calibration period only; the same threshold is then applied to validation and future. | H2: =Data!A2 | I2: =IF(Data!P2>$B$8,Data!P2,0) | J2: =IF(Data!R2>$B$8,Data!R2,0) | K2: =IF(Data!S2>$B$8,Data!S2,0)
H3: =Data!A3 | I3: =IF(Data!P3>$B$8,Data!P3,0) | J3: =IF(Data!R3>$B$8,Data!R3,0) | K3: =IF(Data!S3>$B$8,Data!S3,0)
A4: N, days in the calibration period | B4: =COUNT(Data!$O$2:$O$2441) | H4: =Data!A4 | I4: =IF(Data!P4>$B$8,Data!P4,0) | J4: =IF(Data!R4>$B$8,Data!R4,0) | K4: =IF(Data!S4>$B$8,Data!S4,0)
A5: Observed wet days (rain > 0) | B5: =COUNTIF(Data!$O$2:$O$2441,">0") | H5: =Data!A5 | I5: =IF(Data!P5>$B$8,Data!P5,0) | J5: =IF(Data!R5>$B$8,Data!R5,0) | K5: =IF(Data!S5>$B$8,Data!S5,0)
A6: Observed wet-day fraction | B6: =B5/B4 | H6: =Data!A6 | I6: =IF(Data!P6>$B$8,Data!P6,0) | J6: =IF(Data!R6>$B$8,Data!R6,0) | K6: =IF(Data!S6>$B$8,Data!S6,0)
A7: Model wet-day fraction, raw (rain > 0) | B7: =COUNTIF(Data!$P$2:$P$2441,">0")/B4 | H7: =Data!A7 | I7: =IF(Data!P7>$B$8,Data!P7,0) | J7: =IF(Data!R7>$B$8,Data!R7,0) | K7: =IF(Data!S7>$B$8,Data!S7,0)
A8: Wet-day threshold for the model (mm/day) | B8: =_xlfn.PERCENTILE.INC(Data!$P$2:$P$2441,1-B6) | H8: =Data!A8 | I8: =IF(Data!P8>$B$8,Data!P8,0) | J8: =IF(Data!R8>$B$8,Data!R8,0) | K8: =IF(Data!S8>$B$8,Data!S8,0)
A9: Model wet-day fraction after adjustment | B9: =COUNTIF(Occurrence!$I$2:$I$2441,">0")/B4 | H9: =Data!A9 | I9: =IF(Data!P9>$B$8,Data!P9,0) | J9: =IF(Data!R9>$B$8,Data!R9,0) | K9: =IF(Data!S9>$B$8,Data!S9,0)
H10: =Data!A10 | I10: =IF(Data!P10>$B$8,Data!P10,0) | J10: =IF(Data!R10>$B$8,Data!R10,0) | K10: =IF(Data!S10>$B$8,Data!S10,0)
H11: =Data!A11 | I11: =IF(Data!P11>$B$8,Data!P11,0) | J11: =IF(Data!R11>$B$8,Data!R11,0) | K11: =IF(Data!S11>$B$8,Data!S11,0)
A12: The drizzle problem: wet-day fraction as a function of the threshold | H12: =Data!A12 | I12: =IF(Data!P12>$B$8,Data!P12,0) | J12: =IF(Data!R12>$B$8,Data!R12,0) | K12: =IF(Data!S12>$B$8,Data!S12,0)
A13: Threshold (mm/day) | B13: Obs wet fraction | C13: Model wet fraction | D13: Obs mean wet-day rain | E13: Model mean wet-day rain | H13: =Data!A13 | I13: =IF(Data!P13>$B$8,Data!P13,0) | J13: =IF(Data!R13>$B$8,Data!R13,0) | K13: =IF(Data!S13>$B$8,Data!S13,0)
A14: 0 | B14: =COUNTIF(Data!$O$2:$O$2441,">"&A14)/$B$4 | C14: =COUNTIF(Data!$P$2:$P$2441,">"&A14)/$B$4 | D14: =IFERROR(AVERAGEIFS(Data!$O$2:$O$2441,Data!$O$2:$O$2441,">"&A14),0) | E14: =IFERROR(AVERAGEIFS(Data!$P$2:$P$2441,Data!$P$2:$P$2441,">"&A14),0) | H14: =Data!A14 | I14: =IF(Data!P14>$B$8,Data!P14,0) | J14: =IF(Data!R14>$B$8,Data!R14,0) | K14: =IF(Data!S14>$B$8,Data!S14,0)
A15: 0.1 | B15: =COUNTIF(Data!$O$2:$O$2441,">"&A15)/$B$4 | C15: =COUNTIF(Data!$P$2:$P$2441,">"&A15)/$B$4 | D15: =IFERROR(AVERAGEIFS(Data!$O$2:$O$2441,Data!$O$2:$O$2441,">"&A15),0) | E15: =IFERROR(AVERAGEIFS(Data!$P$2:$P$2441,Data!$P$2:$P$2441,">"&A15),0) | H15: =Data!A15 | I15: =IF(Data!P15>$B$8,Data!P15,0) | J15: =IF(Data!R15>$B$8,Data!R15,0) | K15: =IF(Data!S15>$B$8,Data!S15,0)
A16: 0.25 | B16: =COUNTIF(Data!$O$2:$O$2441,">"&A16)/$B$4 | C16: =COUNTIF(Data!$P$2:$P$2441,">"&A16)/$B$4 | D16: =IFERROR(AVERAGEIFS(Data!$O$2:$O$2441,Data!$O$2:$O$2441,">"&A16),0) | E16: =IFERROR(AVERAGEIFS(Data!$P$2:$P$2441,Data!$P$2:$P$2441,">"&A16),0) | H16: =Data!A16 | I16: =IF(Data!P16>$B$8,Data!P16,0) | J16: =IF(Data!R16>$B$8,Data!R16,0) | K16: =IF(Data!S16>$B$8,Data!S16,0)
A17: 0.5 | B17: =COUNTIF(Data!$O$2:$O$2441,">"&A17)/$B$4 | C17: =COUNTIF(Data!$P$2:$P$2441,">"&A17)/$B$4 | D17: =IFERROR(AVERAGEIFS(Data!$O$2:$O$2441,Data!$O$2:$O$2441,">"&A17),0) | E17: =IFERROR(AVERAGEIFS(Data!$P$2:$P$2441,Data!$P$2:$P$2441,">"&A17),0) | H17: =Data!A17 | I17: =IF(Data!P17>$B$8,Data!P17,0) | J17: =IF(Data!R17>$B$8,Data!R17,0) | K17: =IF(Data!S17>$B$8,Data!S17,0)
A18: 0.75 | B18: =COUNTIF(Data!$O$2:$O$2441,">"&A18)/$B$4 | C18: =COUNTIF(Data!$P$2:$P$2441,">"&A18)/$B$4 | D18: =IFERROR(AVERAGEIFS(Data!$O$2:$O$2441,Data!$O$2:$O$2441,">"&A18),0) | E18: =IFERROR(AVERAGEIFS(Data!$P$2:$P$2441,Data!$P$2:$P$2441,">"&A18),0) | H18: =Data!A18 | I18: =IF(Data!P18>$B$8,Data!P18,0) | J18: =IF(Data!R18>$B$8,Data!R18,0) | K18: =IF(Data!S18>$B$8,Data!S18,0)
A19: 1 | B19: =COUNTIF(Data!$O$2:$O$2441,">"&A19)/$B$4 | C19: =COUNTIF(Data!$P$2:$P$2441,">"&A19)/$B$4 | D19: =IFERROR(AVERAGEIFS(Data!$O$2:$O$2441,Data!$O$2:$O$2441,">"&A19),0) | E19: =IFERROR(AVERAGEIFS(Data!$P$2:$P$2441,Data!$P$2:$P$2441,">"&A19),0) | H19: =Data!A19 | I19: =IF(Data!P19>$B$8,Data!P19,0) | J19: =IF(Data!R19>$B$8,Data!R19,0) | K19: =IF(Data!S19>$B$8,Data!S19,0)
A20: 1.5 | B20: =COUNTIF(Data!$O$2:$O$2441,">"&A20)/$B$4 | C20: =COUNTIF(Data!$P$2:$P$2441,">"&A20)/$B$4 | D20: =IFERROR(AVERAGEIFS(Data!$O$2:$O$2441,Data!$O$2:$O$2441,">"&A20),0) | E20: =IFERROR(AVERAGEIFS(Data!$P$2:$P$2441,Data!$P$2:$P$2441,">"&A20),0) | H20: =Data!A20 | I20: =IF(Data!P20>$B$8,Data!P20,0) | J20: =IF(Data!R20>$B$8,Data!R20,0) | K20: =IF(Data!S20>$B$8,Data!S20,0)
A21: 2 | B21: =COUNTIF(Data!$O$2:$O$2441,">"&A21)/$B$4 | C21: =COUNTIF(Data!$P$2:$P$2441,">"&A21)/$B$4 | D21: =IFERROR(AVERAGEIFS(Data!$O$2:$O$2441,Data!$O$2:$O$2441,">"&A21),0) | E21: =IFERROR(AVERAGEIFS(Data!$P$2:$P$2441,Data!$P$2:$P$2441,">"&A21),0) | H21: =Data!A21 | I21: =IF(Data!P21>$B$8,Data!P21,0) | J21: =IF(Data!R21>$B$8,Data!R21,0) | K21: =IF(Data!S21>$B$8,Data!S21,0)
A22: 3 | B22: =COUNTIF(Data!$O$2:$O$2441,">"&A22)/$B$4 | C22: =COUNTIF(Data!$P$2:$P$2441,">"&A22)/$B$4 | D22: =IFERROR(AVERAGEIFS(Data!$O$2:$O$2441,Data!$O$2:$O$2441,">"&A22),0) | E22: =IFERROR(AVERAGEIFS(Data!$P$2:$P$2441,Data!$P$2:$P$2441,">"&A22),0) | H22: =Data!A22 | I22: =IF(Data!P22>$B$8,Data!P22,0) | J22: =IF(Data!R22>$B$8,Data!R22,0) | K22: =IF(Data!S22>$B$8,Data!S22,0)
A23: 5 | B23: =COUNTIF(Data!$O$2:$O$2441,">"&A23)/$B$4 | C23: =COUNTIF(Data!$P$2:$P$2441,">"&A23)/$B$4 | D23: =IFERROR(AVERAGEIFS(Data!$O$2:$O$2441,Data!$O$2:$O$2441,">"&A23),0) | E23: =IFERROR(AVERAGEIFS(Data!$P$2:$P$2441,Data!$P$2:$P$2441,">"&A23),0) | H23: =Data!A23 | I23: =IF(Data!P23>$B$8,Data!P23,0) | J23: =IF(Data!R23>$B$8,Data!R23,0) | K23: =IF(Data!S23>$B$8,Data!S23,0)
H24: =Data!A24 | I24: =IF(Data!P24>$B$8,Data!P24,0) | J24: =IF(Data!R24>$B$8,Data!R24,0) | K24: =IF(Data!S24>$B$8,Data!S24,0)
A25: The model has rain on almost every day, most of it a fraction of a millimetre. A threshold of about 1 mm brings its wet-day fraction down to the observed value. | H25: =Data!A25 | I25: =IF(Data!P25>$B$8,Data!P25,0) | J25: =IF(Data!R25>$B$8,Data!R25,0) | K25: =IF(Data!S25>$B$8,Data!S25,0)
H26: =Data!A26 | I26: =IF(Data!P26>$B$8,Data!P26,0) | J26: =IF(Data!R26>$B$8,Data!R26,0) | K26: =IF(Data!S26>$B$8,Data!S26,0)
H27: =Data!A27 | I27: =IF(Data!P27>$B$8,Data!P27,0) | J27: =IF(Data!R27>$B$8,Data!R27,0) | K27: =IF(Data!S27>$B$8,Data!S27,0)
H28: =Data!A28 | I28: =IF(Data!P28>$B$8,Data!P28,0) | J28: =IF(Data!R28>$B$8,Data!R28,0) | K28: =IF(Data!S28>$B$8,Data!S28,0)
H29: =Data!A29 | I29: =IF(Data!P29>$B$8,Data!P29,0) | J29: =IF(Data!R29>$B$8,Data!R29,0) | K29: =IF(Data!S29>$B$8,Data!S29,0)
H30: =Data!A30 | I30: =IF(Data!P30>$B$8,Data!P30,0) | J30: =IF(Data!R30>$B$8,Data!R30,0) | K30: =IF(Data!S30>$B$8,Data!S30,0)
H31: =Data!A31 | I31: =IF(Data!P31>$B$8,Data!P31,0) | J31: =IF(Data!R31>$B$8,Data!R31,0) | K31: =IF(Data!S31>$B$8,Data!S31,0)
H32: =Data!A32 | I32: =IF(Data!P32>$B$8,Data!P32,0) | J32: =IF(Data!R32>$B$8,Data!R32,0) | K32: =IF(Data!S32>$B$8,Data!S32,0)
H33: =Data!A33 | I33: =IF(Data!P33>$B$8,Data!P33,0) | J33: =IF(Data!R33>$B$8,Data!R33,0) | K33: =IF(Data!S33>$B$8,Data!S33,0)
H34: =Data!A34 | I34: =IF(Data!P34>$B$8,Data!P34,0) | J34: =IF(Data!R34>$B$8,Data!R34,0) | K34: =IF(Data!S34>$B$8,Data!S34,0)
H35: =Data!A35 | I35: =IF(Data!P35>$B$8,Data!P35,0) | J35: =IF(Data!R35>$B$8,Data!R35,0) | K35: =IF(Data!S35>$B$8,Data!S35,0)
H36: =Data!A36 | I36: =IF(Data!P36>$B$8,Data!P36,0) | J36: =IF(Data!R36>$B$8,Data!R36,0) | K36: =IF(Data!S36>$B$8,Data!S36,0)
H37: =Data!A37 | I37: =IF(Data!P37>$B$8,Data!P37,0) | J37: =IF(Data!R37>$B$8,Data!R37,0) | K37: =IF(Data!S37>$B$8,Data!S37,0)
... H2441: =Data!A2441 | I2441: =IF(Data!P2441>$B$8,Data!P2441,0) | J2441: =IF(Data!R2441>$B$8,Data!R2441,0) | K2441: =IF(Data!S2441>$B$8,Data!S2441,0)

Sheet Delta
A1: Empirical (delta) method: scale the mean (and spread) of the model | H1: day | I1: rain val: mean only | J1: rain val: mean+spread | K1: rain fut: mean only | L1: rain fut: mean+spread | M1: temp val: shift | N1: temp val: shift+spread | O1: temp fut: shift | P1: temp fut: shift+spread
A2: Rain (multiplicative, wet days only, after occurrence adjustment): y = (x - m_t)*s_obs/s_mod + m_t*m_obs/m_mod. Temperature (additive): y = (x - m_t)*s_obs/s_mod + m_t + (m_obs - m_mod). m_t = mean of the series being corrected. | H2: =Data!A2 | I2: =IF(Occurrence!J2>0,Occurrence!J2*$B$6,0) | J2: =IF(Occurrence!J2>0,MAX(0,(Occurrence!J2-$D$4)*$B$7+$D$4*$B$6),0) | K2: =IF(Occurrence!K2>0,Occurrence!K2*$B$6,0) | L2: =IF(Occurrence!K2>0,MAX(0,(Occurrence!K2-$E$4)*$B$7+$E$4*$B$6),0) | M2: =Data!X2+$B$11 | N2: =(Data!X2-$D$9)*$B$12+$D$9+$B$11 | O2: =Data!Y2+$B$11 | P2: =(Data!Y2-$E$9)*$B$12+$E$9+$B$11
A3: Statistic | B3: Obs cal | C3: Model cal | D3: Model val (target) | E3: Model fut (target) | H3: =Data!A3 | I3: =IF(Occurrence!J3>0,Occurrence!J3*$B$6,0) | J3: =IF(Occurrence!J3>0,MAX(0,(Occurrence!J3-$D$4)*$B$7+$D$4*$B$6),0) | K3: =IF(Occurrence!K3>0,Occurrence!K3*$B$6,0) | L3: =IF(Occurrence!K3>0,MAX(0,(Occurrence!K3-$E$4)*$B$7+$E$4*$B$6),0) | M3: =Data!X3+$B$11 | N3: =(Data!X3-$D$9)*$B$12+$D$9+$B$11 | O3: =Data!Y3+$B$11 | P3: =(Data!Y3-$E$9)*$B$12+$E$9+$B$11
A4: Rain: wet-day mean (mm) | B4: =AVERAGEIFS(Data!$O$2:$O$2441,Data!$O$2:$O$2441,">0") | C4: =AVERAGEIFS(Occurrence!$I$2:$I$2441,Occurrence!$I$2:$I$2441,">0") | D4: =AVERAGEIFS(Occurrence!$J$2:$J$2441,Occurrence!$J$2:$J$2441,">0") | E4: =AVERAGEIFS(Occurrence!$K$2:$K$2441,Occurrence!$K$2:$K$2441,">0") | H4: =Data!A4 | I4: =IF(Occurrence!J4>0,Occurrence!J4*$B$6,0) | J4: =IF(Occurrence!J4>0,MAX(0,(Occurrence!J4-$D$4)*$B$7+$D$4*$B$6),0) | K4: =IF(Occurrence!K4>0,Occurrence!K4*$B$6,0) | L4: =IF(Occurrence!K4>0,MAX(0,(Occurrence!K4-$E$4)*$B$7+$E$4*$B$6),0) | M4: =Data!X4+$B$11 | N4: =(Data!X4-$D$9)*$B$12+$D$9+$B$11 | O4: =Data!Y4+$B$11 | P4: =(Data!Y4-$E$9)*$B$12+$E$9+$B$11
A5: Rain: wet-day standard deviation (mm) | B5: =SQRT((SUMPRODUCT((Data!$O$2:$O$2441>0)*Data!$O$2:$O$2441^2)-COUNTIF(Data!$O$2:$O$2441,">0")*B4^2)/(COUNTIF(Data!$O$2:$O$2441,">0")-1)) | C5: =SQRT((SUMPRODUCT((Occurrence!$I$2:$I$2441>0)*Occurrence!$I$2:$I$2441^2)-COUNTIF(Occurrence!$I$2:$I$2441,">0")*C4^2)/(COUNTIF(Occurrence!$I$2:$I$2441,">0")-1)) | D5: =SQRT((SUMPRODUCT((Occurrence!$J$2:$J$2441>0)*Occurrence!$J$2:$J$2441^2)-COUNTIF(Occurrence!$J$2:$J$2441,">0")*D4^2)/(COUNTIF(Occurrence!$J$2:$J$2441,">0")-1)) | E5: =SQRT((SUMPRODUCT((Occurrence!$K$2:$K$2441>0)*Occurrence!$K$2:$K$2441^2)-COUNTIF(Occurrence!$K$2:$K$2441,">0")*E4^2)/(COUNTIF(Occurrence!$K$2:$K$2441,">0")-1)) | H5: =Data!A5 | I5: =IF(Occurrence!J5>0,Occurrence!J5*$B$6,0) | J5: =IF(Occurrence!J5>0,MAX(0,(Occurrence!J5-$D$4)*$B$7+$D$4*$B$6),0) | K5: =IF(Occurrence!K5>0,Occurrence!K5*$B$6,0) | L5: =IF(Occurrence!K5>0,MAX(0,(Occurrence!K5-$E$4)*$B$7+$E$4*$B$6),0) | M5: =Data!X5+$B$11 | N5: =(Data!X5-$D$9)*$B$12+$D$9+$B$11 | O5: =Data!Y5+$B$11 | P5: =(Data!Y5-$E$9)*$B$12+$E$9+$B$11
A6: Rain: mean ratio, obs / model (cal) | B6: =B4/C4 | H6: =Data!A6 | I6: =IF(Occurrence!J6>0,Occurrence!J6*$B$6,0) | J6: =IF(Occurrence!J6>0,MAX(0,(Occurrence!J6-$D$4)*$B$7+$D$4*$B$6),0) | K6: =IF(Occurrence!K6>0,Occurrence!K6*$B$6,0) | L6: =IF(Occurrence!K6>0,MAX(0,(Occurrence!K6-$E$4)*$B$7+$E$4*$B$6),0) | M6: =Data!X6+$B$11 | N6: =(Data!X6-$D$9)*$B$12+$D$9+$B$11 | O6: =Data!Y6+$B$11 | P6: =(Data!Y6-$E$9)*$B$12+$E$9+$B$11
A7: Rain: spread ratio, obs / model (cal) | B7: =B5/C5 | H7: =Data!A7 | I7: =IF(Occurrence!J7>0,Occurrence!J7*$B$6,0) | J7: =IF(Occurrence!J7>0,MAX(0,(Occurrence!J7-$D$4)*$B$7+$D$4*$B$6),0) | K7: =IF(Occurrence!K7>0,Occurrence!K7*$B$6,0) | L7: =IF(Occurrence!K7>0,MAX(0,(Occurrence!K7-$E$4)*$B$7+$E$4*$B$6),0) | M7: =Data!X7+$B$11 | N7: =(Data!X7-$D$9)*$B$12+$D$9+$B$11 | O7: =Data!Y7+$B$11 | P7: =(Data!Y7-$E$9)*$B$12+$E$9+$B$11
H8: =Data!A8 | I8: =IF(Occurrence!J8>0,Occurrence!J8*$B$6,0) | J8: =IF(Occurrence!J8>0,MAX(0,(Occurrence!J8-$D$4)*$B$7+$D$4*$B$6),0) | K8: =IF(Occurrence!K8>0,Occurrence!K8*$B$6,0) | L8: =IF(Occurrence!K8>0,MAX(0,(Occurrence!K8-$E$4)*$B$7+$E$4*$B$6),0) | M8: =Data!X8+$B$11 | N8: =(Data!X8-$D$9)*$B$12+$D$9+$B$11 | O8: =Data!Y8+$B$11 | P8: =(Data!Y8-$E$9)*$B$12+$E$9+$B$11
A9: Temperature: mean (degC) | B9: =AVERAGE(Data!$U$2:$U$2441) | C9: =AVERAGE(Data!$V$2:$V$2441) | D9: =AVERAGE(Data!$X$2:$X$2441) | E9: =AVERAGE(Data!$Y$2:$Y$2441) | H9: =Data!A9 | I9: =IF(Occurrence!J9>0,Occurrence!J9*$B$6,0) | J9: =IF(Occurrence!J9>0,MAX(0,(Occurrence!J9-$D$4)*$B$7+$D$4*$B$6),0) | K9: =IF(Occurrence!K9>0,Occurrence!K9*$B$6,0) | L9: =IF(Occurrence!K9>0,MAX(0,(Occurrence!K9-$E$4)*$B$7+$E$4*$B$6),0) | M9: =Data!X9+$B$11 | N9: =(Data!X9-$D$9)*$B$12+$D$9+$B$11 | O9: =Data!Y9+$B$11 | P9: =(Data!Y9-$E$9)*$B$12+$E$9+$B$11
A10: Temperature: standard deviation (degC) | B10: =_xlfn.STDEV.S(Data!$U$2:$U$2441) | C10: =_xlfn.STDEV.S(Data!$V$2:$V$2441) | D10: =_xlfn.STDEV.S(Data!$X$2:$X$2441) | E10: =_xlfn.STDEV.S(Data!$Y$2:$Y$2441) | H10: =Data!A10 | I10: =IF(Occurrence!J10>0,Occurrence!J10*$B$6,0) | J10: =IF(Occurrence!J10>0,MAX(0,(Occurrence!J10-$D$4)*$B$7+$D$4*$B$6),0) | K10: =IF(Occurrence!K10>0,Occurrence!K10*$B$6,0) | L10: =IF(Occurrence!K10>0,MAX(0,(Occurrence!K10-$E$4)*$B$7+$E$4*$B$6),0) | M10: =Data!X10+$B$11 | N10: =(Data!X10-$D$9)*$B$12+$D$9+$B$11 | O10: =Data!Y10+$B$11 | P10: =(Data!Y10-$E$9)*$B$12+$E$9+$B$11
A11: Temperature: shift, obs - model (cal) | B11: =B9-C9 | H11: =Data!A11 | I11: =IF(Occurrence!J11>0,Occurrence!J11*$B$6,0) | J11: =IF(Occurrence!J11>0,MAX(0,(Occurrence!J11-$D$4)*$B$7+$D$4*$B$6),0) | K11: =IF(Occurrence!K11>0,Occurrence!K11*$B$6,0) | L11: =IF(Occurrence!K11>0,MAX(0,(Occurrence!K11-$E$4)*$B$7+$E$4*$B$6),0) | M11: =Data!X11+$B$11 | N11: =(Data!X11-$D$9)*$B$12+$D$9+$B$11 | O11: =Data!Y11+$B$11 | P11: =(Data!Y11-$E$9)*$B$12+$E$9+$B$11
A12: Temperature: spread ratio, obs / model (cal) | B12: =B10/C10 | H12: =Data!A12 | I12: =IF(Occurrence!J12>0,Occurrence!J12*$B$6,0) | J12: =IF(Occurrence!J12>0,MAX(0,(Occurrence!J12-$D$4)*$B$7+$D$4*$B$6),0) | K12: =IF(Occurrence!K12>0,Occurrence!K12*$B$6,0) | L12: =IF(Occurrence!K12>0,MAX(0,(Occurrence!K12-$E$4)*$B$7+$E$4*$B$6),0) | M12: =Data!X12+$B$11 | N12: =(Data!X12-$D$9)*$B$12+$D$9+$B$11 | O12: =Data!Y12+$B$11 | P12: =(Data!Y12-$E$9)*$B$12+$E$9+$B$11
H13: =Data!A13 | I13: =IF(Occurrence!J13>0,Occurrence!J13*$B$6,0) | J13: =IF(Occurrence!J13>0,MAX(0,(Occurrence!J13-$D$4)*$B$7+$D$4*$B$6),0) | K13: =IF(Occurrence!K13>0,Occurrence!K13*$B$6,0) | L13: =IF(Occurrence!K13>0,MAX(0,(Occurrence!K13-$E$4)*$B$7+$E$4*$B$6),0) | M13: =Data!X13+$B$11 | N13: =(Data!X13-$D$9)*$B$12+$D$9+$B$11 | O13: =Data!Y13+$B$11 | P13: =(Data!Y13-$E$9)*$B$12+$E$9+$B$11
A14: Wet days lost to the floor at 0 mm (validation) | B14: =COUNTIF(Occurrence!$J$2:$J$2441,">0")-COUNTIF(Delta!$J$2:$J$2441,">0") | H14: =Data!A14 | I14: =IF(Occurrence!J14>0,Occurrence!J14*$B$6,0) | J14: =IF(Occurrence!J14>0,MAX(0,(Occurrence!J14-$D$4)*$B$7+$D$4*$B$6),0) | K14: =IF(Occurrence!K14>0,Occurrence!K14*$B$6,0) | L14: =IF(Occurrence!K14>0,MAX(0,(Occurrence!K14-$E$4)*$B$7+$E$4*$B$6),0) | M14: =Data!X14+$B$11 | N14: =(Data!X14-$D$9)*$B$12+$D$9+$B$11 | O14: =Data!Y14+$B$11 | P14: =(Data!Y14-$E$9)*$B$12+$E$9+$B$11
A15: Wet days lost to the floor at 0 mm (future) | B15: =COUNTIF(Occurrence!$K$2:$K$2441,">0")-COUNTIF(Delta!$L$2:$L$2441,">0") | H15: =Data!A15 | I15: =IF(Occurrence!J15>0,Occurrence!J15*$B$6,0) | J15: =IF(Occurrence!J15>0,MAX(0,(Occurrence!J15-$D$4)*$B$7+$D$4*$B$6),0) | K15: =IF(Occurrence!K15>0,Occurrence!K15*$B$6,0) | L15: =IF(Occurrence!K15>0,MAX(0,(Occurrence!K15-$E$4)*$B$7+$E$4*$B$6),0) | M15: =Data!X15+$B$11 | N15: =(Data!X15-$D$9)*$B$12+$D$9+$B$11 | O15: =Data!Y15+$B$11 | P15: =(Data!Y15-$E$9)*$B$12+$E$9+$B$11
A16: Mean-and-spread scaling can give NEGATIVE rain for the lightest wet days; the floor at 0 removes them and the wet-day fraction falls. | H16: =Data!A16 | I16: =IF(Occurrence!J16>0,Occurrence!J16*$B$6,0) | J16: =IF(Occurrence!J16>0,MAX(0,(Occurrence!J16-$D$4)*$B$7+$D$4*$B$6),0) | K16: =IF(Occurrence!K16>0,Occurrence!K16*$B$6,0) | L16: =IF(Occurrence!K16>0,MAX(0,(Occurrence!K16-$E$4)*$B$7+$E$4*$B$6),0) | M16: =Data!X16+$B$11 | N16: =(Data!X16-$D$9)*$B$12+$D$9+$B$11 | O16: =Data!Y16+$B$11 | P16: =(Data!Y16-$E$9)*$B$12+$E$9+$B$11
H17: =Data!A17 | I17: =IF(Occurrence!J17>0,Occurrence!J17*$B$6,0) | J17: =IF(Occurrence!J17>0,MAX(0,(Occurrence!J17-$D$4)*$B$7+$D$4*$B$6),0) | K17: =IF(Occurrence!K17>0,Occurrence!K17*$B$6,0) | L17: =IF(Occurrence!K17>0,MAX(0,(Occurrence!K17-$E$4)*$B$7+$E$4*$B$6),0) | M17: =Data!X17+$B$11 | N17: =(Data!X17-$D$9)*$B$12+$D$9+$B$11 | O17: =Data!Y17+$B$11 | P17: =(Data!Y17-$E$9)*$B$12+$E$9+$B$11
A18: Warning: a ratio of means near zero (illustrative inputs) | H18: =Data!A18 | I18: =IF(Occurrence!J18>0,Occurrence!J18*$B$6,0) | J18: =IF(Occurrence!J18>0,MAX(0,(Occurrence!J18-$D$4)*$B$7+$D$4*$B$6),0) | K18: =IF(Occurrence!K18>0,Occurrence!K18*$B$6,0) | L18: =IF(Occurrence!K18>0,MAX(0,(Occurrence!K18-$E$4)*$B$7+$E$4*$B$6),0) | M18: =Data!X18+$B$11 | N18: =(Data!X18-$D$9)*$B$12+$D$9+$B$11 | O18: =Data!Y18+$B$11 | P18: =(Data!Y18-$E$9)*$B$12+$E$9+$B$11
A19: Observed dry-season mean (mm/day) | B19: 2 | H19: =Data!A19 | I19: =IF(Occurrence!J19>0,Occurrence!J19*$B$6,0) | J19: =IF(Occurrence!J19>0,MAX(0,(Occurrence!J19-$D$4)*$B$7+$D$4*$B$6),0) | K19: =IF(Occurrence!K19>0,Occurrence!K19*$B$6,0) | L19: =IF(Occurrence!K19>0,MAX(0,(Occurrence!K19-$E$4)*$B$7+$E$4*$B$6),0) | M19: =Data!X19+$B$11 | N19: =(Data!X19-$D$9)*$B$12+$D$9+$B$11 | O19: =Data!Y19+$B$11 | P19: =(Data!Y19-$E$9)*$B$12+$E$9+$B$11
A20: Model dry-season mean (mm/day) | B20: 0.05 | H20: =Data!A20 | I20: =IF(Occurrence!J20>0,Occurrence!J20*$B$6,0) | J20: =IF(Occurrence!J20>0,MAX(0,(Occurrence!J20-$D$4)*$B$7+$D$4*$B$6),0) | K20: =IF(Occurrence!K20>0,Occurrence!K20*$B$6,0) | L20: =IF(Occurrence!K20>0,MAX(0,(Occurrence!K20-$E$4)*$B$7+$E$4*$B$6),0) | M20: =Data!X20+$B$11 | N20: =(Data!X20-$D$9)*$B$12+$D$9+$B$11 | O20: =Data!Y20+$B$11 | P20: =(Data!Y20-$E$9)*$B$12+$E$9+$B$11
A21: Multiplicative factor obs / model | B21: =B19/B20 | H21: =Data!A21 | I21: =IF(Occurrence!J21>0,Occurrence!J21*$B$6,0) | J21: =IF(Occurrence!J21>0,MAX(0,(Occurrence!J21-$D$4)*$B$7+$D$4*$B$6),0) | K21: =IF(Occurrence!K21>0,Occurrence!K21*$B$6,0) | L21: =IF(Occurrence!K21>0,MAX(0,(Occurrence!K21-$E$4)*$B$7+$E$4*$B$6),0) | M21: =Data!X21+$B$11 | N21: =(Data!X21-$D$9)*$B$12+$D$9+$B$11 | O21: =Data!Y21+$B$11 | P21: =(Data!Y21-$E$9)*$B$12+$E$9+$B$11
A22: A model day of (mm) | B22: 0.4 | H22: =Data!A22 | I22: =IF(Occurrence!J22>0,Occurrence!J22*$B$6,0) | J22: =IF(Occurrence!J22>0,MAX(0,(Occurrence!J22-$D$4)*$B$7+$D$4*$B$6),0) | K22: =IF(Occurrence!K22>0,Occurrence!K22*$B$6,0) | L22: =IF(Occurrence!K22>0,MAX(0,(Occurrence!K22-$E$4)*$B$7+$E$4*$B$6),0) | M22: =Data!X22+$B$11 | N22: =(Data!X22-$D$9)*$B$12+$D$9+$B$11 | O22: =Data!Y22+$B$11 | P22: =(Data!Y22-$E$9)*$B$12+$E$9+$B$11
A23: becomes (mm) | B23: =B21*B22 | H23: =Data!A23 | I23: =IF(Occurrence!J23>0,Occurrence!J23*$B$6,0) | J23: =IF(Occurrence!J23>0,MAX(0,(Occurrence!J23-$D$4)*$B$7+$D$4*$B$6),0) | K23: =IF(Occurrence!K23>0,Occurrence!K23*$B$6,0) | L23: =IF(Occurrence!K23>0,MAX(0,(Occurrence!K23-$E$4)*$B$7+$E$4*$B$6),0) | M23: =Data!X23+$B$11 | N23: =(Data!X23-$D$9)*$B$12+$D$9+$B$11 | O23: =Data!Y23+$B$11 | P23: =(Data!Y23-$E$9)*$B$12+$E$9+$B$11
A24: A factor of 40 turns a 0.4 mm model drizzle into 16 mm. Never use a ratio when the model mean is close to zero; use an additive correction or a bounded one. | H24: =Data!A24 | I24: =IF(Occurrence!J24>0,Occurrence!J24*$B$6,0) | J24: =IF(Occurrence!J24>0,MAX(0,(Occurrence!J24-$D$4)*$B$7+$D$4*$B$6),0) | K24: =IF(Occurrence!K24>0,Occurrence!K24*$B$6,0) | L24: =IF(Occurrence!K24>0,MAX(0,(Occurrence!K24-$E$4)*$B$7+$E$4*$B$6),0) | M24: =Data!X24+$B$11 | N24: =(Data!X24-$D$9)*$B$12+$D$9+$B$11 | O24: =Data!Y24+$B$11 | P24: =(Data!Y24-$E$9)*$B$12+$E$9+$B$11
H25: =Data!A25 | I25: =IF(Occurrence!J25>0,Occurrence!J25*$B$6,0) | J25: =IF(Occurrence!J25>0,MAX(0,(Occurrence!J25-$D$4)*$B$7+$D$4*$B$6),0) | K25: =IF(Occurrence!K25>0,Occurrence!K25*$B$6,0) | L25: =IF(Occurrence!K25>0,MAX(0,(Occurrence!K25-$E$4)*$B$7+$E$4*$B$6),0) | M25: =Data!X25+$B$11 | N25: =(Data!X25-$D$9)*$B$12+$D$9+$B$11 | O25: =Data!Y25+$B$11 | P25: =(Data!Y25-$E$9)*$B$12+$E$9+$B$11
H26: =Data!A26 | I26: =IF(Occurrence!J26>0,Occurrence!J26*$B$6,0) | J26: =IF(Occurrence!J26>0,MAX(0,(Occurrence!J26-$D$4)*$B$7+$D$4*$B$6),0) | K26: =IF(Occurrence!K26>0,Occurrence!K26*$B$6,0) | L26: =IF(Occurrence!K26>0,MAX(0,(Occurrence!K26-$E$4)*$B$7+$E$4*$B$6),0) | M26: =Data!X26+$B$11 | N26: =(Data!X26-$D$9)*$B$12+$D$9+$B$11 | O26: =Data!Y26+$B$11 | P26: =(Data!Y26-$E$9)*$B$12+$E$9+$B$11
H27: =Data!A27 | I27: =IF(Occurrence!J27>0,Occurrence!J27*$B$6,0) | J27: =IF(Occurrence!J27>0,MAX(0,(Occurrence!J27-$D$4)*$B$7+$D$4*$B$6),0) | K27: =IF(Occurrence!K27>0,Occurrence!K27*$B$6,0) | L27: =IF(Occurrence!K27>0,MAX(0,(Occurrence!K27-$E$4)*$B$7+$E$4*$B$6),0) | M27: =Data!X27+$B$11 | N27: =(Data!X27-$D$9)*$B$12+$D$9+$B$11 | O27: =Data!Y27+$B$11 | P27: =(Data!Y27-$E$9)*$B$12+$E$9+$B$11
H28: =Data!A28 | I28: =IF(Occurrence!J28>0,Occurrence!J28*$B$6,0) | J28: =IF(Occurrence!J28>0,MAX(0,(Occurrence!J28-$D$4)*$B$7+$D$4*$B$6),0) | K28: =IF(Occurrence!K28>0,Occurrence!K28*$B$6,0) | L28: =IF(Occurrence!K28>0,MAX(0,(Occurrence!K28-$E$4)*$B$7+$E$4*$B$6),0) | M28: =Data!X28+$B$11 | N28: =(Data!X28-$D$9)*$B$12+$D$9+$B$11 | O28: =Data!Y28+$B$11 | P28: =(Data!Y28-$E$9)*$B$12+$E$9+$B$11
H29: =Data!A29 | I29: =IF(Occurrence!J29>0,Occurrence!J29*$B$6,0) | J29: =IF(Occurrence!J29>0,MAX(0,(Occurrence!J29-$D$4)*$B$7+$D$4*$B$6),0) | K29: =IF(Occurrence!K29>0,Occurrence!K29*$B$6,0) | L29: =IF(Occurrence!K29>0,MAX(0,(Occurrence!K29-$E$4)*$B$7+$E$4*$B$6),0) | M29: =Data!X29+$B$11 | N29: =(Data!X29-$D$9)*$B$12+$D$9+$B$11 | O29: =Data!Y29+$B$11 | P29: =(Data!Y29-$E$9)*$B$12+$E$9+$B$11
H30: =Data!A30 | I30: =IF(Occurrence!J30>0,Occurrence!J30*$B$6,0) | J30: =IF(Occurrence!J30>0,MAX(0,(Occurrence!J30-$D$4)*$B$7+$D$4*$B$6),0) | K30: =IF(Occurrence!K30>0,Occurrence!K30*$B$6,0) | L30: =IF(Occurrence!K30>0,MAX(0,(Occurrence!K30-$E$4)*$B$7+$E$4*$B$6),0) | M30: =Data!X30+$B$11 | N30: =(Data!X30-$D$9)*$B$12+$D$9+$B$11 | O30: =Data!Y30+$B$11 | P30: =(Data!Y30-$E$9)*$B$12+$E$9+$B$11
H31: =Data!A31 | I31: =IF(Occurrence!J31>0,Occurrence!J31*$B$6,0) | J31: =IF(Occurrence!J31>0,MAX(0,(Occurrence!J31-$D$4)*$B$7+$D$4*$B$6),0) | K31: =IF(Occurrence!K31>0,Occurrence!K31*$B$6,0) | L31: =IF(Occurrence!K31>0,MAX(0,(Occurrence!K31-$E$4)*$B$7+$E$4*$B$6),0) | M31: =Data!X31+$B$11 | N31: =(Data!X31-$D$9)*$B$12+$D$9+$B$11 | O31: =Data!Y31+$B$11 | P31: =(Data!Y31-$E$9)*$B$12+$E$9+$B$11
H32: =Data!A32 | I32: =IF(Occurrence!J32>0,Occurrence!J32*$B$6,0) | J32: =IF(Occurrence!J32>0,MAX(0,(Occurrence!J32-$D$4)*$B$7+$D$4*$B$6),0) | K32: =IF(Occurrence!K32>0,Occurrence!K32*$B$6,0) | L32: =IF(Occurrence!K32>0,MAX(0,(Occurrence!K32-$E$4)*$B$7+$E$4*$B$6),0) | M32: =Data!X32+$B$11 | N32: =(Data!X32-$D$9)*$B$12+$D$9+$B$11 | O32: =Data!Y32+$B$11 | P32: =(Data!Y32-$E$9)*$B$12+$E$9+$B$11
H33: =Data!A33 | I33: =IF(Occurrence!J33>0,Occurrence!J33*$B$6,0) | J33: =IF(Occurrence!J33>0,MAX(0,(Occurrence!J33-$D$4)*$B$7+$D$4*$B$6),0) | K33: =IF(Occurrence!K33>0,Occurrence!K33*$B$6,0) | L33: =IF(Occurrence!K33>0,MAX(0,(Occurrence!K33-$E$4)*$B$7+$E$4*$B$6),0) | M33: =Data!X33+$B$11 | N33: =(Data!X33-$D$9)*$B$12+$D$9+$B$11 | O33: =Data!Y33+$B$11 | P33: =(Data!Y33-$E$9)*$B$12+$E$9+$B$11
H34: =Data!A34 | I34: =IF(Occurrence!J34>0,Occurrence!J34*$B$6,0) | J34: =IF(Occurrence!J34>0,MAX(0,(Occurrence!J34-$D$4)*$B$7+$D$4*$B$6),0) | K34: =IF(Occurrence!K34>0,Occurrence!K34*$B$6,0) | L34: =IF(Occurrence!K34>0,MAX(0,(Occurrence!K34-$E$4)*$B$7+$E$4*$B$6),0) | M34: =Data!X34+$B$11 | N34: =(Data!X34-$D$9)*$B$12+$D$9+$B$11 | O34: =Data!Y34+$B$11 | P34: =(Data!Y34-$E$9)*$B$12+$E$9+$B$11
H35: =Data!A35 | I35: =IF(Occurrence!J35>0,Occurrence!J35*$B$6,0) | J35: =IF(Occurrence!J35>0,MAX(0,(Occurrence!J35-$D$4)*$B$7+$D$4*$B$6),0) | K35: =IF(Occurrence!K35>0,Occurrence!K35*$B$6,0) | L35: =IF(Occurrence!K35>0,MAX(0,(Occurrence!K35-$E$4)*$B$7+$E$4*$B$6),0) | M35: =Data!X35+$B$11 | N35: =(Data!X35-$D$9)*$B$12+$D$9+$B$11 | O35: =Data!Y35+$B$11 | P35: =(Data!Y35-$E$9)*$B$12+$E$9+$B$11
H36: =Data!A36 | I36: =IF(Occurrence!J36>0,Occurrence!J36*$B$6,0) | J36: =IF(Occurrence!J36>0,MAX(0,(Occurrence!J36-$D$4)*$B$7+$D$4*$B$6),0) | K36: =IF(Occurrence!K36>0,Occurrence!K36*$B$6,0) | L36: =IF(Occurrence!K36>0,MAX(0,(Occurrence!K36-$E$4)*$B$7+$E$4*$B$6),0) | M36: =Data!X36+$B$11 | N36: =(Data!X36-$D$9)*$B$12+$D$9+$B$11 | O36: =Data!Y36+$B$11 | P36: =(Data!Y36-$E$9)*$B$12+$E$9+$B$11
... H2441: =Data!A2441 | I2441: =IF(Occurrence!J2441>0,Occurrence!J2441*$B$6,0) | J2441: =IF(Occurrence!J2441>0,MAX(0,(Occurrence!J2441-$D$4)*$B$7+$D$4*$B$6),0) | K2441: =IF(Occurrence!K2441>0,Occurrence!K2441*$B$6,0) | L2441: =IF(Occurrence!K2441>0,MAX(0,(Occurrence!K2441-$E$4)*$B$7+$E$4*$B$6),0) | M2441: =Data!X2441+$B$11 | N2441: =(Data!X2441-$D$9)*$B$12+$D$9+$B$11 | O2441: =Data!Y2441+$B$11 | P2441: =(Data!Y2441-$E$9)*$B$12+$E$9+$B$11

Sheet QM_tiny
A1: Quantile mapping by hand: 12 values
A2: Pair the i-th smallest model value with the i-th smallest observed value, join the pairs by straight lines, and read the corrected value off this line. All values are made up (mm).
D3: n = | E3: =COUNT(A5:A16)
A4: Obs wet-day rain (mm) | B4: Model wet-day rain (mm) | D4: rank k | E4: obs, sorted | F4: model, sorted | G4: probability p_k = (k-1)/(n-1)
A5: 11.5 | B5: 4.1 | D5: 1 | E5: =SMALL($A$5:$A$16,D5) | F5: =SMALL($B$5:$B$16,D5) | G5: =(D5-1)/($E$3-1)
A6: 0.6 | B6: 1.4 | D6: 2 | E6: =SMALL($A$5:$A$16,D6) | F6: =SMALL($B$5:$B$16,D6) | G6: =(D6-1)/($E$3-1)
A7: 31 | B7: 9.5 | D7: 3 | E7: =SMALL($A$5:$A$16,D7) | F7: =SMALL($B$5:$B$16,D7) | G7: =(D7-1)/($E$3-1)
A8: 3.1 | B8: 2.2 | D8: 4 | E8: =SMALL($A$5:$A$16,D8) | F8: =SMALL($B$5:$B$16,D8) | G8: =(D8-1)/($E$3-1)
A9: 8.3 | B9: 6.3 | D9: 5 | E9: =SMALL($A$5:$A$16,D9) | F9: =SMALL($B$5:$B$16,D9) | G9: =(D9-1)/($E$3-1)
A10: 58 | B10: 14 | D10: 6 | E10: =SMALL($A$5:$A$16,D10) | F10: =SMALL($B$5:$B$16,D10) | G10: =(D10-1)/($E$3-1)
A11: 1.2 | B11: 1.1 | D11: 7 | E11: =SMALL($A$5:$A$16,D11) | F11: =SMALL($B$5:$B$16,D11) | G11: =(D11-1)/($E$3-1)
A12: 22.4 | B12: 5 | D12: 8 | E12: =SMALL($A$5:$A$16,D12) | F12: =SMALL($B$5:$B$16,D12) | G12: =(D12-1)/($E$3-1)
A13: 4.8 | B13: 2.8 | D13: 9 | E13: =SMALL($A$5:$A$16,D13) | F13: =SMALL($B$5:$B$16,D13) | G13: =(D13-1)/($E$3-1)
A14: 15 | B14: 7.7 | D14: 10 | E14: =SMALL($A$5:$A$16,D14) | F14: =SMALL($B$5:$B$16,D14) | G14: =(D14-1)/($E$3-1)
A15: 2.5 | B15: 1.9 | D15: 11 | E15: =SMALL($A$5:$A$16,D15) | F15: =SMALL($B$5:$B$16,D15) | G15: =(D15-1)/($E$3-1)
A16: 6 | B16: 3.4 | D16: 12 | E16: =SMALL($A$5:$A$16,D16) | F16: =SMALL($B$5:$B$16,D16) | G16: =(D16-1)/($E$3-1)
A18: Correct new model values
A19: x, new model value (mm) | B19: i: last sorted model value <= x | C19: p = model probability of x | D19: y, corrected (mm) | E19: check: PERCENTILE.INC(obs, p) | F19: rule used
A20: 0.8 | B20: =IFERROR(MATCH(A20,$F$5:$F$16,1),0) | C20: =IF(OR(B20=0,B20=$E$3),"outside range",(B20-1+(A20-INDEX($F$5:$F$16,B20))/(INDEX($F$5:$F$16,B20+1)-INDEX($F$5:$F$16,B20)))/($E$3-1)) | D20: =IF(B20=0,A20*$E$5/$F$5,IF(B20=$E$3,A20*INDEX($E$5:$E$16,$E$3)/INDEX($F$5:$F$16,$E$3),INDEX($E$5:$E$16,B20)+(A20-INDEX($F$5:$F$16,B20))/(INDEX($F$5:$F$16,B20+1)-INDEX($F$5:$F$16,B20))*(INDEX($E$5:$E$16,B20+1)-INDEX($E$5:$E$16,B20)))) | E20: =IF(ISNUMBER(C20),_xlfn.PERCENTILE.INC($A$5:$A$16,C20),"n/a") | F20: =IF(B20=0,"below range: ratio of smallest pair",IF(B20=$E$3,"above range: ratio of largest pair","interpolate between neighbours"))
A21: 2.5 | B21: =IFERROR(MATCH(A21,$F$5:$F$16,1),0) | C21: =IF(OR(B21=0,B21=$E$3),"outside range",(B21-1+(A21-INDEX($F$5:$F$16,B21))/(INDEX($F$5:$F$16,B21+1)-INDEX($F$5:$F$16,B21)))/($E$3-1)) | D21: =IF(B21=0,A21*$E$5/$F$5,IF(B21=$E$3,A21*INDEX($E$5:$E$16,$E$3)/INDEX($F$5:$F$16,$E$3),INDEX($E$5:$E$16,B21)+(A21-INDEX($F$5:$F$16,B21))/(INDEX($F$5:$F$16,B21+1)-INDEX($F$5:$F$16,B21))*(INDEX($E$5:$E$16,B21+1)-INDEX($E$5:$E$16,B21)))) | E21: =IF(ISNUMBER(C21),_xlfn.PERCENTILE.INC($A$5:$A$16,C21),"n/a") | F21: =IF(B21=0,"below range: ratio of smallest pair",IF(B21=$E$3,"above range: ratio of largest pair","interpolate between neighbours"))
A22: 4.5 | B22: =IFERROR(MATCH(A22,$F$5:$F$16,1),0) | C22: =IF(OR(B22=0,B22=$E$3),"outside range",(B22-1+(A22-INDEX($F$5:$F$16,B22))/(INDEX($F$5:$F$16,B22+1)-INDEX($F$5:$F$16,B22)))/($E$3-1)) | D22: =IF(B22=0,A22*$E$5/$F$5,IF(B22=$E$3,A22*INDEX($E$5:$E$16,$E$3)/INDEX($F$5:$F$16,$E$3),INDEX($E$5:$E$16,B22)+(A22-INDEX($F$5:$F$16,B22))/(INDEX($F$5:$F$16,B22+1)-INDEX($F$5:$F$16,B22))*(INDEX($E$5:$E$16,B22+1)-INDEX($E$5:$E$16,B22)))) | E22: =IF(ISNUMBER(C22),_xlfn.PERCENTILE.INC($A$5:$A$16,C22),"n/a") | F22: =IF(B22=0,"below range: ratio of smallest pair",IF(B22=$E$3,"above range: ratio of largest pair","interpolate between neighbours"))
A23: 7 | B23: =IFERROR(MATCH(A23,$F$5:$F$16,1),0) | C23: =IF(OR(B23=0,B23=$E$3),"outside range",(B23-1+(A23-INDEX($F$5:$F$16,B23))/(INDEX($F$5:$F$16,B23+1)-INDEX($F$5:$F$16,B23)))/($E$3-1)) | D23: =IF(B23=0,A23*$E$5/$F$5,IF(B23=$E$3,A23*INDEX($E$5:$E$16,$E$3)/INDEX($F$5:$F$16,$E$3),INDEX($E$5:$E$16,B23)+(A23-INDEX($F$5:$F$16,B23))/(INDEX($F$5:$F$16,B23+1)-INDEX($F$5:$F$16,B23))*(INDEX($E$5:$E$16,B23+1)-INDEX($E$5:$E$16,B23)))) | E23: =IF(ISNUMBER(C23),_xlfn.PERCENTILE.INC($A$5:$A$16,C23),"n/a") | F23: =IF(B23=0,"below range: ratio of smallest pair",IF(B23=$E$3,"above range: ratio of largest pair","interpolate between neighbours"))
A24: 12 | B24: =IFERROR(MATCH(A24,$F$5:$F$16,1),0) | C24: =IF(OR(B24=0,B24=$E$3),"outside range",(B24-1+(A24-INDEX($F$5:$F$16,B24))/(INDEX($F$5:$F$16,B24+1)-INDEX($F$5:$F$16,B24)))/($E$3-1)) | D24: =IF(B24=0,A24*$E$5/$F$5,IF(B24=$E$3,A24*INDEX($E$5:$E$16,$E$3)/INDEX($F$5:$F$16,$E$3),INDEX($E$5:$E$16,B24)+(A24-INDEX($F$5:$F$16,B24))/(INDEX($F$5:$F$16,B24+1)-INDEX($F$5:$F$16,B24))*(INDEX($E$5:$E$16,B24+1)-INDEX($E$5:$E$16,B24)))) | E24: =IF(ISNUMBER(C24),_xlfn.PERCENTILE.INC($A$5:$A$16,C24),"n/a") | F24: =IF(B24=0,"below range: ratio of smallest pair",IF(B24=$E$3,"above range: ratio of largest pair","interpolate between neighbours"))
A25: 20 | B25: =IFERROR(MATCH(A25,$F$5:$F$16,1),0) | C25: =IF(OR(B25=0,B25=$E$3),"outside range",(B25-1+(A25-INDEX($F$5:$F$16,B25))/(INDEX($F$5:$F$16,B25+1)-INDEX($F$5:$F$16,B25)))/($E$3-1)) | D25: =IF(B25=0,A25*$E$5/$F$5,IF(B25=$E$3,A25*INDEX($E$5:$E$16,$E$3)/INDEX($F$5:$F$16,$E$3),INDEX($E$5:$E$16,B25)+(A25-INDEX($F$5:$F$16,B25))/(INDEX($F$5:$F$16,B25+1)-INDEX($F$5:$F$16,B25))*(INDEX($E$5:$E$16,B25+1)-INDEX($E$5:$E$16,B25)))) | E25: =IF(ISNUMBER(C25),_xlfn.PERCENTILE.INC($A$5:$A$16,C25),"n/a") | F25: =IF(B25=0,"below range: ratio of smallest pair",IF(B25=$E$3,"above range: ratio of largest pair","interpolate between neighbours"))
A27: Example: x = 4.5 lies between the 7th (4.1) and 8th (5.0) sorted model values, so it is 0.44 of the way from the 7th to the 8th; the corrected value is the same fraction of the way from the 7th to the 8th sorted observation.

Sheet QM_gamma
A1: Parametric quantile mapping: gamma (rain) and normal (temperature) | H1: day | I1: rain val: F_mod(x) | J1: rain val: y | K1: rain fut: F_mod(x) | L1: rain fut: y | M1: temp val: F_mod(x) | N1: temp val: y | O1: temp fut: F_mod(x) | P1: temp fut: y
A2: Fit by moments on the calibration period: k = m^2/s^2, theta = s^2/m. Then y = F_obs^-1( F_mod(x) ) = GAMMA.INV( GAMMA.DIST(x, k_mod, theta_mod, TRUE), k_obs, theta_obs ). | H2: =Data!A2 | I2: =IF(Occurrence!J2>0,_xlfn.GAMMA.DIST(Occurrence!J2,$C$6,$C$7,TRUE),0) | J2: =IF(Occurrence!J2>0,_xlfn.GAMMA.INV(I2,$B$6,$B$7),0) | K2: =IF(Occurrence!K2>0,_xlfn.GAMMA.DIST(Occurrence!K2,$C$6,$C$7,TRUE),0) | L2: =IF(Occurrence!K2>0,_xlfn.GAMMA.INV(K2,$B$6,$B$7),0) | M2: =_xlfn.NORM.DIST(Data!X2,$C$9,$C$10,TRUE) | N2: =_xlfn.NORM.INV(M2,$B$9,$B$10) | O2: =_xlfn.NORM.DIST(Data!Y2,$C$9,$C$10,TRUE) | P2: =_xlfn.NORM.INV(O2,$B$9,$B$10)
A3: Quantity | B3: Obs cal | C3: Model cal (adj.) | H3: =Data!A3 | I3: =IF(Occurrence!J3>0,_xlfn.GAMMA.DIST(Occurrence!J3,$C$6,$C$7,TRUE),0) | J3: =IF(Occurrence!J3>0,_xlfn.GAMMA.INV(I3,$B$6,$B$7),0) | K3: =IF(Occurrence!K3>0,_xlfn.GAMMA.DIST(Occurrence!K3,$C$6,$C$7,TRUE),0) | L3: =IF(Occurrence!K3>0,_xlfn.GAMMA.INV(K3,$B$6,$B$7),0) | M3: =_xlfn.NORM.DIST(Data!X3,$C$9,$C$10,TRUE) | N3: =_xlfn.NORM.INV(M3,$B$9,$B$10) | O3: =_xlfn.NORM.DIST(Data!Y3,$C$9,$C$10,TRUE) | P3: =_xlfn.NORM.INV(O3,$B$9,$B$10)
A4: Rain: wet-day mean m (mm) | B4: =AVERAGEIFS(Data!$O$2:$O$2441,Data!$O$2:$O$2441,">0") | C4: =AVERAGEIFS(Occurrence!$I$2:$I$2441,Occurrence!$I$2:$I$2441,">0") | H4: =Data!A4 | I4: =IF(Occurrence!J4>0,_xlfn.GAMMA.DIST(Occurrence!J4,$C$6,$C$7,TRUE),0) | J4: =IF(Occurrence!J4>0,_xlfn.GAMMA.INV(I4,$B$6,$B$7),0) | K4: =IF(Occurrence!K4>0,_xlfn.GAMMA.DIST(Occurrence!K4,$C$6,$C$7,TRUE),0) | L4: =IF(Occurrence!K4>0,_xlfn.GAMMA.INV(K4,$B$6,$B$7),0) | M4: =_xlfn.NORM.DIST(Data!X4,$C$9,$C$10,TRUE) | N4: =_xlfn.NORM.INV(M4,$B$9,$B$10) | O4: =_xlfn.NORM.DIST(Data!Y4,$C$9,$C$10,TRUE) | P4: =_xlfn.NORM.INV(O4,$B$9,$B$10)
A5: Rain: wet-day standard deviation s (mm) | B5: =SQRT((SUMPRODUCT((Data!$O$2:$O$2441>0)*Data!$O$2:$O$2441^2)-COUNTIF(Data!$O$2:$O$2441,">0")*B4^2)/(COUNTIF(Data!$O$2:$O$2441,">0")-1)) | C5: =SQRT((SUMPRODUCT((Occurrence!$I$2:$I$2441>0)*Occurrence!$I$2:$I$2441^2)-COUNTIF(Occurrence!$I$2:$I$2441,">0")*C4^2)/(COUNTIF(Occurrence!$I$2:$I$2441,">0")-1)) | H5: =Data!A5 | I5: =IF(Occurrence!J5>0,_xlfn.GAMMA.DIST(Occurrence!J5,$C$6,$C$7,TRUE),0) | J5: =IF(Occurrence!J5>0,_xlfn.GAMMA.INV(I5,$B$6,$B$7),0) | K5: =IF(Occurrence!K5>0,_xlfn.GAMMA.DIST(Occurrence!K5,$C$6,$C$7,TRUE),0) | L5: =IF(Occurrence!K5>0,_xlfn.GAMMA.INV(K5,$B$6,$B$7),0) | M5: =_xlfn.NORM.DIST(Data!X5,$C$9,$C$10,TRUE) | N5: =_xlfn.NORM.INV(M5,$B$9,$B$10) | O5: =_xlfn.NORM.DIST(Data!Y5,$C$9,$C$10,TRUE) | P5: =_xlfn.NORM.INV(O5,$B$9,$B$10)
A6: Rain: gamma shape k = m^2/s^2 | B6: =B4^2/B5^2 | C6: =C4^2/C5^2 | H6: =Data!A6 | I6: =IF(Occurrence!J6>0,_xlfn.GAMMA.DIST(Occurrence!J6,$C$6,$C$7,TRUE),0) | J6: =IF(Occurrence!J6>0,_xlfn.GAMMA.INV(I6,$B$6,$B$7),0) | K6: =IF(Occurrence!K6>0,_xlfn.GAMMA.DIST(Occurrence!K6,$C$6,$C$7,TRUE),0) | L6: =IF(Occurrence!K6>0,_xlfn.GAMMA.INV(K6,$B$6,$B$7),0) | M6: =_xlfn.NORM.DIST(Data!X6,$C$9,$C$10,TRUE) | N6: =_xlfn.NORM.INV(M6,$B$9,$B$10) | O6: =_xlfn.NORM.DIST(Data!Y6,$C$9,$C$10,TRUE) | P6: =_xlfn.NORM.INV(O6,$B$9,$B$10)
